Workbook

Sheet Overview
B2: Context-Synthetic Model — Full Experiment
B3: Heart-Disease (10, 13, 2) · Zhuravlev metric on three feature sets · Ψ(r) by (5) · ω by (4) · η by (6) · HAG · meta-algorithm · evaluation
B5: Workbook map
B6: # | C6: Sheet | D6: Stage | E6: What it contains
B7: 1 | C7: Parameters | D7: 0 · Parameters | E7: k range (k_min = 3, k_max = 2·min|Kᵢ| − 3 from the class sizes), HAG parameters α, δ, ϰ, cr1, majorizer, the two template/article switches, base operators and rules.
B8: 2 | C8: Template Deviations | D8: 0 · Template deviations | E8: ⚠1 running class centres in θ/γ and ⚠2 double majorizer in STEP 4: exact template cells, worked examples on the template data, fixes, and the effect of both switches.
B9: 3 | C9: Dataset | D9: 1 · Input data | E9: Original sample: 10 objects (S₁–S₁₀) × 13 features (x₁–x₁₃), class labels (K1 = 4, K2 = 6), feature-type flags (1 = quantitative, 0 = nominal).
B10: 4 | C10: Quantitative | D10: 1 · Input data | E10: The 6 quantitative features (x₁, x₄, x₅, x₈, x₁₀, x₁₂) with class labels.
B11: 5 | C11: Nominal | D11: 1 · Input data | E11: The 7 nominal features (x₂, x₃, x₆, x₇, x₉, x₁₁, x₁₃) with class labels.
B12: 6 | C12: Normalized Dataset | D12: Step 1 · Scale unification | E12: Quantitative features mapped to [0, 1] by (x − min)/(max − min); nominal codes unchanged; type, min and max rows.
B13: 7 | C13: Zhuravlev Distances | D13: Step 2 · Distances | E13: Three base operators: Zhuravlev distance ρ, its quantitative part ρ_I and its nominal part ρ_J, for all pairs.
B14: 8 | C14: Sorted Neighbors (ρ) | D14: Step 3 · Sorting (ρ) | E14: Rank matrix and one block per object under ρ: neighbours with original index, distance, class, same-class count μ and K1 count χ₁; permitted k marked.
B15: 9 | C15: Sorted Neighbors (ρ_I) | D15: Step 3 · Sorting (ρ_I) | E15: The same for the quantitative operator ρ_I.
B16: 10 | C16: Sorted Neighbors (ρ_J) | D16: Step 3 · Sorting (ρ_J) | E16: The same for the nominal operator ρ_J (many ties — see Model Properties).
B17: 11 | C17: Synthetic Features (k-NN) | D17: Step 4 · Same-class counts μ | E17: Synthetic Features based on k-NN: μ = same-class neighbours for every permitted k and operator (training-side gradations).
B18: 12 | C18: Ψ(r) Binary Features | D18: Step 5 · Ψ(r) — formula (5) | E18: Feature map a₁ … a₆ = (operator, k); χ₁, χ₂ and the class-free synthetic features aᵤ ∈ {1, 2}.
... B38: 32 | C38: Validation | D38: Checks · Validation | E38: Workbook formulas vs the independent Python engine; highlighted template deviations; recalculation and template notes.
B40: Algorithm — pipeline specification (article element → sheet → planned Python function)
B41: # | C41: Article element | D41: Sheet | E41: Definition → Python function (csmodel)
B42: 1 | C42: Data, feature types, classes | D42: Dataset | E42: E₀ = {S₁ … Sₘ}, X(n) heterogeneous, K1, K2 → core.load_dataset(path) → (X, y, types)
B43: 2 | C43: Scale unification | D43: Normalized Dataset | E43: x′ = (x − min)/(max − min) for j ∈ I, training min/max → core.scale_params, core.unify
B44: 3 | C44: Base operators ρ, ρ_I, ρ_J | D44: Zhuravlev Distances | E44: Zhuravlev metric on I ∪ J, on I and on J (article: variants of Ψ) → core.rho(zx, zy, x, y, types, op)
B45: 4 | C45: Nested neighbourhoods | D45: Sorted Neighbors (ρ) | E45: order by (ρ, original index), self excluded; μ and χ₁ per rank → core.neighbours, core.chi1
B46: 5 | C46: Permitted k | D46: Parameters | E46: k = 3, 5, …, 2·min|Kᵢ| − 3 → core.permitted_k(y)
B47: 6 | C47: Formula (5) — Ψ(r) | D47: Ψ(r) Binary Features | E47: aᵤ = 1 if χ₁ > [k/2], 2 if χ₂ > [k/2] → core.binary_a
B48: 7 | C48: Formulas (1), (2) | D48: Membership & Stability | E48: f_k(μ), stability g_k (β = k), meta-object, bit masks → core.membership, core.stability
B49: 8 | C49: Formulas (3), (4) | D49: Informativeness ω | E49: G_k = (q₁ + q₂)/2, ω = share of objects on the correct side → core.boundary, core.informativeness
B50: 9 | C50: Formula (6) | D50: Ψ(r) Contribution & Weight | E50: η(j) = ω(α¹ⱼ/|K1| − α²ⱼ/|K2|), Ψ(r) as contribution values → core.contributions
B51: 10 | C51: HAG, Steps 1–5 | D51: Greedy upon Weight (1-Latent) | E51: u = argmax ω, b = R + η, majorizer, θ/γ, q = argmin, stop rule → hag.hag(C, w, y, α, δ, ϰ, centres, step4_passes)
B52: 11 | C52: Meta-description Y | D52: Dataset for Meta-algorithm | E52: Y = (y₀ … y_p, r₁ … r_p), aᵢ and dᵢ → pipeline.fit(...)["A"], ["D"]
B53: 12 | C53: New object (Theorem) | D53: Brace for Meta-algorithm | E53: context relative to E without K(S) → pipeline.represent(model, x)
... B56: 15 | C56: Validation | D56: Validation | E56: workbook vs engine; template replication → tests (golden values from this workbook)
B58: Key results (live)
B59: # | C59: Figure | D59: Value | E59: Linked to
B60: 1 | C60: Permitted k (k_min = 3, k_max = 2·min|Kᵢ| − 3) | D60: ='Parameters'!$B$11 -> 3, 5 | E60: Parameters
B61: 2 | C61: Synthetic features r = |Ψ(r)| | D61: ='Parameters'!$B$14 -> 6 | E61: Parameters
B62: 3 | C62: TUPLAM (selected synthetic features, in order) | D62: ='Dataset for Meta-algorithm'!$C$13 -> {a₆, a₃, a₁, a₂, a₄} | E62: Dataset for Meta-algorithm
B63: 4 | C63: Latent (additional) features p | D63: ='Dataset for Meta-algorithm'!$C$12 -> 4 | E63: Dataset for Meta-algorithm
B64: 5 | C64: Resubstitution accuracy (Definition 2) | D64: ='Accuracy'!$H$4 -> 0.7 | E64: Accuracy
B65: 6 | C65: Leave-one-out accuracy (Definition 3) | D65: ='Accuracy'!$H$5 -> 0.2 | E65: Accuracy
...

Sheet Parameters
A1: Experiment parameters — every stage reads its settings from this sheet
A3: k range · formula-based (k_min = 3 fixed, k_max = 2 · min |Kᵢ| − 3 from the class sizes)
A4: Parameter | B4: Value | C4: Rule / meaning
A5: Objects m | B5: =COUNT(Dataset!O3:O12) -> 10 | C5: Rows S₁ … S₁₀ of the Dataset sheet
A6: |K1| (objects of class 1) | B6: =COUNTIF(Dataset!O3:O12,1) -> 4 | C6: Counted from the class column — never typed in
A7: |K2| (objects of class 2) | B7: =COUNTIF(Dataset!O3:O12,2) -> 6
A8: min |Kᵢ| | B8: =MIN(B6,B7) -> 4 | C8: Smallest class
A9: k_min | B9: 3 | C9: Fixed for every dataset
A10: k_max = 2 · min |Kᵢ| − 3 | B10: =2*B8-3 -> 5 | C10: At k = k_max a same-class majority needs (k + 1)/2 = min |Kᵢ| − 1 neighbours
A11: Permitted k (odd, k_min … k_max) | B11: =IF(ISNUMBER('Synthetic Features (k-NN)'!B4),'Synthetic Features (k-NN)'!B4&IF(ISNUMBER('Synthetic Features (k-NN)'!C4),", "&'Synthetic Features (k-NN)'!C4,""),"none") -> 3, 5
A12: Number of permitted k | B12: =IF(B10<B9,0,INT((B10-B9)/2)+1) -> 2
A13: Base operators | B13: 3 | C13: ρ, ρ_I, ρ_J — see the table below
A14: r = |Ψ(r)| (synthetic features) | B14: =B13*B12 -> 6 | C14: One synthetic feature per (operator, permitted k)
A15: Layout check | B15: =IF(B12=2,"✓ the workbook has a column for every permitted k","⚠ class sizes changed: "&B12&" permitted k, the layout has 2") -> ✓ the workbook has a column for every permitted k
A17: Hierarchical agglomerative grouping (HAG) · values of the template experiment
A18: Parameter | B18: Value | C18: Rule / meaning
A19: α (regularisation of the margin, 0 < α < 1) | B19: 0.3 | C19: Template value
A20: δ (threshold for θ / γ, 0 < δ < 0.5) | B20: 0.1 | C20: Template value
A21: ϰ (maximum |TUPLAM|) | B21: 5 | C21: =IF(B21<=B14-1,"Template value; ϰ ≤ r − 1 = "&(B14-1)&" ✓","⚠ ϰ must not exceed r − 1 = "&(B14-1)) -> Template value; ϰ ≤ r − 1 = 5 ✓
A22: cr1 (initial value of the criterion) | B22: 10 | C22: Template value
A23: Majorizing function ϕ | B23: σ(x) = 1 / (1 + e^(−x)) | C23: b ← b + α·σ(−b) for Sₜ ∈ K1, b ← b − α·σ(−b) for Sₜ ∈ K2 (logistic sigmoid, as in the template)
A24: ⚠1 Class centres in θ and γ | B24: 1 | C24: 1 = running partial class means, as computed in the template cells · 2 = final class means M₁, M₂ (article and the template formula box) · see “Template Deviations”
A25: ⚠2 Majorizer passes in STEP 4 | B25: 2 | C25: 2 = template (the majorizer is applied again to b of STEP 3) · 1 = article (R ← R + η_q, then the majorizer once) · see “Template Deviations”
A27: Base operators · the same Zhuravlev metric on different feature sets (article: variants of Ψ)
A28: Operator | B28: Feature set | C28: Definition
A29: ρ | B29: all 13 (I ∪ J) | C29: ρ(x, y) = Σ(j∈I) |x′ⱼ − y′ⱼ| + Σ(j∈J) [xⱼ ≠ yⱼ] — Zhuravlev metric
A30: ρ_I | B30: 6 quantitative (I) | C30: ρ_I(x, y) = Σ(j∈I) |x′ⱼ − y′ⱼ| — quantitative part of ρ
A31: ρ_J | B31: 7 nominal (J) | C31: ρ_J(x, y) = Σ(j∈J) [xⱼ ≠ yⱼ] — nominal part of ρ (Hamming)
A33: Other rules
A34: Tie rule | B34: smaller index first | C34: Equal distances are ordered by the original index of the neighbour
A35: Distance rounding | B35: 10 decimals | C35: So that mathematically equal distances tie exactly
A36: Positive class (evaluation) | B36: 1 | C36: Class 1 is "positive" in the confusion matrix, precision, recall and ROC
A37: Meta-algorithm decision | B37: Step 4 | C37: K1 if |B1|/|K1| > |B2|/|K2|, K2 if <, 0 = refusal if equal

Sheet Template Deviations
A1: Template Deviations — where the template HAG calculations differ from the article, and what each one changes
A3: Template workbook: hag-regularized-stacking-boosting-meta\resources\experiments\hag-algorithm\RegularizedStackingEnsembleWithHAG [My Experiment on Heart-Disease (10, 13, 2)].xlsx (the “- Opus 5.5” copy has the same cells). In this workbook both calculations are switches on the Parameters sheet; the default reproduces the template exactly.
A5: ⚠1 · θ and γ are measured from running partial class means instead of the final class means M₁ and M₂
A6: Article, HAG Step 3: M₁ = Σ(Sₜ∈K1) bₜ / |K1|, M₂ = Σ(Sₜ∈K2) bₜ / |K2| are computed over all objects first; then θ = Σ |bₜ − M(own class)|, γ = Σ |bₜ − M(other class)|. The template’s own formula boxes show the same final means (sheet “Greedy upon Weight (1-Latent)”, boxes at AB2 and AB6).
A7: Template cells (first candidate block, rows 32–41 of “Greedy upon Weight (1-Latent)”): I32 = IF(G32=1, H32 + N(I31), N(I31)) is a running sum; K32 = I32 / COUNTIF($G$32:$G$41, 1) is therefore the mean of the rows up to 32 only; M32 = M31 + ABS(H32 − IF(G32=1, K32, L32)) uses that running mean (N32 likewise). Only the last row (K41, L41) holds the real means M₁ and M₂. The same pattern is in every candidate block of all four “Greedy upon Weight (n-Latent)” sheets (columns I–N).
A8: Worked example (template data, iteration 1, candidate x₁, object S₁ ∈ K2 with bₜ = 0.2766): running M₂ at S₁’s row = 0.0461 → |bₜ − M₂| = 0.2305; final M₂ = -0.5991 → |bₜ − M₂| = 0.8757. Summed over all objects: θ = 3.5549, γ = 9.3403 (template, θ/γ = 0.3806) vs θ = 2.1192, γ = 12.0884 (article, θ/γ = 0.1753).
A10: Iteration 1 on the template data (R = η₃ of x₃) | B10: θ running | C10: γ running | D10: θ/γ running (template) | E10: θ final | F10: γ final | G10: θ/γ final (article) | H10: M₁ final | I10: M₂ final
A11: x₁ | B11: 3.5549167 | C11: 9.3403133 | D11: 0.3805993 | E11: 2.1192458 | F11: 12.088406 | G11: 0.17531226 | H11: 0.60973484 | I11: -0.59910578
A12: x₂ | B12: 1.9639069 | C12: 3.3940148 | D12: 0.57863829 | E12: 1.6273712 | F12: 4.426876 | G12: 0.36761166 | H12: 0.11945182 | I12: -0.32323578
A13: x₄ | B13: 2.2301907 | C13: 4.9447478 | D13: 0.45102213 | E13: 1.7940032 | F13: 6.2412343 | G13: 0.28744366 | H13: 0.23084189 | I13: -0.39328154
A14: x₅ | B14: 1.0481607 | C14: 2.7701296 | D14: 0.37837967 | E14: 0.83433639 | F14: 3.7318333 | G14: 0.22357279 | H14: 0.094700341 | I14: -0.27848299
A15: x₆ | B15: 0.9681974 | C15: 2.7222258 | D15: 0.35566388 | E15: 0.72117188 | F15: 3.5585009 | G15: 0.20266171 | H15: 0.18801433 | I15: -0.16783577
A16: x₇ | B16: 1.4288975 | C16: 3.2840249 | D16: 0.43510556 | E16: 1.1389012 | F16: 4.4271068 | G16: 0.25725631 | H16: 0.11948643 | I16: -0.32322425
A17: x₈ | B17: 1.754685 | C17: 4.4070579 | D17: 0.39815338 | E17: 1.4273433 | F17: 6.2415223 | G17: 0.22868513 | H17: 0.2308707 | I17: -0.39328154
A18: x₉ | B18: 1.2130201 | C18: 2.7380551 | D18: 0.44302251 | E18: 1.0219503 | F18: 3.5957778 | G18: 0.28420841 | H18: 0.11947982 | I18: -0.24009796
A19: x₁₀ | B19: 2.1511232 | C19: 4.8456475 | D19: 0.44392896 | E19: 1.7415683 | F19: 6.2413303 | G19: 0.279038 | H19: 0.2308707 | I19: -0.39326233
A20: x₁₁ | B20: 1.6897176 | C20: 3.3689108 | D20: 0.50156198 | E20: 1.5052295 | F20: 4.4269337 | G20: 0.34001628 | H20: 0.11946913 | I20: -0.32322425
A21: x₁₂ | B21: 1.3952807 | C21: 3.0165013 | D21: 0.46254936 | E21: 1.2063927 | F21: 4.0860579 | G21: 0.2952461 | H21: 0.11947603 | I21: -0.28912976
A22: x₁₃ | B22: 0.98604289 | C22: 2.7598651 | D22: 0.35727938 | E22: 0.71515295 | F22: 3.6395965 | G22: 0.19649237 | H22: 0.17569967 | I22: -0.18825999
A23: Selected q (green): template (running) → x₆ with θ/γ = 0.3557; article (final) → x₁ with θ/γ = 0.1753. The whole SET then changes — see the effect table below.
A24: Fix in the template (if the article is right): in every block use the last-row means, e.g. M32 = IF(ROW()=32, 0, M31) + ABS(H32 − IF($G32=1, $K$41, $L$41)) and N32 = IF(ROW()=32, 0, N31) + ABS(H32 − IF($G32=1, $L$41, $K$41)), copied down to row 41 (and the same in every block).
A25: In this workbook: the orange columns I–L (“Σ K1/K2 (running)”, “M₁/M₂ used”) of every candidate block on the four “Greedy upon Weight” sheets; switch Parameters!B24 (1 = running = template, 2 = final = article).
A27: ⚠2 · In STEP 4 the majorizer is applied twice instead of once
A28: Article, HAG Step 4: R(Sₜ) ← R(Sₜ) + η_q(a_tq); then R(Sₜ) ← R(Sₜ) + α·ϕ(−R(Sₜ)) for Sₜ ∈ K1 (− α·ϕ(−R) for K2) — one application of the majorizer to R + η_q.
A29: Template cells (STEP 4 block, rows 222–231 of “Greedy upon Weight (1-Latent)”): F222 = R + η_q; H222 = F222 ± α·σ(−F222) (once — this equals the STEP 3 value of the chosen candidate); I222 = H222 ± α·σ(−H222) (twice); K222 = I222 → r₁. Same in 2-Latent rows 207–216, 3-Latent rows 192–201, 4-Latent rows 177–186. Because the next iteration starts from this R, every latent feature receives the extra push.
A31: r₁ on the template data (q = x₆) | B31: R + η_q (F) | C31: once — article (H) | D31: twice — template (I = K) | E31: template file K222…K231 | F31: Class
A32: S₁ | B32: -0.05787037 | C32: -0.21220944 | D32: -0.37806569 | E32: -0.37806569 | F32: 2
A33: S₂ | B33: 0.1400463 | C33: 0.27955996 | D33: 0.40872846 | E33: 0.40872846 | F33: 1
A34: S₃ | B34: 0.1400463 | C34: 0.0005326351 | D34: -0.14942742 | E34: -0.14942742 | F34: 2
A35: S₄ | B35: -0.05787037 | C35: 0.096468697 | D35: 0.23923915 | E35: 0.23923915 | F35: 1
A36: S₅ | B36: 0.1400463 | C36: 0.27955996 | D36: 0.40872846 | E36: 0.40872846 | F36: 1
A37: S₆ | B37: -0.05787037 | C37: 0.096468697 | D37: 0.23923915 | E37: 0.23923915 | F37: 1
A38: S₇ | B38: -0.0081018519 | C38: -0.15870949 | D38: -0.32058778 | E38: -0.32058778 | F38: 2
A39: S₈ | B39: -0.05787037 | C39: -0.21220944 | D39: -0.37806569 | E39: -0.37806569 | F39: 2
A40: S₉ | B40: -0.05787037 | C40: -0.21220944 | D40: -0.37806569 | E40: -0.37806569 | F40: 2
A41: S₁₀ | B41: -0.05787037 | C41: -0.21220944 | D41: -0.37806569 | E41: -0.37806569 | F41: 2
A42: Fix in the template (if the article is right): take the latent value from column H — K222 = H222 (and the same in the other STEP 4 blocks) — or equivalently skip the second majorizer.
A43: In this workbook: the pink columns H–I of the STEP 4 block on the four “Greedy upon Weight” sheets; switch Parameters!B25 (2 = twice = template, 1 = once = article).
A45: Effect of the two switches
A46: Template data (13 original features) | B46: Class centres | C46: STEP 4 passes | D46: SET | E46: max |r − template r|
...

Sheet Dataset
A1: Heart + Disease (10, 13, 2)
A2: № | O2: Class | Q2: K1 = 4
B3: 70 | C3: 1 | D3: 4 | E3: 130 | F3: 322 | G3: 0 | H3: 2 | I3: 109 | J3: 0 | K3: 2.4 | L3: 2 | M3: 3 | N3: 3 | O3: 2 | Q3: K2 = 6
B4: 67 | C4: 0 | D4: 3 | E4: 115 | F4: 564 | G4: 0 | H4: 2 | I4: 160 | J4: 0 | K4: 1.6 | L4: 2 | M4: 0 | N4: 7 | O4: 1
B5: 57 | C5: 1 | D5: 2 | E5: 124 | F5: 261 | G5: 0 | H5: 0 | I5: 141 | J5: 0 | K5: 0.3 | L5: 1 | M5: 0 | N5: 7 | O5: 2 | Q5: Sign of Quantitative Features - | T5: 1
B6: 64 | C6: 1 | D6: 4 | E6: 128 | F6: 263 | G6: 0 | H6: 0 | I6: 105 | J6: 1 | K6: 0.2 | L6: 2 | M6: 1 | N6: 7 | O6: 1 | Q6: Sign of Nominal Features - | T6: 0
B7: 74 | C7: 0 | D7: 2 | E7: 120 | F7: 269 | G7: 0 | H7: 2 | I7: 121 | J7: 1 | K7: 0.2 | L7: 1 | M7: 1 | N7: 3 | O7: 1
B8: 65 | C8: 1 | D8: 4 | E8: 120 | F8: 177 | G8: 0 | H8: 0 | I8: 140 | J8: 0 | K8: 0.4 | L8: 1 | M8: 0 | N8: 7 | O8: 1
B9: 56 | C9: 1 | D9: 3 | E9: 130 | F9: 256 | G9: 1 | H9: 2 | I9: 142 | J9: 1 | K9: 0.6 | L9: 2 | M9: 1 | N9: 6 | O9: 2
B10: 59 | C10: 1 | D10: 4 | E10: 110 | F10: 239 | G10: 0 | H10: 2 | I10: 142 | J10: 1 | K10: 1.2 | L10: 2 | M10: 1 | N10: 7 | O10: 2
B11: 60 | C11: 1 | D11: 4 | E11: 140 | F11: 293 | G11: 0 | H11: 2 | I11: 170 | J11: 0 | K11: 1.2 | L11: 2 | M11: 2 | N11: 7 | O11: 2
B12: 63 | C12: 0 | D12: 4 | E12: 150 | F12: 407 | G12: 0 | H12: 2 | I12: 154 | J12: 0 | K12: 4 | L12: 2 | M12: 3 | N12: 7 | O12: 2
B13: 1 | C13: 0 | D13: 0 | E13: 1 | F13: 1 | G13: 0 | H13: 0 | I13: 1 | J13: 0 | K13: 1 | L13: 0 | M13: 1 | N13: 0
B17: Total Number of Quantitative Features - | F17: 6 | L17: Total Number of Nominal Features - | P17: 7
A19: Quantitative Features | K19: Nominal Features
A20: № | H20: Class | K20: № | S20: Class
B21: 70 | C21: 130 | D21: 322 | E21: 109 | F21: 2.4 | G21: 3 | H21: 2 | L21: 1 | M21: 4 | N21: 0 | O21: 2 | P21: 0 | Q21: 2 | R21: 3 | S21: 2
B22: 67 | C22: 115 | D22: 564 | E22: 160 | F22: 1.6 | G22: 0 | H22: 1 | L22: 0 | M22: 3 | N22: 0 | O22: 2 | P22: 0 | Q22: 2 | R22: 7 | S22: 1
B23: 57 | C23: 124 | D23: 261 | E23: 141 | F23: 0.3 | G23: 0 | H23: 2 | L23: 1 | M23: 2 | N23: 0 | O23: 0 | P23: 0 | Q23: 1 | R23: 7 | S23: 2
B24: 64 | C24: 128 | D24: 263 | E24: 105 | F24: 0.2 | G24: 1 | H24: 1 | L24: 1 | M24: 4 | N24: 0 | O24: 0 | P24: 1 | Q24: 2 | R24: 7 | S24: 1
B25: 74 | C25: 120 | D25: 269 | E25: 121 | F25: 0.2 | G25: 1 | H25: 1 | L25: 0 | M25: 2 | N25: 0 | O25: 2 | P25: 1 | Q25: 1 | R25: 3 | S25: 1
B26: 65 | C26: 120 | D26: 177 | E26: 140 | F26: 0.4 | G26: 0 | H26: 1 | L26: 1 | M26: 4 | N26: 0 | O26: 0 | P26: 0 | Q26: 1 | R26: 7 | S26: 1
B27: 56 | C27: 130 | D27: 256 | E27: 142 | F27: 0.6 | G27: 1 | H27: 2 | L27: 1 | M27: 3 | N27: 1 | O27: 2 | P27: 1 | Q27: 2 | R27: 6 | S27: 2
B28: 59 | C28: 110 | D28: 239 | E28: 142 | F28: 1.2 | G28: 1 | H28: 2 | L28: 1 | M28: 4 | N28: 0 | O28: 2 | P28: 1 | Q28: 2 | R28: 7 | S28: 2
B29: 60 | C29: 140 | D29: 293 | E29: 170 | F29: 1.2 | G29: 2 | H29: 2 | L29: 1 | M29: 4 | N29: 0 | O29: 2 | P29: 0 | Q29: 2 | R29: 7 | S29: 2
B30: 63 | C30: 150 | D30: 407 | E30: 154 | F30: 4 | G30: 3 | H30: 2 | L30: 0 | M30: 4 | N30: 0 | O30: 2 | P30: 0 | Q30: 2 | R30: 7 | S30: 2
B31: 1 | C31: 1 | D31: 1 | E31: 1 | F31: 1 | G31: 1 | L31: 0 | M31: 0 | N31: 0 | O31: 0 | P31: 0 | Q31: 0 | R31: 0

Sheet Quantitative
A1: Quantitative Features
A2: № | H2: Class | K2: K1 = 4
B3: 70 | C3: 130 | D3: 322 | E3: 109 | F3: 2.4 | G3: 3 | H3: 2 | K3: K2 = 6 | M3: Color and Sign of Quantitative Features - | Q3: 1
B4: 67 | C4: 115 | D4: 564 | E4: 160 | F4: 1.6 | G4: 0 | H4: 1
B5: 57 | C5: 124 | D5: 261 | E5: 141 | F5: 0.3 | G5: 0 | H5: 2
B6: 64 | C6: 128 | D6: 263 | E6: 105 | F6: 0.2 | G6: 1 | H6: 1
B7: 74 | C7: 120 | D7: 269 | E7: 121 | F7: 0.2 | G7: 1 | H7: 1
B8: 65 | C8: 120 | D8: 177 | E8: 140 | F8: 0.4 | G8: 0 | H8: 1
B9: 56 | C9: 130 | D9: 256 | E9: 142 | F9: 0.6 | G9: 1 | H9: 2
B10: 59 | C10: 110 | D10: 239 | E10: 142 | F10: 1.2 | G10: 1 | H10: 2
B11: 60 | C11: 140 | D11: 293 | E11: 170 | F11: 1.2 | G11: 2 | H11: 2
B12: 63 | C12: 150 | D12: 407 | E12: 154 | F12: 4 | G12: 3 | H12: 2
B13: 1 | C13: 1 | D13: 1 | E13: 1 | F13: 1 | G13: 1

Sheet Nominal
A1: Nominal Features
A2: № | I2: Class | L2: K1 = 4
B3: 1 | C3: 4 | D3: 0 | E3: 2 | F3: 0 | G3: 2 | H3: 3 | I3: 2 | L3: K2 = 6 | N3: Color and Sign of Nominal Features - | R3: 0
B4: 0 | C4: 3 | D4: 0 | E4: 2 | F4: 0 | G4: 2 | H4: 7 | I4: 1
B5: 1 | C5: 2 | D5: 0 | E5: 0 | F5: 0 | G5: 1 | H5: 7 | I5: 2
B6: 1 | C6: 4 | D6: 0 | E6: 0 | F6: 1 | G6: 2 | H6: 7 | I6: 1
B7: 0 | C7: 2 | D7: 0 | E7: 2 | F7: 1 | G7: 1 | H7: 3 | I7: 1
B8: 1 | C8: 4 | D8: 0 | E8: 0 | F8: 0 | G8: 1 | H8: 7 | I8: 1
B9: 1 | C9: 3 | D9: 1 | E9: 2 | F9: 1 | G9: 2 | H9: 6 | I9: 2
B10: 1 | C10: 4 | D10: 0 | E10: 2 | F10: 1 | G10: 2 | H10: 7 | I10: 2
B11: 1 | C11: 4 | D11: 0 | E11: 2 | F11: 0 | G11: 2 | H11: 7 | I11: 2
B12: 0 | C12: 4 | D12: 0 | E12: 2 | F12: 0 | G12: 2 | H12: 7 | I12: 2
B13: 0 | C13: 0 | D13: 0 | E13: 0 | F13: 0 | G13: 0 | H13: 0

Sheet Normalized Dataset
A1: Step 1 · Normalized dataset — quantitative features mapped to [0, 1], nominal features unchanged
A3: Heart + Disease (10, 13, 2) after scale unification: x′ = (x − min) / (max − min) for j ∈ I
A4: № | B4: x₁ | C4: x₂ | D4: x₃ | E4: x₄ | F4: x₅ | G4: x₆ | H4: x₇ | I4: x₈ | J4: x₉ | K4: x₁₀ | L4: x₁₁ | M4: x₁₂ | N4: x₁₃ | O4: Class
A5: S₁ | B5: =IF(MAX(Dataset!B$3:B$12)=MIN(Dataset!B$3:B$12),0,(Dataset!B3-MIN(Dataset!B$3:B$12))/(MAX(Dataset!B$3:B$12)-MIN(Dataset!B$3:B$12))) -> 0.77777778 | C5: =Dataset!C3 -> 1 | D5: =Dataset!D3 -> 4 | E5: =IF(MAX(Dataset!E$3:E$12)=MIN(Dataset!E$3:E$12),0,(Dataset!E3-MIN(Dataset!E$3:E$12))/(MAX(Dataset!E$3:E$12)-MIN(Dataset!E$3:E$12))) -> 0.5 | F5: =IF(MAX(Dataset!F$3:F$12)=MIN(Dataset!F$3:F$12),0,(Dataset!F3-MIN(Dataset!F$3:F$12))/(MAX(Dataset!F$3:F$12)-MIN(Dataset!F$3:F$12))) -> 0.374677 | G5: =Dataset!G3 -> 0 | H5: =Dataset!H3 -> 2 | I5: =IF(MAX(Dataset!I$3:I$12)=MIN(Dataset!I$3:I$12),0,(Dataset!I3-MIN(Dataset!I$3:I$12))/(MAX(Dataset!I$3:I$12)-MIN(Dataset!I$3:I$12))) -> 0.061538462 | J5: =Dataset!J3 -> 0 | K5: =IF(MAX(Dataset!K$3:K$12)=MIN(Dataset!K$3:K$12),0,(Dataset!K3-MIN(Dataset!K$3:K$12))/(MAX(Dataset!K$3:K$12)-MIN(Dataset!K$3:K$12))) -> 0.57894737 | L5: =Dataset!L3 -> 2 | M5: =IF(MAX(Dataset!M$3:M$12)=MIN(Dataset!M$3:M$12),0,(Dataset!M3-MIN(Dataset!M$3:M$12))/(MAX(Dataset!M$3:M$12)-MIN(Dataset!M$3:M$12))) -> 1 | N5: =Dataset!N3 -> 3 | O5: =Dataset!O3 -> 2
A6: S₂ | B6: =IF(MAX(Dataset!B$3:B$12)=MIN(Dataset!B$3:B$12),0,(Dataset!B4-MIN(Dataset!B$3:B$12))/(MAX(Dataset!B$3:B$12)-MIN(Dataset!B$3:B$12))) -> 0.61111111 | C6: =Dataset!C4 -> 0 | D6: =Dataset!D4 -> 3 | E6: =IF(MAX(Dataset!E$3:E$12)=MIN(Dataset!E$3:E$12),0,(Dataset!E4-MIN(Dataset!E$3:E$12))/(MAX(Dataset!E$3:E$12)-MIN(Dataset!E$3:E$12))) -> 0.125 | F6: =IF(MAX(Dataset!F$3:F$12)=MIN(Dataset!F$3:F$12),0,(Dataset!F4-MIN(Dataset!F$3:F$12))/(MAX(Dataset!F$3:F$12)-MIN(Dataset!F$3:F$12))) -> 1 | G6: =Dataset!G4 -> 0 | H6: =Dataset!H4 -> 2 | I6: =IF(MAX(Dataset!I$3:I$12)=MIN(Dataset!I$3:I$12),0,(Dataset!I4-MIN(Dataset!I$3:I$12))/(MAX(Dataset!I$3:I$12)-MIN(Dataset!I$3:I$12))) -> 0.84615385 | J6: =Dataset!J4 -> 0 | K6: =IF(MAX(Dataset!K$3:K$12)=MIN(Dataset!K$3:K$12),0,(Dataset!K4-MIN(Dataset!K$3:K$12))/(MAX(Dataset!K$3:K$12)-MIN(Dataset!K$3:K$12))) -> 0.36842105 | L6: =Dataset!L4 -> 2 | M6: =IF(MAX(Dataset!M$3:M$12)=MIN(Dataset!M$3:M$12),0,(Dataset!M4-MIN(Dataset!M$3:M$12))/(MAX(Dataset!M$3:M$12)-MIN(Dataset!M$3:M$12))) -> 0 | N6: =Dataset!N4 -> 7 | O6: =Dataset!O4 -> 1
A7: S₃ | B7: =IF(MAX(Dataset!B$3:B$12)=MIN(Dataset!B$3:B$12),0,(Dataset!B5-MIN(Dataset!B$3:B$12))/(MAX(Dataset!B$3:B$12)-MIN(Dataset!B$3:B$12))) -> 0.055555556 | C7: =Dataset!C5 -> 1 | D7: =Dataset!D5 -> 2 | E7: =IF(MAX(Dataset!E$3:E$12)=MIN(Dataset!E$3:E$12),0,(Dataset!E5-MIN(Dataset!E$3:E$12))/(MAX(Dataset!E$3:E$12)-MIN(Dataset!E$3:E$12))) -> 0.35 | F7: =IF(MAX(Dataset!F$3:F$12)=MIN(Dataset!F$3:F$12),0,(Dataset!F5-MIN(Dataset!F$3:F$12))/(MAX(Dataset!F$3:F$12)-MIN(Dataset!F$3:F$12))) -> 0.21705426 | G7: =Dataset!G5 -> 0 | H7: =Dataset!H5 -> 0 | I7: =IF(MAX(Dataset!I$3:I$12)=MIN(Dataset!I$3:I$12),0,(Dataset!I5-MIN(Dataset!I$3:I$12))/(MAX(Dataset!I$3:I$12)-MIN(Dataset!I$3:I$12))) -> 0.55384615 | J7: =Dataset!J5 -> 0 | K7: =IF(MAX(Dataset!K$3:K$12)=MIN(Dataset!K$3:K$12),0,(Dataset!K5-MIN(Dataset!K$3:K$12))/(MAX(Dataset!K$3:K$12)-MIN(Dataset!K$3:K$12))) -> 0.026315789 | L7: =Dataset!L5 -> 1 | M7: =IF(MAX(Dataset!M$3:M$12)=MIN(Dataset!M$3:M$12),0,(Dataset!M5-MIN(Dataset!M$3:M$12))/(MAX(Dataset!M$3:M$12)-MIN(Dataset!M$3:M$12))) -> 0 | N7: =Dataset!N5 -> 7 | O7: =Dataset!O5 -> 2
A8: S₄ | B8: =IF(MAX(Dataset!B$3:B$12)=MIN(Dataset!B$3:B$12),0,(Dataset!B6-MIN(Dataset!B$3:B$12))/(MAX(Dataset!B$3:B$12)-MIN(Dataset!B$3:B$12))) -> 0.44444444 | C8: =Dataset!C6 -> 1 | D8: =Dataset!D6 -> 4 | E8: =IF(MAX(Dataset!E$3:E$12)=MIN(Dataset!E$3:E$12),0,(Dataset!E6-MIN(Dataset!E$3:E$12))/(MAX(Dataset!E$3:E$12)-MIN(Dataset!E$3:E$12))) -> 0.45 | F8: =IF(MAX(Dataset!F$3:F$12)=MIN(Dataset!F$3:F$12),0,(Dataset!F6-MIN(Dataset!F$3:F$12))/(MAX(Dataset!F$3:F$12)-MIN(Dataset!F$3:F$12))) -> 0.22222222 | G8: =Dataset!G6 -> 0 | H8: =Dataset!H6 -> 0 | I8: =IF(MAX(Dataset!I$3:I$12)=MIN(Dataset!I$3:I$12),0,(Dataset!I6-MIN(Dataset!I$3:I$12))/(MAX(Dataset!I$3:I$12)-MIN(Dataset!I$3:I$12))) -> 0 | J8: =Dataset!J6 -> 1 | K8: =IF(MAX(Dataset!K$3:K$12)=MIN(Dataset!K$3:K$12),0,(Dataset!K6-MIN(Dataset!K$3:K$12))/(MAX(Dataset!K$3:K$12)-MIN(Dataset!K$3:K$12))) -> 0 | L8: =Dataset!L6 -> 2 | M8: =IF(MAX(Dataset!M$3:M$12)=MIN(Dataset!M$3:M$12),0,(Dataset!M6-MIN(Dataset!M$3:M$12))/(MAX(Dataset!M$3:M$12)-MIN(Dataset!M$3:M$12))) -> 0.33333333 | N8: =Dataset!N6 -> 7 | O8: =Dataset!O6 -> 1
A9: S₅ | B9: =IF(MAX(Dataset!B$3:B$12)=MIN(Dataset!B$3:B$12),0,(Dataset!B7-MIN(Dataset!B$3:B$12))/(MAX(Dataset!B$3:B$12)-MIN(Dataset!B$3:B$12))) -> 1 | C9: =Dataset!C7 -> 0 | D9: =Dataset!D7 -> 2 | E9: =IF(MAX(Dataset!E$3:E$12)=MIN(Dataset!E$3:E$12),0,(Dataset!E7-MIN(Dataset!E$3:E$12))/(MAX(Dataset!E$3:E$12)-MIN(Dataset!E$3:E$12))) -> 0.25 | F9: =IF(MAX(Dataset!F$3:F$12)=MIN(Dataset!F$3:F$12),0,(Dataset!F7-MIN(Dataset!F$3:F$12))/(MAX(Dataset!F$3:F$12)-MIN(Dataset!F$3:F$12))) -> 0.2377261 | G9: =Dataset!G7 -> 0 | H9: =Dataset!H7 -> 2 | I9: =IF(MAX(Dataset!I$3:I$12)=MIN(Dataset!I$3:I$12),0,(Dataset!I7-MIN(Dataset!I$3:I$12))/(MAX(Dataset!I$3:I$12)-MIN(Dataset!I$3:I$12))) -> 0.24615385 | J9: =Dataset!J7 -> 1 | K9: =IF(MAX(Dataset!K$3:K$12)=MIN(Dataset!K$3:K$12),0,(Dataset!K7-MIN(Dataset!K$3:K$12))/(MAX(Dataset!K$3:K$12)-MIN(Dataset!K$3:K$12))) -> 0 | L9: =Dataset!L7 -> 1 | M9: =IF(MAX(Dataset!M$3:M$12)=MIN(Dataset!M$3:M$12),0,(Dataset!M7-MIN(Dataset!M$3:M$12))/(MAX(Dataset!M$3:M$12)-MIN(Dataset!M$3:M$12))) -> 0.33333333 | N9: =Dataset!N7 -> 3 | O9: =Dataset!O7 -> 1
A10: S₆ | B10: =IF(MAX(Dataset!B$3:B$12)=MIN(Dataset!B$3:B$12),0,(Dataset!B8-MIN(Dataset!B$3:B$12))/(MAX(Dataset!B$3:B$12)-MIN(Dataset!B$3:B$12))) -> 0.5 | C10: =Dataset!C8 -> 1 | D10: =Dataset!D8 -> 4 | E10: =IF(MAX(Dataset!E$3:E$12)=MIN(Dataset!E$3:E$12),0,(Dataset!E8-MIN(Dataset!E$3:E$12))/(MAX(Dataset!E$3:E$12)-MIN(Dataset!E$3:E$12))) -> 0.25 | F10: =IF(MAX(Dataset!F$3:F$12)=MIN(Dataset!F$3:F$12),0,(Dataset!F8-MIN(Dataset!F$3:F$12))/(MAX(Dataset!F$3:F$12)-MIN(Dataset!F$3:F$12))) -> 0 | G10: =Dataset!G8 -> 0 | H10: =Dataset!H8 -> 0 | I10: =IF(MAX(Dataset!I$3:I$12)=MIN(Dataset!I$3:I$12),0,(Dataset!I8-MIN(Dataset!I$3:I$12))/(MAX(Dataset!I$3:I$12)-MIN(Dataset!I$3:I$12))) -> 0.53846154 | J10: =Dataset!J8 -> 0 | K10: =IF(MAX(Dataset!K$3:K$12)=MIN(Dataset!K$3:K$12),0,(Dataset!K8-MIN(Dataset!K$3:K$12))/(MAX(Dataset!K$3:K$12)-MIN(Dataset!K$3:K$12))) -> 0.052631579 | L10: =Dataset!L8 -> 1 | M10: =IF(MAX(Dataset!M$3:M$12)=MIN(Dataset!M$3:M$12),0,(Dataset!M8-MIN(Dataset!M$3:M$12))/(MAX(Dataset!M$3:M$12)-MIN(Dataset!M$3:M$12))) -> 0 | N10: =Dataset!N8 -> 7 | O10: =Dataset!O8 -> 1
A11: S₇ | B11: =IF(MAX(Dataset!B$3:B$12)=MIN(Dataset!B$3:B$12),0,(Dataset!B9-MIN(Dataset!B$3:B$12))/(MAX(Dataset!B$3:B$12)-MIN(Dataset!B$3:B$12))) -> 0 | C11: =Dataset!C9 -> 1 | D11: =Dataset!D9 -> 3 | E11: =IF(MAX(Dataset!E$3:E$12)=MIN(Dataset!E$3:E$12),0,(Dataset!E9-MIN(Dataset!E$3:E$12))/(MAX(Dataset!E$3:E$12)-MIN(Dataset!E$3:E$12))) -> 0.5 | F11: =IF(MAX(Dataset!F$3:F$12)=MIN(Dataset!F$3:F$12),0,(Dataset!F9-MIN(Dataset!F$3:F$12))/(MAX(Dataset!F$3:F$12)-MIN(Dataset!F$3:F$12))) -> 0.20413437 | G11: =Dataset!G9 -> 1 | H11: =Dataset!H9 -> 2 | I11: =IF(MAX(Dataset!I$3:I$12)=MIN(Dataset!I$3:I$12),0,(Dataset!I9-MIN(Dataset!I$3:I$12))/(MAX(Dataset!I$3:I$12)-MIN(Dataset!I$3:I$12))) -> 0.56923077 | J11: =Dataset!J9 -> 1 | K11: =IF(MAX(Dataset!K$3:K$12)=MIN(Dataset!K$3:K$12),0,(Dataset!K9-MIN(Dataset!K$3:K$12))/(MAX(Dataset!K$3:K$12)-MIN(Dataset!K$3:K$12))) -> 0.10526316 | L11: =Dataset!L9 -> 2 | M11: =IF(MAX(Dataset!M$3:M$12)=MIN(Dataset!M$3:M$12),0,(Dataset!M9-MIN(Dataset!M$3:M$12))/(MAX(Dataset!M$3:M$12)-MIN(Dataset!M$3:M$12))) -> 0.33333333 | N11: =Dataset!N9 -> 6 | O11: =Dataset!O9 -> 2
A12: S₈ | B12: =IF(MAX(Dataset!B$3:B$12)=MIN(Dataset!B$3:B$12),0,(Dataset!B10-MIN(Dataset!B$3:B$12))/(MAX(Dataset!B$3:B$12)-MIN(Dataset!B$3:B$12))) -> 0.16666667 | C12: =Dataset!C10 -> 1 | D12: =Dataset!D10 -> 4 | E12: =IF(MAX(Dataset!E$3:E$12)=MIN(Dataset!E$3:E$12),0,(Dataset!E10-MIN(Dataset!E$3:E$12))/(MAX(Dataset!E$3:E$12)-MIN(Dataset!E$3:E$12))) -> 0 | F12: =IF(MAX(Dataset!F$3:F$12)=MIN(Dataset!F$3:F$12),0,(Dataset!F10-MIN(Dataset!F$3:F$12))/(MAX(Dataset!F$3:F$12)-MIN(Dataset!F$3:F$12))) -> 0.16020672 | G12: =Dataset!G10 -> 0 | H12: =Dataset!H10 -> 2 | I12: =IF(MAX(Dataset!I$3:I$12)=MIN(Dataset!I$3:I$12),0,(Dataset!I10-MIN(Dataset!I$3:I$12))/(MAX(Dataset!I$3:I$12)-MIN(Dataset!I$3:I$12))) -> 0.56923077 | J12: =Dataset!J10 -> 1 | K12: =IF(MAX(Dataset!K$3:K$12)=MIN(Dataset!K$3:K$12),0,(Dataset!K10-MIN(Dataset!K$3:K$12))/(MAX(Dataset!K$3:K$12)-MIN(Dataset!K$3:K$12))) -> 0.26315789 | L12: =Dataset!L10 -> 2 | M12: =IF(MAX(Dataset!M$3:M$12)=MIN(Dataset!M$3:M$12),0,(Dataset!M10-MIN(Dataset!M$3:M$12))/(MAX(Dataset!M$3:M$12)-MIN(Dataset!M$3:M$12))) -> 0.33333333 | N12: =Dataset!N10 -> 7 | O12: =Dataset!O10 -> 2
A13: S₉ | B13: =IF(MAX(Dataset!B$3:B$12)=MIN(Dataset!B$3:B$12),0,(Dataset!B11-MIN(Dataset!B$3:B$12))/(MAX(Dataset!B$3:B$12)-MIN(Dataset!B$3:B$12))) -> 0.22222222 | C13: =Dataset!C11 -> 1 | D13: =Dataset!D11 -> 4 | E13: =IF(MAX(Dataset!E$3:E$12)=MIN(Dataset!E$3:E$12),0,(Dataset!E11-MIN(Dataset!E$3:E$12))/(MAX(Dataset!E$3:E$12)-MIN(Dataset!E$3:E$12))) -> 0.75 | F13: =IF(MAX(Dataset!F$3:F$12)=MIN(Dataset!F$3:F$12),0,(Dataset!F11-MIN(Dataset!F$3:F$12))/(MAX(Dataset!F$3:F$12)-MIN(Dataset!F$3:F$12))) -> 0.2997416 | G13: =Dataset!G11 -> 0 | H13: =Dataset!H11 -> 2 | I13: =IF(MAX(Dataset!I$3:I$12)=MIN(Dataset!I$3:I$12),0,(Dataset!I11-MIN(Dataset!I$3:I$12))/(MAX(Dataset!I$3:I$12)-MIN(Dataset!I$3:I$12))) -> 1 | J13: =Dataset!J11 -> 0 | K13: =IF(MAX(Dataset!K$3:K$12)=MIN(Dataset!K$3:K$12),0,(Dataset!K11-MIN(Dataset!K$3:K$12))/(MAX(Dataset!K$3:K$12)-MIN(Dataset!K$3:K$12))) -> 0.26315789 | L13: =Dataset!L11 -> 2 | M13: =IF(MAX(Dataset!M$3:M$12)=MIN(Dataset!M$3:M$12),0,(Dataset!M11-MIN(Dataset!M$3:M$12))/(MAX(Dataset!M$3:M$12)-MIN(Dataset!M$3:M$12))) -> 0.66666667 | N13: =Dataset!N11 -> 7 | O13: =Dataset!O11 -> 2
A14: S₁₀ | B14: =IF(MAX(Dataset!B$3:B$12)=MIN(Dataset!B$3:B$12),0,(Dataset!B12-MIN(Dataset!B$3:B$12))/(MAX(Dataset!B$3:B$12)-MIN(Dataset!B$3:B$12))) -> 0.38888889 | C14: =Dataset!C12 -> 0 | D14: =Dataset!D12 -> 4 | E14: =IF(MAX(Dataset!E$3:E$12)=MIN(Dataset!E$3:E$12),0,(Dataset!E12-MIN(Dataset!E$3:E$12))/(MAX(Dataset!E$3:E$12)-MIN(Dataset!E$3:E$12))) -> 1 | F14: =IF(MAX(Dataset!F$3:F$12)=MIN(Dataset!F$3:F$12),0,(Dataset!F12-MIN(Dataset!F$3:F$12))/(MAX(Dataset!F$3:F$12)-MIN(Dataset!F$3:F$12))) -> 0.59431525 | G14: =Dataset!G12 -> 0 | H14: =Dataset!H12 -> 2 | I14: =IF(MAX(Dataset!I$3:I$12)=MIN(Dataset!I$3:I$12),0,(Dataset!I12-MIN(Dataset!I$3:I$12))/(MAX(Dataset!I$3:I$12)-MIN(Dataset!I$3:I$12))) -> 0.75384615 | J14: =Dataset!J12 -> 0 | K14: =IF(MAX(Dataset!K$3:K$12)=MIN(Dataset!K$3:K$12),0,(Dataset!K12-MIN(Dataset!K$3:K$12))/(MAX(Dataset!K$3:K$12)-MIN(Dataset!K$3:K$12))) -> 1 | L14: =Dataset!L12 -> 2 | M14: =IF(MAX(Dataset!M$3:M$12)=MIN(Dataset!M$3:M$12),0,(Dataset!M12-MIN(Dataset!M$3:M$12))/(MAX(Dataset!M$3:M$12)-MIN(Dataset!M$3:M$12))) -> 1 | N14: =Dataset!N12 -> 7 | O14: =Dataset!O12 -> 2
A15: Type | B15: =Dataset!B13 -> 1 | C15: =Dataset!C13 -> 0 | D15: =Dataset!D13 -> 0 | E15: =Dataset!E13 -> 1 | F15: =Dataset!F13 -> 1 | G15: =Dataset!G13 -> 0 | H15: =Dataset!H13 -> 0 | I15: =Dataset!I13 -> 1 | ... N15: =Dataset!N13 -> 0 | O15: 1 = I
A16: min | B16: =MIN(Dataset!B$3:B$12) -> 56 | C16: — | D16: — | E16: =MIN(Dataset!E$3:E$12) -> 110 | F16: =MIN(Dataset!F$3:F$12) -> 177 | G16: — | H16: — | I16: =MIN(Dataset!I$3:I$12) -> 105 | J16: — | K16: =MIN(Dataset!K$3:K$12) -> 0.2 | L16: — | M16: =MIN(Dataset!M$3:M$12) -> 0 | N16: —
A17: max | B17: =MAX(Dataset!B$3:B$12) -> 74 | C17: — | D17: — | E17: =MAX(Dataset!E$3:E$12) -> 150 | F17: =MAX(Dataset!F$3:F$12) -> 564 | G17: — | H17: — | I17: =MAX(Dataset!I$3:I$12) -> 170 | J17: — | K17: =MAX(Dataset!K$3:K$12) -> 4 | L17: — | M17: =MAX(Dataset!M$3:M$12) -> 3 | N17: —
A19: Type 1 = quantitative feature (set I): rescaled to [0, 1] with the fractional-linear (min–max) transform; min and max are taken over the training objects S₁ … S₁₀.
A20: Type 0 = nominal feature (set J): the original code is kept, because the metric only asks whether two codes are equal.
A21: A new object (Brace for Meta-algorithm) is rescaled with the same training min and max, so its values may fall outside [0, 1].

Sheet Zhuravlev Distances
A1: Step 2 · Pairwise distances of the three base operators — ρ (Zhuravlev), ρ_I (quantitative part), ρ_J (nominal part)
A3: Operator ρ · Zhuravlev distance ρ(Sᵢ, Sⱼ) = ρ_I + ρ_J — row = target object Sᵢ, column = Sⱼ in original order
A4: ρ | B4: S₁ | C4: S₂ | D4: S₃ | E4: S₄ | F4: S₅ | G4: S₆ | H4: S₇ | I4: S₈ | J4: S₉ | K4: S₁₀
A5: S₁ | B5: =ROUND(B18+B31,10) -> 0 | C5: =ROUND(C18+C31,10) -> 6.1621314 | D5: =ROUND(D18+D31,10) -> 7.0747842 | E5: =ROUND(E18+E31,10) -> 4.8429406 | F5: =ROUND(F18+F31,10) -> 6.0394025 | G5: =ROUND(G18+G31,10) -> 5.9056936 | H5: =ROUND(H18+H31,10) -> 6.5963636 | I5: =ROUND(I18+I31,10) -> 4.8157298 | ... K5: =ROUND(K18+K31,10) -> 4.2218875
A6: S₂ | B6: =ROUND(B19+B32,10) -> 6.1621314 | C6: =ROUND(C19+C32,10) -> 0 | D6: =ROUND(D19+D32,10) -> 6.1979142 | E6: =ROUND(E19+E32,10) -> 6.8173527 | F6: =ROUND(F19+F32,10) -> 6.5779172 | G6: =ROUND(G19+G32,10) -> 5.8595929 | H6: =ROUND(H19+H32,10) -> 6.655391 | I6: =ROUND(I19+I32,10) -> 5.1247573 | ... K6: =ROUND(K19+K32,10) -> 4.2267936
A7: S₃ | B7: =ROUND(B20+B33,10) -> 7.0747842 | C7: =ROUND(C20+C33,10) -> 6.1979142 | D7: =ROUND(D20+D33,10) -> 0 | E7: =ROUND(E20+E33,10) -> 4.4075521 | F7: =ROUND(F20+F33,10) -> 5.7324577 | G7: =ROUND(G20+G33,10) -> 1.8031991 | H7: =ROUND(H20+H33,10) -> 6.6461408 | I7: =ROUND(I20+I33,10) -> 5.1035187 | ... K7: =ROUND(K20+K33,10) -> 7.5342785
A8: S₄ | B8: =ROUND(B21+B34,10) -> 4.8429406 | C8: =ROUND(C21+C34,10) -> 6.8173527 | D8: =ROUND(D21+D34,10) -> 4.4075521 | E8: =ROUND(E21+E34,10) -> 0 | F8: =ROUND(F21+F34,10) -> 6.0172133 | G8: =ROUND(G21+G34,10) -> 3.4022042 | H8: =ROUND(H21+H34,10) -> 5.1870262 | I8: =ROUND(I21+I34,10) -> 2.6221819 | ... K8: =ROUND(K21+K34,10) -> 6.3981614
A9: S₅ | B9: =ROUND(B22+B35,10) -> 6.0394025 | C9: =ROUND(C22+C35,10) -> 6.5779172 | D9: =ROUND(D22+D35,10) -> 5.7324577 | E9: =ROUND(E22+E35,10) -> 6.0172133 | F9: =ROUND(F22+F35,10) -> 0 | G9: =ROUND(G22+G35,10) -> 6.4159987 | H9: =ROUND(H22+H35,10) -> 6.7119318 | I9: =ROUND(I22+I35,10) -> 5.7470875 | ... K9: =ROUND(K22+K35,10) -> 7.8920592
A10: S₆ | B10: =ROUND(B23+B36,10) -> 5.9056936 | C10: =ROUND(C23+C36,10) -> 5.8595929 | D10: =ROUND(D23+D36,10) -> 1.8031991 | E10: =ROUND(E23+E36,10) -> 3.4022042 | F10: =ROUND(F23+F36,10) -> 6.4159987 | G10: =ROUND(G23+G36,10) -> 0 | H10: =ROUND(H23+H36,10) -> 7.3708685 | I10: =ROUND(I23+I36,10) -> 4.3181689 | ... K10: =ROUND(K23+K36,10) -> 6.6181794
A11: S₇ | B11: =ROUND(B24+B37,10) -> 6.5963636 | C11: =ROUND(C24+C37,10) -> 6.655391 | D11: =ROUND(D24+D37,10) -> 6.6461408 | E11: =ROUND(E24+E37,10) -> 5.1870262 | F11: =ROUND(F24+F37,10) -> 6.7119318 | G11: =ROUND(G24+G37,10) -> 7.3708685 | H11: =ROUND(H24+H37,10) -> 0 | I11: =ROUND(I24+I37,10) -> 3.8684891 | ... K11: =ROUND(K24+K37,10) -> 8.0250887
A12: S₈ | B12: =ROUND(B25+B38,10) -> 4.8157298 | C12: =ROUND(C25+C38,10) -> 5.1247573 | D12: =ROUND(D25+D38,10) -> 5.1035187 | E12: =ROUND(E25+E38,10) -> 2.6221819 | F12: =ROUND(F25+F38,10) -> 5.7470875 | G12: =ROUND(G25+G38,10) -> 4.3181689 | H12: =ROUND(H25+H38,10) -> 3.8684891 | I12: =ROUND(I25+I38,10) -> 0 | ... K12: =ROUND(K25+K38,10) -> 5.2444549
A13: S₉ | B13: =ROUND(B26+B39,10) -> 3.4680753 | C13: =ROUND(C26+C39,10) -> 4.6399233 | D13: =ROUND(D26+D39,10) -> 4.9990166 | E13: =ROUND(E26+E39,10) -> 4.1962328 | F13: =ROUND(F26+F39,10) -> 7.6901307 | G13: =ROUND(G26+G39,10) -> 4.4162508 | H13: =ROUND(H26+H39,10) -> 5.4898268 | I13: =ROUND(I26+I39,10) -> 2.709193 | ... K13: =ROUND(K26+K39,10) -> 3.0275696
A14: S₁₀ | B14: =ROUND(B27+B40,10) -> 4.2218875 | C14: =ROUND(C27+C40,10) -> 4.2267936 | D14: =ROUND(D27+D40,10) -> 7.5342785 | E14: =ROUND(E27+E40,10) -> 6.3981614 | F14: =ROUND(F27+F40,10) -> 7.8920592 | G14: =ROUND(G27+G40,10) -> 6.6181794 | H14: =ROUND(H27+H40,10) -> 8.0250887 | I14: =ROUND(I27+I40,10) -> 5.2444549 | ... K14: =ROUND(K27+K40,10) -> 0
A16: Operator ρ_I · quantitative part Σ(j∈I) |x′ⱼ − y′ⱼ| (normalized values from Step 1)
A17: ρ_I | B17: S₁ | C17: S₂ | D17: S₃ | E17: S₄ | F17: S₅ | G17: S₆ | H17: S₇ | I17: S₈ | J17: S₉ | K17: S₁₀
A18: S₁ | B18: =ROUND(SUMPRODUCT(Dataset!$B$13:$N$13,ABS('Normalized Dataset'!$B$5:$N$5-'Normalized Dataset'!$B$5:$N$5)),10) -> 0 | C18: =ROUND(SUMPRODUCT(Dataset!$B$13:$N$13,ABS('Normalized Dataset'!$B$5:$N$5-'Normalized Dataset'!$B$6:$N$6)),10) -> 3.1621314 | D18: =ROUND(SUMPRODUCT(Dataset!$B$13:$N$13,ABS('Normalized Dataset'!$B$5:$N$5-'Normalized Dataset'!$B$7:$N$7)),10) -> 3.0747842 | E18: =ROUND(SUMPRODUCT(Dataset!$B$13:$N$13,ABS('Normalized Dataset'!$B$5:$N$5-'Normalized Dataset'!$B$8:$N$8)),10) -> 1.8429406 | F18: =ROUND(SUMPRODUCT(Dataset!$B$13:$N$13,ABS('Normalized Dataset'!$B$5:$N$5-'Normalized Dataset'!$B$9:$N$9)),10) -> 2.0394025 | G18: =ROUND(SUMPRODUCT(Dataset!$B$13:$N$13,ABS('Normalized Dataset'!$B$5:$N$5-'Normalized Dataset'!$B$10:$N$10)),10) -> 2.9056936 | H18: =ROUND(SUMPRODUCT(Dataset!$B$13:$N$13,ABS('Normalized Dataset'!$B$5:$N$5-'Normalized Dataset'!$B$11:$N$11)),10) -> 2.5963636 | I18: =ROUND(SUMPRODUCT(Dataset!$B$13:$N$13,ABS('Normalized Dataset'!$B$5:$N$5-'Normalized Dataset'!$B$12:$N$12)),10) -> 2.8157298 | J18: =ROUND(SUMPRODUCT(Dataset!$B$13:$N$13,ABS('Normalized Dataset'!$B$5:$N$5-'Normalized Dataset'!$B$13:$N$13)),10) -> 2.4680753 | K18: =ROUND(SUMPRODUCT(Dataset!$B$13:$N$13,ABS('Normalized Dataset'!$B$5:$N$5-'Normalized Dataset'!$B$14:$N$14)),10) -> 2.2218875
A19: S₂ | B19: =ROUND(SUMPRODUCT(Dataset!$B$13:$N$13,ABS('Normalized Dataset'!$B$6:$N$6-'Normalized Dataset'!$B$5:$N$5)),10) -> 3.1621314 | C19: =ROUND(SUMPRODUCT(Dataset!$B$13:$N$13,ABS('Normalized Dataset'!$B$6:$N$6-'Normalized Dataset'!$B$6:$N$6)),10) -> 0 | D19: =ROUND(SUMPRODUCT(Dataset!$B$13:$N$13,ABS('Normalized Dataset'!$B$6:$N$6-'Normalized Dataset'!$B$7:$N$7)),10) -> 2.1979142 | E19: =ROUND(SUMPRODUCT(Dataset!$B$13:$N$13,ABS('Normalized Dataset'!$B$6:$N$6-'Normalized Dataset'!$B$8:$N$8)),10) -> 2.8173527 | F19: =ROUND(SUMPRODUCT(Dataset!$B$13:$N$13,ABS('Normalized Dataset'!$B$6:$N$6-'Normalized Dataset'!$B$9:$N$9)),10) -> 2.5779172 | G19: =ROUND(SUMPRODUCT(Dataset!$B$13:$N$13,ABS('Normalized Dataset'!$B$6:$N$6-'Normalized Dataset'!$B$10:$N$10)),10) -> 1.8595929 | H19: =ROUND(SUMPRODUCT(Dataset!$B$13:$N$13,ABS('Normalized Dataset'!$B$6:$N$6-'Normalized Dataset'!$B$11:$N$11)),10) -> 2.655391 | I19: =ROUND(SUMPRODUCT(Dataset!$B$13:$N$13,ABS('Normalized Dataset'!$B$6:$N$6-'Normalized Dataset'!$B$12:$N$12)),10) -> 2.1247573 | J19: =ROUND(SUMPRODUCT(Dataset!$B$13:$N$13,ABS('Normalized Dataset'!$B$6:$N$6-'Normalized Dataset'!$B$13:$N$13)),10) -> 2.6399233 | K19: =ROUND(SUMPRODUCT(Dataset!$B$13:$N$13,ABS('Normalized Dataset'!$B$6:$N$6-'Normalized Dataset'!$B$14:$N$14)),10) -> 3.2267936
A20: S₃ | B20: =ROUND(SUMPRODUCT(Dataset!$B$13:$N$13,ABS('Normalized Dataset'!$B$7:$N$7-'Normalized Dataset'!$B$5:$N$5)),10) -> 3.0747842 | C20: =ROUND(SUMPRODUCT(Dataset!$B$13:$N$13,ABS('Normalized Dataset'!$B$7:$N$7-'Normalized Dataset'!$B$6:$N$6)),10) -> 2.1979142 | D20: =ROUND(SUMPRODUCT(Dataset!$B$13:$N$13,ABS('Normalized Dataset'!$B$7:$N$7-'Normalized Dataset'!$B$7:$N$7)),10) -> 0 | E20: =ROUND(SUMPRODUCT(Dataset!$B$13:$N$13,ABS('Normalized Dataset'!$B$7:$N$7-'Normalized Dataset'!$B$8:$N$8)),10) -> 1.4075521 | F20: =ROUND(SUMPRODUCT(Dataset!$B$13:$N$13,ABS('Normalized Dataset'!$B$7:$N$7-'Normalized Dataset'!$B$9:$N$9)),10) -> 1.7324577 | G20: =ROUND(SUMPRODUCT(Dataset!$B$13:$N$13,ABS('Normalized Dataset'!$B$7:$N$7-'Normalized Dataset'!$B$10:$N$10)),10) -> 0.80319911 | H20: =ROUND(SUMPRODUCT(Dataset!$B$13:$N$13,ABS('Normalized Dataset'!$B$7:$N$7-'Normalized Dataset'!$B$11:$N$11)),10) -> 0.64614077 | I20: =ROUND(SUMPRODUCT(Dataset!$B$13:$N$13,ABS('Normalized Dataset'!$B$7:$N$7-'Normalized Dataset'!$B$12:$N$12)),10) -> 1.1035187 | J20: =ROUND(SUMPRODUCT(Dataset!$B$13:$N$13,ABS('Normalized Dataset'!$B$7:$N$7-'Normalized Dataset'!$B$13:$N$13)),10) -> 1.9990166 | K20: =ROUND(SUMPRODUCT(Dataset!$B$13:$N$13,ABS('Normalized Dataset'!$B$7:$N$7-'Normalized Dataset'!$B$14:$N$14)),10) -> 3.5342785
A21: S₄ | B21: =ROUND(SUMPRODUCT(Dataset!$B$13:$N$13,ABS('Normalized Dataset'!$B$8:$N$8-'Normalized Dataset'!$B$5:$N$5)),10) -> 1.8429406 | C21: =ROUND(SUMPRODUCT(Dataset!$B$13:$N$13,ABS('Normalized Dataset'!$B$8:$N$8-'Normalized Dataset'!$B$6:$N$6)),10) -> 2.8173527 | D21: =ROUND(SUMPRODUCT(Dataset!$B$13:$N$13,ABS('Normalized Dataset'!$B$8:$N$8-'Normalized Dataset'!$B$7:$N$7)),10) -> 1.4075521 | E21: =ROUND(SUMPRODUCT(Dataset!$B$13:$N$13,ABS('Normalized Dataset'!$B$8:$N$8-'Normalized Dataset'!$B$8:$N$8)),10) -> 0 | F21: =ROUND(SUMPRODUCT(Dataset!$B$13:$N$13,ABS('Normalized Dataset'!$B$8:$N$8-'Normalized Dataset'!$B$9:$N$9)),10) -> 1.0172133 | G21: =ROUND(SUMPRODUCT(Dataset!$B$13:$N$13,ABS('Normalized Dataset'!$B$8:$N$8-'Normalized Dataset'!$B$10:$N$10)),10) -> 1.4022042 | H21: =ROUND(SUMPRODUCT(Dataset!$B$13:$N$13,ABS('Normalized Dataset'!$B$8:$N$8-'Normalized Dataset'!$B$11:$N$11)),10) -> 1.1870262 | I21: =ROUND(SUMPRODUCT(Dataset!$B$13:$N$13,ABS('Normalized Dataset'!$B$8:$N$8-'Normalized Dataset'!$B$12:$N$12)),10) -> 1.6221819 | J21: =ROUND(SUMPRODUCT(Dataset!$B$13:$N$13,ABS('Normalized Dataset'!$B$8:$N$8-'Normalized Dataset'!$B$13:$N$13)),10) -> 2.1962328 | K21: =ROUND(SUMPRODUCT(Dataset!$B$13:$N$13,ABS('Normalized Dataset'!$B$8:$N$8-'Normalized Dataset'!$B$14:$N$14)),10) -> 3.3981614
A22: S₅ | B22: =ROUND(SUMPRODUCT(Dataset!$B$13:$N$13,ABS('Normalized Dataset'!$B$9:$N$9-'Normalized Dataset'!$B$5:$N$5)),10) -> 2.0394025 | C22: =ROUND(SUMPRODUCT(Dataset!$B$13:$N$13,ABS('Normalized Dataset'!$B$9:$N$9-'Normalized Dataset'!$B$6:$N$6)),10) -> 2.5779172 | D22: =ROUND(SUMPRODUCT(Dataset!$B$13:$N$13,ABS('Normalized Dataset'!$B$9:$N$9-'Normalized Dataset'!$B$7:$N$7)),10) -> 1.7324577 | E22: =ROUND(SUMPRODUCT(Dataset!$B$13:$N$13,ABS('Normalized Dataset'!$B$9:$N$9-'Normalized Dataset'!$B$8:$N$8)),10) -> 1.0172133 | F22: =ROUND(SUMPRODUCT(Dataset!$B$13:$N$13,ABS('Normalized Dataset'!$B$9:$N$9-'Normalized Dataset'!$B$9:$N$9)),10) -> 0 | G22: =ROUND(SUMPRODUCT(Dataset!$B$13:$N$13,ABS('Normalized Dataset'!$B$9:$N$9-'Normalized Dataset'!$B$10:$N$10)),10) -> 1.4159987 | H22: =ROUND(SUMPRODUCT(Dataset!$B$13:$N$13,ABS('Normalized Dataset'!$B$9:$N$9-'Normalized Dataset'!$B$11:$N$11)),10) -> 1.7119318 | I22: =ROUND(SUMPRODUCT(Dataset!$B$13:$N$13,ABS('Normalized Dataset'!$B$9:$N$9-'Normalized Dataset'!$B$12:$N$12)),10) -> 1.7470875 | J22: =ROUND(SUMPRODUCT(Dataset!$B$13:$N$13,ABS('Normalized Dataset'!$B$9:$N$9-'Normalized Dataset'!$B$13:$N$13)),10) -> 2.6901307 | K22: =ROUND(SUMPRODUCT(Dataset!$B$13:$N$13,ABS('Normalized Dataset'!$B$9:$N$9-'Normalized Dataset'!$B$14:$N$14)),10) -> 3.8920592
A23: S₆ | B23: =ROUND(SUMPRODUCT(Dataset!$B$13:$N$13,ABS('Normalized Dataset'!$B$10:$N$10-'Normalized Dataset'!$B$5:$N$5)),10) -> 2.9056936 | C23: =ROUND(SUMPRODUCT(Dataset!$B$13:$N$13,ABS('Normalized Dataset'!$B$10:$N$10-'Normalized Dataset'!$B$6:$N$6)),10) -> 1.8595929 | D23: =ROUND(SUMPRODUCT(Dataset!$B$13:$N$13,ABS('Normalized Dataset'!$B$10:$N$10-'Normalized Dataset'!$B$7:$N$7)),10) -> 0.80319911 | E23: =ROUND(SUMPRODUCT(Dataset!$B$13:$N$13,ABS('Normalized Dataset'!$B$10:$N$10-'Normalized Dataset'!$B$8:$N$8)),10) -> 1.4022042 | F23: =ROUND(SUMPRODUCT(Dataset!$B$13:$N$13,ABS('Normalized Dataset'!$B$10:$N$10-'Normalized Dataset'!$B$9:$N$9)),10) -> 1.4159987 | G23: =ROUND(SUMPRODUCT(Dataset!$B$13:$N$13,ABS('Normalized Dataset'!$B$10:$N$10-'Normalized Dataset'!$B$10:$N$10)),10) -> 0 | H23: =ROUND(SUMPRODUCT(Dataset!$B$13:$N$13,ABS('Normalized Dataset'!$B$10:$N$10-'Normalized Dataset'!$B$11:$N$11)),10) -> 1.3708685 | I23: =ROUND(SUMPRODUCT(Dataset!$B$13:$N$13,ABS('Normalized Dataset'!$B$10:$N$10-'Normalized Dataset'!$B$12:$N$12)),10) -> 1.3181689 | J23: =ROUND(SUMPRODUCT(Dataset!$B$13:$N$13,ABS('Normalized Dataset'!$B$10:$N$10-'Normalized Dataset'!$B$13:$N$13)),10) -> 2.4162508 | K23: =ROUND(SUMPRODUCT(Dataset!$B$13:$N$13,ABS('Normalized Dataset'!$B$10:$N$10-'Normalized Dataset'!$B$14:$N$14)),10) -> 3.6181794
A24: S₇ | B24: =ROUND(SUMPRODUCT(Dataset!$B$13:$N$13,ABS('Normalized Dataset'!$B$11:$N$11-'Normalized Dataset'!$B$5:$N$5)),10) -> 2.5963636 | C24: =ROUND(SUMPRODUCT(Dataset!$B$13:$N$13,ABS('Normalized Dataset'!$B$11:$N$11-'Normalized Dataset'!$B$6:$N$6)),10) -> 2.655391 | D24: =ROUND(SUMPRODUCT(Dataset!$B$13:$N$13,ABS('Normalized Dataset'!$B$11:$N$11-'Normalized Dataset'!$B$7:$N$7)),10) -> 0.64614077 | E24: =ROUND(SUMPRODUCT(Dataset!$B$13:$N$13,ABS('Normalized Dataset'!$B$11:$N$11-'Normalized Dataset'!$B$8:$N$8)),10) -> 1.1870262 | F24: =ROUND(SUMPRODUCT(Dataset!$B$13:$N$13,ABS('Normalized Dataset'!$B$11:$N$11-'Normalized Dataset'!$B$9:$N$9)),10) -> 1.7119318 | G24: =ROUND(SUMPRODUCT(Dataset!$B$13:$N$13,ABS('Normalized Dataset'!$B$11:$N$11-'Normalized Dataset'!$B$10:$N$10)),10) -> 1.3708685 | H24: =ROUND(SUMPRODUCT(Dataset!$B$13:$N$13,ABS('Normalized Dataset'!$B$11:$N$11-'Normalized Dataset'!$B$11:$N$11)),10) -> 0 | I24: =ROUND(SUMPRODUCT(Dataset!$B$13:$N$13,ABS('Normalized Dataset'!$B$11:$N$11-'Normalized Dataset'!$B$12:$N$12)),10) -> 0.86848905 | J24: =ROUND(SUMPRODUCT(Dataset!$B$13:$N$13,ABS('Normalized Dataset'!$B$11:$N$11-'Normalized Dataset'!$B$13:$N$13)),10) -> 1.4898268 | K24: =ROUND(SUMPRODUCT(Dataset!$B$13:$N$13,ABS('Normalized Dataset'!$B$11:$N$11-'Normalized Dataset'!$B$14:$N$14)),10) -> 3.0250887
A25: S₈ | B25: =ROUND(SUMPRODUCT(Dataset!$B$13:$N$13,ABS('Normalized Dataset'!$B$12:$N$12-'Normalized Dataset'!$B$5:$N$5)),10) -> 2.8157298 | C25: =ROUND(SUMPRODUCT(Dataset!$B$13:$N$13,ABS('Normalized Dataset'!$B$12:$N$12-'Normalized Dataset'!$B$6:$N$6)),10) -> 2.1247573 | D25: =ROUND(SUMPRODUCT(Dataset!$B$13:$N$13,ABS('Normalized Dataset'!$B$12:$N$12-'Normalized Dataset'!$B$7:$N$7)),10) -> 1.1035187 | E25: =ROUND(SUMPRODUCT(Dataset!$B$13:$N$13,ABS('Normalized Dataset'!$B$12:$N$12-'Normalized Dataset'!$B$8:$N$8)),10) -> 1.6221819 | F25: =ROUND(SUMPRODUCT(Dataset!$B$13:$N$13,ABS('Normalized Dataset'!$B$12:$N$12-'Normalized Dataset'!$B$9:$N$9)),10) -> 1.7470875 | G25: =ROUND(SUMPRODUCT(Dataset!$B$13:$N$13,ABS('Normalized Dataset'!$B$12:$N$12-'Normalized Dataset'!$B$10:$N$10)),10) -> 1.3181689 | H25: =ROUND(SUMPRODUCT(Dataset!$B$13:$N$13,ABS('Normalized Dataset'!$B$12:$N$12-'Normalized Dataset'!$B$11:$N$11)),10) -> 0.86848905 | I25: =ROUND(SUMPRODUCT(Dataset!$B$13:$N$13,ABS('Normalized Dataset'!$B$12:$N$12-'Normalized Dataset'!$B$12:$N$12)),10) -> 0 | J25: =ROUND(SUMPRODUCT(Dataset!$B$13:$N$13,ABS('Normalized Dataset'!$B$12:$N$12-'Normalized Dataset'!$B$13:$N$13)),10) -> 1.709193 | K25: =ROUND(SUMPRODUCT(Dataset!$B$13:$N$13,ABS('Normalized Dataset'!$B$12:$N$12-'Normalized Dataset'!$B$14:$N$14)),10) -> 3.2444549
A26: S₉ | B26: =ROUND(SUMPRODUCT(Dataset!$B$13:$N$13,ABS('Normalized Dataset'!$B$13:$N$13-'Normalized Dataset'!$B$5:$N$5)),10) -> 2.4680753 | C26: =ROUND(SUMPRODUCT(Dataset!$B$13:$N$13,ABS('Normalized Dataset'!$B$13:$N$13-'Normalized Dataset'!$B$6:$N$6)),10) -> 2.6399233 | D26: =ROUND(SUMPRODUCT(Dataset!$B$13:$N$13,ABS('Normalized Dataset'!$B$13:$N$13-'Normalized Dataset'!$B$7:$N$7)),10) -> 1.9990166 | E26: =ROUND(SUMPRODUCT(Dataset!$B$13:$N$13,ABS('Normalized Dataset'!$B$13:$N$13-'Normalized Dataset'!$B$8:$N$8)),10) -> 2.1962328 | F26: =ROUND(SUMPRODUCT(Dataset!$B$13:$N$13,ABS('Normalized Dataset'!$B$13:$N$13-'Normalized Dataset'!$B$9:$N$9)),10) -> 2.6901307 | G26: =ROUND(SUMPRODUCT(Dataset!$B$13:$N$13,ABS('Normalized Dataset'!$B$13:$N$13-'Normalized Dataset'!$B$10:$N$10)),10) -> 2.4162508 | H26: =ROUND(SUMPRODUCT(Dataset!$B$13:$N$13,ABS('Normalized Dataset'!$B$13:$N$13-'Normalized Dataset'!$B$11:$N$11)),10) -> 1.4898268 | I26: =ROUND(SUMPRODUCT(Dataset!$B$13:$N$13,ABS('Normalized Dataset'!$B$13:$N$13-'Normalized Dataset'!$B$12:$N$12)),10) -> 1.709193 | J26: =ROUND(SUMPRODUCT(Dataset!$B$13:$N$13,ABS('Normalized Dataset'!$B$13:$N$13-'Normalized Dataset'!$B$13:$N$13)),10) -> 0 | K26: =ROUND(SUMPRODUCT(Dataset!$B$13:$N$13,ABS('Normalized Dataset'!$B$13:$N$13-'Normalized Dataset'!$B$14:$N$14)),10) -> 2.0275696
A27: S₁₀ | B27: =ROUND(SUMPRODUCT(Dataset!$B$13:$N$13,ABS('Normalized Dataset'!$B$14:$N$14-'Normalized Dataset'!$B$5:$N$5)),10) -> 2.2218875 | C27: =ROUND(SUMPRODUCT(Dataset!$B$13:$N$13,ABS('Normalized Dataset'!$B$14:$N$14-'Normalized Dataset'!$B$6:$N$6)),10) -> 3.2267936 | D27: =ROUND(SUMPRODUCT(Dataset!$B$13:$N$13,ABS('Normalized Dataset'!$B$14:$N$14-'Normalized Dataset'!$B$7:$N$7)),10) -> 3.5342785 | E27: =ROUND(SUMPRODUCT(Dataset!$B$13:$N$13,ABS('Normalized Dataset'!$B$14:$N$14-'Normalized Dataset'!$B$8:$N$8)),10) -> 3.3981614 | F27: =ROUND(SUMPRODUCT(Dataset!$B$13:$N$13,ABS('Normalized Dataset'!$B$14:$N$14-'Normalized Dataset'!$B$9:$N$9)),10) -> 3.8920592 | G27: =ROUND(SUMPRODUCT(Dataset!$B$13:$N$13,ABS('Normalized Dataset'!$B$14:$N$14-'Normalized Dataset'!$B$10:$N$10)),10) -> 3.6181794 | H27: =ROUND(SUMPRODUCT(Dataset!$B$13:$N$13,ABS('Normalized Dataset'!$B$14:$N$14-'Normalized Dataset'!$B$11:$N$11)),10) -> 3.0250887 | I27: =ROUND(SUMPRODUCT(Dataset!$B$13:$N$13,ABS('Normalized Dataset'!$B$14:$N$14-'Normalized Dataset'!$B$12:$N$12)),10) -> 3.2444549 | J27: =ROUND(SUMPRODUCT(Dataset!$B$13:$N$13,ABS('Normalized Dataset'!$B$14:$N$14-'Normalized Dataset'!$B$13:$N$13)),10) -> 2.0275696 | K27: =ROUND(SUMPRODUCT(Dataset!$B$13:$N$13,ABS('Normalized Dataset'!$B$14:$N$14-'Normalized Dataset'!$B$14:$N$14)),10) -> 0
A29: Operator ρ_J · nominal part Σ(j∈J) [xⱼ ≠ yⱼ] (number of nominal features with different codes)
A30: ρ_J | B30: S₁ | C30: S₂ | D30: S₃ | E30: S₄ | F30: S₅ | G30: S₆ | H30: S₇ | I30: S₈ | J30: S₉ | K30: S₁₀
A31: S₁ | B31: =SUMPRODUCT((1-Dataset!$B$13:$N$13)*(Dataset!$B$3:$N$3<>Dataset!$B$3:$N$3)) -> 0 | C31: =SUMPRODUCT((1-Dataset!$B$13:$N$13)*(Dataset!$B$3:$N$3<>Dataset!$B$4:$N$4)) -> 3 | D31: =SUMPRODUCT((1-Dataset!$B$13:$N$13)*(Dataset!$B$3:$N$3<>Dataset!$B$5:$N$5)) -> 4 | E31: =SUMPRODUCT((1-Dataset!$B$13:$N$13)*(Dataset!$B$3:$N$3<>Dataset!$B$6:$N$6)) -> 3 | F31: =SUMPRODUCT((1-Dataset!$B$13:$N$13)*(Dataset!$B$3:$N$3<>Dataset!$B$7:$N$7)) -> 4 | G31: =SUMPRODUCT((1-Dataset!$B$13:$N$13)*(Dataset!$B$3:$N$3<>Dataset!$B$8:$N$8)) -> 3 | H31: =SUMPRODUCT((1-Dataset!$B$13:$N$13)*(Dataset!$B$3:$N$3<>Dataset!$B$9:$N$9)) -> 4 | I31: =SUMPRODUCT((1-Dataset!$B$13:$N$13)*(Dataset!$B$3:$N$3<>Dataset!$B$10:$N$10)) -> 2 | J31: =SUMPRODUCT((1-Dataset!$B$13:$N$13)*(Dataset!$B$3:$N$3<>Dataset!$B$11:$N$11)) -> 1 | K31: =SUMPRODUCT((1-Dataset!$B$13:$N$13)*(Dataset!$B$3:$N$3<>Dataset!$B$12:$N$12)) -> 2
A32: S₂ | B32: =SUMPRODUCT((1-Dataset!$B$13:$N$13)*(Dataset!$B$4:$N$4<>Dataset!$B$3:$N$3)) -> 3 | C32: =SUMPRODUCT((1-Dataset!$B$13:$N$13)*(Dataset!$B$4:$N$4<>Dataset!$B$4:$N$4)) -> 0 | D32: =SUMPRODUCT((1-Dataset!$B$13:$N$13)*(Dataset!$B$4:$N$4<>Dataset!$B$5:$N$5)) -> 4 | E32: =SUMPRODUCT((1-Dataset!$B$13:$N$13)*(Dataset!$B$4:$N$4<>Dataset!$B$6:$N$6)) -> 4 | F32: =SUMPRODUCT((1-Dataset!$B$13:$N$13)*(Dataset!$B$4:$N$4<>Dataset!$B$7:$N$7)) -> 4 | G32: =SUMPRODUCT((1-Dataset!$B$13:$N$13)*(Dataset!$B$4:$N$4<>Dataset!$B$8:$N$8)) -> 4 | H32: =SUMPRODUCT((1-Dataset!$B$13:$N$13)*(Dataset!$B$4:$N$4<>Dataset!$B$9:$N$9)) -> 4 | I32: =SUMPRODUCT((1-Dataset!$B$13:$N$13)*(Dataset!$B$4:$N$4<>Dataset!$B$10:$N$10)) -> 3 | J32: =SUMPRODUCT((1-Dataset!$B$13:$N$13)*(Dataset!$B$4:$N$4<>Dataset!$B$11:$N$11)) -> 2 | K32: =SUMPRODUCT((1-Dataset!$B$13:$N$13)*(Dataset!$B$4:$N$4<>Dataset!$B$12:$N$12)) -> 1
A33: S₃ | B33: =SUMPRODUCT((1-Dataset!$B$13:$N$13)*(Dataset!$B$5:$N$5<>Dataset!$B$3:$N$3)) -> 4 | C33: =SUMPRODUCT((1-Dataset!$B$13:$N$13)*(Dataset!$B$5:$N$5<>Dataset!$B$4:$N$4)) -> 4 | D33: =SUMPRODUCT((1-Dataset!$B$13:$N$13)*(Dataset!$B$5:$N$5<>Dataset!$B$5:$N$5)) -> 0 | E33: =SUMPRODUCT((1-Dataset!$B$13:$N$13)*(Dataset!$B$5:$N$5<>Dataset!$B$6:$N$6)) -> 3 | F33: =SUMPRODUCT((1-Dataset!$B$13:$N$13)*(Dataset!$B$5:$N$5<>Dataset!$B$7:$N$7)) -> 4 | G33: =SUMPRODUCT((1-Dataset!$B$13:$N$13)*(Dataset!$B$5:$N$5<>Dataset!$B$8:$N$8)) -> 1 | H33: =SUMPRODUCT((1-Dataset!$B$13:$N$13)*(Dataset!$B$5:$N$5<>Dataset!$B$9:$N$9)) -> 6 | I33: =SUMPRODUCT((1-Dataset!$B$13:$N$13)*(Dataset!$B$5:$N$5<>Dataset!$B$10:$N$10)) -> 4 | J33: =SUMPRODUCT((1-Dataset!$B$13:$N$13)*(Dataset!$B$5:$N$5<>Dataset!$B$11:$N$11)) -> 3 | K33: =SUMPRODUCT((1-Dataset!$B$13:$N$13)*(Dataset!$B$5:$N$5<>Dataset!$B$12:$N$12)) -> 4
A34: S₄ | B34: =SUMPRODUCT((1-Dataset!$B$13:$N$13)*(Dataset!$B$6:$N$6<>Dataset!$B$3:$N$3)) -> 3 | C34: =SUMPRODUCT((1-Dataset!$B$13:$N$13)*(Dataset!$B$6:$N$6<>Dataset!$B$4:$N$4)) -> 4 | D34: =SUMPRODUCT((1-Dataset!$B$13:$N$13)*(Dataset!$B$6:$N$6<>Dataset!$B$5:$N$5)) -> 3 | E34: =SUMPRODUCT((1-Dataset!$B$13:$N$13)*(Dataset!$B$6:$N$6<>Dataset!$B$6:$N$6)) -> 0 | F34: =SUMPRODUCT((1-Dataset!$B$13:$N$13)*(Dataset!$B$6:$N$6<>Dataset!$B$7:$N$7)) -> 5 | G34: =SUMPRODUCT((1-Dataset!$B$13:$N$13)*(Dataset!$B$6:$N$6<>Dataset!$B$8:$N$8)) -> 2 | H34: =SUMPRODUCT((1-Dataset!$B$13:$N$13)*(Dataset!$B$6:$N$6<>Dataset!$B$9:$N$9)) -> 4 | I34: =SUMPRODUCT((1-Dataset!$B$13:$N$13)*(Dataset!$B$6:$N$6<>Dataset!$B$10:$N$10)) -> 1 | J34: =SUMPRODUCT((1-Dataset!$B$13:$N$13)*(Dataset!$B$6:$N$6<>Dataset!$B$11:$N$11)) -> 2 | K34: =SUMPRODUCT((1-Dataset!$B$13:$N$13)*(Dataset!$B$6:$N$6<>Dataset!$B$12:$N$12)) -> 3
A35: S₅ | B35: =SUMPRODUCT((1-Dataset!$B$13:$N$13)*(Dataset!$B$7:$N$7<>Dataset!$B$3:$N$3)) -> 4 | C35: =SUMPRODUCT((1-Dataset!$B$13:$N$13)*(Dataset!$B$7:$N$7<>Dataset!$B$4:$N$4)) -> 4 | D35: =SUMPRODUCT((1-Dataset!$B$13:$N$13)*(Dataset!$B$7:$N$7<>Dataset!$B$5:$N$5)) -> 4 | E35: =SUMPRODUCT((1-Dataset!$B$13:$N$13)*(Dataset!$B$7:$N$7<>Dataset!$B$6:$N$6)) -> 5 | F35: =SUMPRODUCT((1-Dataset!$B$13:$N$13)*(Dataset!$B$7:$N$7<>Dataset!$B$7:$N$7)) -> 0 | G35: =SUMPRODUCT((1-Dataset!$B$13:$N$13)*(Dataset!$B$7:$N$7<>Dataset!$B$8:$N$8)) -> 5 | H35: =SUMPRODUCT((1-Dataset!$B$13:$N$13)*(Dataset!$B$7:$N$7<>Dataset!$B$9:$N$9)) -> 5 | I35: =SUMPRODUCT((1-Dataset!$B$13:$N$13)*(Dataset!$B$7:$N$7<>Dataset!$B$10:$N$10)) -> 4 | J35: =SUMPRODUCT((1-Dataset!$B$13:$N$13)*(Dataset!$B$7:$N$7<>Dataset!$B$11:$N$11)) -> 5 | K35: =SUMPRODUCT((1-Dataset!$B$13:$N$13)*(Dataset!$B$7:$N$7<>Dataset!$B$12:$N$12)) -> 4
A36: S₆ | B36: =SUMPRODUCT((1-Dataset!$B$13:$N$13)*(Dataset!$B$8:$N$8<>Dataset!$B$3:$N$3)) -> 3 | C36: =SUMPRODUCT((1-Dataset!$B$13:$N$13)*(Dataset!$B$8:$N$8<>Dataset!$B$4:$N$4)) -> 4 | D36: =SUMPRODUCT((1-Dataset!$B$13:$N$13)*(Dataset!$B$8:$N$8<>Dataset!$B$5:$N$5)) -> 1 | E36: =SUMPRODUCT((1-Dataset!$B$13:$N$13)*(Dataset!$B$8:$N$8<>Dataset!$B$6:$N$6)) -> 2 | F36: =SUMPRODUCT((1-Dataset!$B$13:$N$13)*(Dataset!$B$8:$N$8<>Dataset!$B$7:$N$7)) -> 5 | G36: =SUMPRODUCT((1-Dataset!$B$13:$N$13)*(Dataset!$B$8:$N$8<>Dataset!$B$8:$N$8)) -> 0 | H36: =SUMPRODUCT((1-Dataset!$B$13:$N$13)*(Dataset!$B$8:$N$8<>Dataset!$B$9:$N$9)) -> 6 | I36: =SUMPRODUCT((1-Dataset!$B$13:$N$13)*(Dataset!$B$8:$N$8<>Dataset!$B$10:$N$10)) -> 3 | J36: =SUMPRODUCT((1-Dataset!$B$13:$N$13)*(Dataset!$B$8:$N$8<>Dataset!$B$11:$N$11)) -> 2 | K36: =SUMPRODUCT((1-Dataset!$B$13:$N$13)*(Dataset!$B$8:$N$8<>Dataset!$B$12:$N$12)) -> 3
A37: S₇ | B37: =SUMPRODUCT((1-Dataset!$B$13:$N$13)*(Dataset!$B$9:$N$9<>Dataset!$B$3:$N$3)) -> 4 | C37: =SUMPRODUCT((1-Dataset!$B$13:$N$13)*(Dataset!$B$9:$N$9<>Dataset!$B$4:$N$4)) -> 4 | D37: =SUMPRODUCT((1-Dataset!$B$13:$N$13)*(Dataset!$B$9:$N$9<>Dataset!$B$5:$N$5)) -> 6 | E37: =SUMPRODUCT((1-Dataset!$B$13:$N$13)*(Dataset!$B$9:$N$9<>Dataset!$B$6:$N$6)) -> 4 | F37: =SUMPRODUCT((1-Dataset!$B$13:$N$13)*(Dataset!$B$9:$N$9<>Dataset!$B$7:$N$7)) -> 5 | G37: =SUMPRODUCT((1-Dataset!$B$13:$N$13)*(Dataset!$B$9:$N$9<>Dataset!$B$8:$N$8)) -> 6 | H37: =SUMPRODUCT((1-Dataset!$B$13:$N$13)*(Dataset!$B$9:$N$9<>Dataset!$B$9:$N$9)) -> 0 | I37: =SUMPRODUCT((1-Dataset!$B$13:$N$13)*(Dataset!$B$9:$N$9<>Dataset!$B$10:$N$10)) -> 3 | J37: =SUMPRODUCT((1-Dataset!$B$13:$N$13)*(Dataset!$B$9:$N$9<>Dataset!$B$11:$N$11)) -> 4 | K37: =SUMPRODUCT((1-Dataset!$B$13:$N$13)*(Dataset!$B$9:$N$9<>Dataset!$B$12:$N$12)) -> 5
A38: S₈ | B38: =SUMPRODUCT((1-Dataset!$B$13:$N$13)*(Dataset!$B$10:$N$10<>Dataset!$B$3:$N$3)) -> 2 | C38: =SUMPRODUCT((1-Dataset!$B$13:$N$13)*(Dataset!$B$10:$N$10<>Dataset!$B$4:$N$4)) -> 3 | D38: =SUMPRODUCT((1-Dataset!$B$13:$N$13)*(Dataset!$B$10:$N$10<>Dataset!$B$5:$N$5)) -> 4 | E38: =SUMPRODUCT((1-Dataset!$B$13:$N$13)*(Dataset!$B$10:$N$10<>Dataset!$B$6:$N$6)) -> 1 | F38: =SUMPRODUCT((1-Dataset!$B$13:$N$13)*(Dataset!$B$10:$N$10<>Dataset!$B$7:$N$7)) -> 4 | G38: =SUMPRODUCT((1-Dataset!$B$13:$N$13)*(Dataset!$B$10:$N$10<>Dataset!$B$8:$N$8)) -> 3 | H38: =SUMPRODUCT((1-Dataset!$B$13:$N$13)*(Dataset!$B$10:$N$10<>Dataset!$B$9:$N$9)) -> 3 | I38: =SUMPRODUCT((1-Dataset!$B$13:$N$13)*(Dataset!$B$10:$N$10<>Dataset!$B$10:$N$10)) -> 0 | J38: =SUMPRODUCT((1-Dataset!$B$13:$N$13)*(Dataset!$B$10:$N$10<>Dataset!$B$11:$N$11)) -> 1 | K38: =SUMPRODUCT((1-Dataset!$B$13:$N$13)*(Dataset!$B$10:$N$10<>Dataset!$B$12:$N$12)) -> 2
A39: S₉ | B39: =SUMPRODUCT((1-Dataset!$B$13:$N$13)*(Dataset!$B$11:$N$11<>Dataset!$B$3:$N$3)) -> 1 | C39: =SUMPRODUCT((1-Dataset!$B$13:$N$13)*(Dataset!$B$11:$N$11<>Dataset!$B$4:$N$4)) -> 2 | D39: =SUMPRODUCT((1-Dataset!$B$13:$N$13)*(Dataset!$B$11:$N$11<>Dataset!$B$5:$N$5)) -> 3 | E39: =SUMPRODUCT((1-Dataset!$B$13:$N$13)*(Dataset!$B$11:$N$11<>Dataset!$B$6:$N$6)) -> 2 | F39: =SUMPRODUCT((1-Dataset!$B$13:$N$13)*(Dataset!$B$11:$N$11<>Dataset!$B$7:$N$7)) -> 5 | G39: =SUMPRODUCT((1-Dataset!$B$13:$N$13)*(Dataset!$B$11:$N$11<>Dataset!$B$8:$N$8)) -> 2 | H39: =SUMPRODUCT((1-Dataset!$B$13:$N$13)*(Dataset!$B$11:$N$11<>Dataset!$B$9:$N$9)) -> 4 | I39: =SUMPRODUCT((1-Dataset!$B$13:$N$13)*(Dataset!$B$11:$N$11<>Dataset!$B$10:$N$10)) -> 1 | J39: =SUMPRODUCT((1-Dataset!$B$13:$N$13)*(Dataset!$B$11:$N$11<>Dataset!$B$11:$N$11)) -> 0 | K39: =SUMPRODUCT((1-Dataset!$B$13:$N$13)*(Dataset!$B$11:$N$11<>Dataset!$B$12:$N$12)) -> 1
A40: S₁₀ | B40: =SUMPRODUCT((1-Dataset!$B$13:$N$13)*(Dataset!$B$12:$N$12<>Dataset!$B$3:$N$3)) -> 2 | C40: =SUMPRODUCT((1-Dataset!$B$13:$N$13)*(Dataset!$B$12:$N$12<>Dataset!$B$4:$N$4)) -> 1 | D40: =SUMPRODUCT((1-Dataset!$B$13:$N$13)*(Dataset!$B$12:$N$12<>Dataset!$B$5:$N$5)) -> 4 | E40: =SUMPRODUCT((1-Dataset!$B$13:$N$13)*(Dataset!$B$12:$N$12<>Dataset!$B$6:$N$6)) -> 3 | F40: =SUMPRODUCT((1-Dataset!$B$13:$N$13)*(Dataset!$B$12:$N$12<>Dataset!$B$7:$N$7)) -> 4 | G40: =SUMPRODUCT((1-Dataset!$B$13:$N$13)*(Dataset!$B$12:$N$12<>Dataset!$B$8:$N$8)) -> 3 | H40: =SUMPRODUCT((1-Dataset!$B$13:$N$13)*(Dataset!$B$12:$N$12<>Dataset!$B$9:$N$9)) -> 5 | I40: =SUMPRODUCT((1-Dataset!$B$13:$N$13)*(Dataset!$B$12:$N$12<>Dataset!$B$10:$N$10)) -> 2 | J40: =SUMPRODUCT((1-Dataset!$B$13:$N$13)*(Dataset!$B$12:$N$12<>Dataset!$B$11:$N$11)) -> 1 | K40: =SUMPRODUCT((1-Dataset!$B$13:$N$13)*(Dataset!$B$12:$N$12<>Dataset!$B$12:$N$12)) -> 0
A42: Each row lists the distances from the target object Sᵢ to S₁ … S₁₀ in their original order (image 1: S₁ → S₂, S₃, …, S₁₀).
A43: The three blocks are the three base operators of the ensemble: the same Zhuravlev metric on all features, on the quantitative features only and on the nominal features only.
A44: Distances are rounded to 10 decimals so that mathematically equal distances tie exactly. The diagonal (grey) is never used as a neighbour.

Sheet Sorted Neighbors (ρ)
