Workbook

Sheet Overview
B2: Forming Synthetic Features using k-NN
B3: Experiment on the Heart-Disease dataset · 10 objects · 13 features (6 quantitative, 7 nominal) · 2 classes · Zhuravlev metric
B5: Workbook map
B6: # | C6: Sheet | D6: Stage | E6: What it contains
B7: 1 | C7: Dataset | D7: Input data | E7: Original sample: 10 objects (S₁–S₁₀) × 13 features (x₁–x₁₃) with class labels (K1 = 4, K2 = 6); feature-type flags in row 13 (1 = quantitative, 0 = nominal) and the split into 6 quantitative and 7 nominal features.
B8: 2 | C8: Quantitative | D8: Input data | E8: The 6 quantitative features (x₁, x₄, x₅, x₈, x₁₀, x₁₂) with class labels.
B9: 3 | C9: Nominal | D9: Input data | E9: The 7 nominal features (x₂, x₃, x₆, x₇, x₉, x₁₁, x₁₃) with class labels.
B10: 4 | C10: Normalized Dataset | D10: Step 1 · Scale unification | E10: Quantitative features mapped to [0, 1] by (x − min) / (max − min); nominal codes unchanged; type, min and max rows.
B11: 5 | C11: Zhuravlev Distances | D11: Step 2 · Distances | E11: Zhuravlev distance ρ(Sᵢ, Sⱼ) for all pairs, with its quantitative part and its nominal (mismatch-count) part.
B12: 6 | C12: Sorted Neighbors | D12: Step 3 · Sorting | E12: Rank matrix, then one block per object: neighbours in ascending ρ with original index, distance, class, same-class flag and running count; the permitted k are marked.
B13: 7 | C13: Synthetic Features (k-NN) | D13: Step 4 · Synthetic features | E13: For each Sᵢ and each permitted k (odd, k_min … k_max, k_max = 2·min|Kᵢ| − 3): the number of its k nearest neighbours that share its class — the synthetic features based on k-NN — with the experiment parameters.
B15: Algorithm — pipeline specification (same steps and names as the planned Python project)
B16: # | C16: Step | D16: Output sheet | E16: Definition → planned Python function
B17: 1 | C17: Load the dataset | D17: Dataset | E17: Objects S₁…Sₘ, features x₁…xₙ, feature type tⱼ (1 = quantitative ∈ I, 0 = nominal ∈ J), class labels. → io.load_dataset(path) -> (names, X, y, types)
B18: 2 | C18: Unify measurement scales | D18: Normalized Dataset | E18: x′ = (x − min) / (max − min) for j ∈ I (0 if max = min); nominal values unchanged. → preprocessing.unify_scales(X, types)
B19: 3 | C19: Zhuravlev distances | D19: Zhuravlev Distances | E19: ρ(x, y) = Σ(j∈I) |x′ⱼ − y′ⱼ| + Σ(j∈J) [xⱼ ≠ yⱼ], rounded to 10 decimals. → metrics.zhuravlev(x, y, types), metrics.distance_matrix(...)
B20: 4 | C20: Sort neighbours | D20: Sorted Neighbors | E20: For each Sᵢ: all Sⱼ ≠ Sᵢ ordered by (ρ(Sᵢ, Sⱼ), j); each neighbour keeps its original index j and class. → neighbours.sorted_neighbours(D, y)
B21: 5 | C21: Synthetic Features based on k-NN | D21: Synthetic Features (k-NN) | E21: k = 3, 5, …, k_max with k_min = 3 fixed and k_max = 2·min|Kᵢ| − 3 (class sizes from the data): count of same-class objects among the first k neighbours. → features.permitted_k(y), features.same_class_counts(neigh, y, ks)
B23: Key figures
B24: # | C24: Figure | D24: Value | E24: Linked to
B25: 1 | C25: Objects (samples) | D25: =COUNT(Dataset!O3:O12) -> 10 | E25: Dataset · O3:O12
B26: 2 | C26: Features | D26: =COUNT(Dataset!B3:N3) -> 13 | E26: Dataset · B3:N3
B27: 3 | C27: Quantitative features (set I) | D27: =SUM(Dataset!B13:N13) -> 6 | E27: Dataset · B13:N13
B28: 4 | C28: Nominal features (set J) | D28: =COUNTIF(Dataset!B13:N13,0) -> 7 | E28: Dataset · B13:N13
B29: 5 | C29: Objects in class 1 (K1) | D29: =COUNTIF(Dataset!O3:O12,1) -> 4 | E29: Dataset · O3:O12
B30: 6 | C30: Objects in class 2 (K2) | D30: =COUNTIF(Dataset!O3:O12,2) -> 6 | E30: Dataset · O3:O12
B31: 7 | C31: Smallest class min |Kᵢ| | D31: ='Synthetic Features (k-NN)'!G8 -> 4 | E31: Synthetic Features (k-NN) · parameters
B32: 8 | C32: k_max = 2 · min |Kᵢ| − 3 | D32: ='Synthetic Features (k-NN)'!G10 -> 5 | E32: Synthetic Features (k-NN) · parameters
B33: 9 | C33: Permitted k values | D33: ='Synthetic Features (k-NN)'!G11 -> 3, 5 | E33: Synthetic Features (k-NN) · parameters
B34: 10 | C34: Nearest neighbour of S₁ | D34: ='Sorted Neighbors'!B19 -> S₉ | E34: Sorted Neighbors · S₁ block, rank 1
B36: Colour legend
B37: Aa | C37: Sheet title bar
B38: Aa | C38: Table / block title bar
B39: Aa | C39: Column header (x₁ … x₁₃, S₁ … S₁₀, rank, k)
B40: Aa | C40: Object label S₁ … S₁₀, neighbour names and row captions
B41: Aa | C41: Quantitative feature values (original or normalized)
B42: Aa | C42: Nominal feature values
B43: Aa | C43: Class label (1 / 2)
B44: Aa | C44: Feature-type flag (1 = quantitative, 0 = nominal)
B45: Aa | C45: Neighbour of the same class as the target (Step 3)
...

Sheet Dataset
A1: Heart + Disease (10, 13, 2)
A2: № | O2: Class | Q2: K1 = 4
B3: 70 | C3: 1 | D3: 4 | E3: 130 | F3: 322 | G3: 0 | H3: 2 | I3: 109 | J3: 0 | K3: 2.4 | L3: 2 | M3: 3 | N3: 3 | O3: 2 | Q3: K2 = 6
B4: 67 | C4: 0 | D4: 3 | E4: 115 | F4: 564 | G4: 0 | H4: 2 | I4: 160 | J4: 0 | K4: 1.6 | L4: 2 | M4: 0 | N4: 7 | O4: 1
B5: 57 | C5: 1 | D5: 2 | E5: 124 | F5: 261 | G5: 0 | H5: 0 | I5: 141 | J5: 0 | K5: 0.3 | L5: 1 | M5: 0 | N5: 7 | O5: 2 | Q5: Sign of Quantitative Features - | T5: 1
B6: 64 | C6: 1 | D6: 4 | E6: 128 | F6: 263 | G6: 0 | H6: 0 | I6: 105 | J6: 1 | K6: 0.2 | L6: 2 | M6: 1 | N6: 7 | O6: 1 | Q6: Sign of Nominal Features - | T6: 0
B7: 74 | C7: 0 | D7: 2 | E7: 120 | F7: 269 | G7: 0 | H7: 2 | I7: 121 | J7: 1 | K7: 0.2 | L7: 1 | M7: 1 | N7: 3 | O7: 1
B8: 65 | C8: 1 | D8: 4 | E8: 120 | F8: 177 | G8: 0 | H8: 0 | I8: 140 | J8: 0 | K8: 0.4 | L8: 1 | M8: 0 | N8: 7 | O8: 1
B9: 56 | C9: 1 | D9: 3 | E9: 130 | F9: 256 | G9: 1 | H9: 2 | I9: 142 | J9: 1 | K9: 0.6 | L9: 2 | M9: 1 | N9: 6 | O9: 2
B10: 59 | C10: 1 | D10: 4 | E10: 110 | F10: 239 | G10: 0 | H10: 2 | I10: 142 | J10: 1 | K10: 1.2 | L10: 2 | M10: 1 | N10: 7 | O10: 2
B11: 60 | C11: 1 | D11: 4 | E11: 140 | F11: 293 | G11: 0 | H11: 2 | I11: 170 | J11: 0 | K11: 1.2 | L11: 2 | M11: 2 | N11: 7 | O11: 2
B12: 63 | C12: 0 | D12: 4 | E12: 150 | F12: 407 | G12: 0 | H12: 2 | I12: 154 | J12: 0 | K12: 4 | L12: 2 | M12: 3 | N12: 7 | O12: 2
B13: 1 | C13: 0 | D13: 0 | E13: 1 | F13: 1 | G13: 0 | H13: 0 | I13: 1 | J13: 0 | K13: 1 | L13: 0 | M13: 1 | N13: 0
B17: Total Number of Quantitative Features - | F17: 6 | L17: Total Number of Nominal Features - | P17: 7
A19: Quantitative Features | K19: Nominal Features
A20: № | H20: Class | K20: № | S20: Class
B21: 70 | C21: 130 | D21: 322 | E21: 109 | F21: 2.4 | G21: 3 | H21: 2 | L21: 1 | M21: 4 | N21: 0 | O21: 2 | P21: 0 | Q21: 2 | R21: 3 | S21: 2
B22: 67 | C22: 115 | D22: 564 | E22: 160 | F22: 1.6 | G22: 0 | H22: 1 | L22: 0 | M22: 3 | N22: 0 | O22: 2 | P22: 0 | Q22: 2 | R22: 7 | S22: 1
B23: 57 | C23: 124 | D23: 261 | E23: 141 | F23: 0.3 | G23: 0 | H23: 2 | L23: 1 | M23: 2 | N23: 0 | O23: 0 | P23: 0 | Q23: 1 | R23: 7 | S23: 2
B24: 64 | C24: 128 | D24: 263 | E24: 105 | F24: 0.2 | G24: 1 | H24: 1 | L24: 1 | M24: 4 | N24: 0 | O24: 0 | P24: 1 | Q24: 2 | R24: 7 | S24: 1
B25: 74 | C25: 120 | D25: 269 | E25: 121 | F25: 0.2 | G25: 1 | H25: 1 | L25: 0 | M25: 2 | N25: 0 | O25: 2 | P25: 1 | Q25: 1 | R25: 3 | S25: 1
B26: 65 | C26: 120 | D26: 177 | E26: 140 | F26: 0.4 | G26: 0 | H26: 1 | L26: 1 | M26: 4 | N26: 0 | O26: 0 | P26: 0 | Q26: 1 | R26: 7 | S26: 1
B27: 56 | C27: 130 | D27: 256 | E27: 142 | F27: 0.6 | G27: 1 | H27: 2 | L27: 1 | M27: 3 | N27: 1 | O27: 2 | P27: 1 | Q27: 2 | R27: 6 | S27: 2
B28: 59 | C28: 110 | D28: 239 | E28: 142 | F28: 1.2 | G28: 1 | H28: 2 | L28: 1 | M28: 4 | N28: 0 | O28: 2 | P28: 1 | Q28: 2 | R28: 7 | S28: 2
B29: 60 | C29: 140 | D29: 293 | E29: 170 | F29: 1.2 | G29: 2 | H29: 2 | L29: 1 | M29: 4 | N29: 0 | O29: 2 | P29: 0 | Q29: 2 | R29: 7 | S29: 2
B30: 63 | C30: 150 | D30: 407 | E30: 154 | F30: 4 | G30: 3 | H30: 2 | L30: 0 | M30: 4 | N30: 0 | O30: 2 | P30: 0 | Q30: 2 | R30: 7 | S30: 2
B31: 1 | C31: 1 | D31: 1 | E31: 1 | F31: 1 | G31: 1 | L31: 0 | M31: 0 | N31: 0 | O31: 0 | P31: 0 | Q31: 0 | R31: 0

Sheet Quantitative
A1: Quantitative Features
A2: № | H2: Class | K2: K1 = 4
B3: 70 | C3: 130 | D3: 322 | E3: 109 | F3: 2.4 | G3: 3 | H3: 2 | K3: K2 = 6 | M3: Color and Sign of Quantitative Features - | Q3: 1
B4: 67 | C4: 115 | D4: 564 | E4: 160 | F4: 1.6 | G4: 0 | H4: 1
B5: 57 | C5: 124 | D5: 261 | E5: 141 | F5: 0.3 | G5: 0 | H5: 2
B6: 64 | C6: 128 | D6: 263 | E6: 105 | F6: 0.2 | G6: 1 | H6: 1
B7: 74 | C7: 120 | D7: 269 | E7: 121 | F7: 0.2 | G7: 1 | H7: 1
B8: 65 | C8: 120 | D8: 177 | E8: 140 | F8: 0.4 | G8: 0 | H8: 1
B9: 56 | C9: 130 | D9: 256 | E9: 142 | F9: 0.6 | G9: 1 | H9: 2
B10: 59 | C10: 110 | D10: 239 | E10: 142 | F10: 1.2 | G10: 1 | H10: 2
B11: 60 | C11: 140 | D11: 293 | E11: 170 | F11: 1.2 | G11: 2 | H11: 2
B12: 63 | C12: 150 | D12: 407 | E12: 154 | F12: 4 | G12: 3 | H12: 2
B13: 1 | C13: 1 | D13: 1 | E13: 1 | F13: 1 | G13: 1

Sheet Nominal
A1: Nominal Features
A2: № | I2: Class | L2: K1 = 4
B3: 1 | C3: 4 | D3: 0 | E3: 2 | F3: 0 | G3: 2 | H3: 3 | I3: 2 | L3: K2 = 6 | N3: Color and Sign of Nominal Features - | R3: 0
B4: 0 | C4: 3 | D4: 0 | E4: 2 | F4: 0 | G4: 2 | H4: 7 | I4: 1
B5: 1 | C5: 2 | D5: 0 | E5: 0 | F5: 0 | G5: 1 | H5: 7 | I5: 2
B6: 1 | C6: 4 | D6: 0 | E6: 0 | F6: 1 | G6: 2 | H6: 7 | I6: 1
B7: 0 | C7: 2 | D7: 0 | E7: 2 | F7: 1 | G7: 1 | H7: 3 | I7: 1
B8: 1 | C8: 4 | D8: 0 | E8: 0 | F8: 0 | G8: 1 | H8: 7 | I8: 1
B9: 1 | C9: 3 | D9: 1 | E9: 2 | F9: 1 | G9: 2 | H9: 6 | I9: 2
B10: 1 | C10: 4 | D10: 0 | E10: 2 | F10: 1 | G10: 2 | H10: 7 | I10: 2
B11: 1 | C11: 4 | D11: 0 | E11: 2 | F11: 0 | G11: 2 | H11: 7 | I11: 2
B12: 0 | C12: 4 | D12: 0 | E12: 2 | F12: 0 | G12: 2 | H12: 7 | I12: 2
B13: 0 | C13: 0 | D13: 0 | E13: 0 | F13: 0 | G13: 0 | H13: 0

Sheet Normalized Dataset
A1: Step 1 · Normalized dataset — quantitative features mapped to [0, 1], nominal features unchanged
A3: Heart + Disease (10, 13, 2) after scale unification: x′ = (x − min) / (max − min) for j ∈ I
A4: № | B4: x₁ | C4: x₂ | D4: x₃ | E4: x₄ | F4: x₅ | G4: x₆ | H4: x₇ | I4: x₈ | J4: x₉ | K4: x₁₀ | L4: x₁₁ | M4: x₁₂ | N4: x₁₃ | O4: Class
A5: S₁ | B5: =IF(MAX(Dataset!B$3:B$12)=MIN(Dataset!B$3:B$12),0,(Dataset!B3-MIN(Dataset!B$3:B$12))/(MAX(Dataset!B$3:B$12)-MIN(Dataset!B$3:B$12))) -> 0.77777778 | C5: =Dataset!C3 -> 1 | D5: =Dataset!D3 -> 4 | E5: =IF(MAX(Dataset!E$3:E$12)=MIN(Dataset!E$3:E$12),0,(Dataset!E3-MIN(Dataset!E$3:E$12))/(MAX(Dataset!E$3:E$12)-MIN(Dataset!E$3:E$12))) -> 0.5 | F5: =IF(MAX(Dataset!F$3:F$12)=MIN(Dataset!F$3:F$12),0,(Dataset!F3-MIN(Dataset!F$3:F$12))/(MAX(Dataset!F$3:F$12)-MIN(Dataset!F$3:F$12))) -> 0.374677 | G5: =Dataset!G3 -> 0 | H5: =Dataset!H3 -> 2 | I5: =IF(MAX(Dataset!I$3:I$12)=MIN(Dataset!I$3:I$12),0,(Dataset!I3-MIN(Dataset!I$3:I$12))/(MAX(Dataset!I$3:I$12)-MIN(Dataset!I$3:I$12))) -> 0.061538462 | J5: =Dataset!J3 -> 0 | K5: =IF(MAX(Dataset!K$3:K$12)=MIN(Dataset!K$3:K$12),0,(Dataset!K3-MIN(Dataset!K$3:K$12))/(MAX(Dataset!K$3:K$12)-MIN(Dataset!K$3:K$12))) -> 0.57894737 | L5: =Dataset!L3 -> 2 | M5: =IF(MAX(Dataset!M$3:M$12)=MIN(Dataset!M$3:M$12),0,(Dataset!M3-MIN(Dataset!M$3:M$12))/(MAX(Dataset!M$3:M$12)-MIN(Dataset!M$3:M$12))) -> 1 | N5: =Dataset!N3 -> 3 | O5: =Dataset!O3 -> 2
A6: S₂ | B6: =IF(MAX(Dataset!B$3:B$12)=MIN(Dataset!B$3:B$12),0,(Dataset!B4-MIN(Dataset!B$3:B$12))/(MAX(Dataset!B$3:B$12)-MIN(Dataset!B$3:B$12))) -> 0.61111111 | C6: =Dataset!C4 -> 0 | D6: =Dataset!D4 -> 3 | E6: =IF(MAX(Dataset!E$3:E$12)=MIN(Dataset!E$3:E$12),0,(Dataset!E4-MIN(Dataset!E$3:E$12))/(MAX(Dataset!E$3:E$12)-MIN(Dataset!E$3:E$12))) -> 0.125 | F6: =IF(MAX(Dataset!F$3:F$12)=MIN(Dataset!F$3:F$12),0,(Dataset!F4-MIN(Dataset!F$3:F$12))/(MAX(Dataset!F$3:F$12)-MIN(Dataset!F$3:F$12))) -> 1 | G6: =Dataset!G4 -> 0 | H6: =Dataset!H4 -> 2 | I6: =IF(MAX(Dataset!I$3:I$12)=MIN(Dataset!I$3:I$12),0,(Dataset!I4-MIN(Dataset!I$3:I$12))/(MAX(Dataset!I$3:I$12)-MIN(Dataset!I$3:I$12))) -> 0.84615385 | J6: =Dataset!J4 -> 0 | K6: =IF(MAX(Dataset!K$3:K$12)=MIN(Dataset!K$3:K$12),0,(Dataset!K4-MIN(Dataset!K$3:K$12))/(MAX(Dataset!K$3:K$12)-MIN(Dataset!K$3:K$12))) -> 0.36842105 | L6: =Dataset!L4 -> 2 | M6: =IF(MAX(Dataset!M$3:M$12)=MIN(Dataset!M$3:M$12),0,(Dataset!M4-MIN(Dataset!M$3:M$12))/(MAX(Dataset!M$3:M$12)-MIN(Dataset!M$3:M$12))) -> 0 | N6: =Dataset!N4 -> 7 | O6: =Dataset!O4 -> 1
A7: S₃ | B7: =IF(MAX(Dataset!B$3:B$12)=MIN(Dataset!B$3:B$12),0,(Dataset!B5-MIN(Dataset!B$3:B$12))/(MAX(Dataset!B$3:B$12)-MIN(Dataset!B$3:B$12))) -> 0.055555556 | C7: =Dataset!C5 -> 1 | D7: =Dataset!D5 -> 2 | E7: =IF(MAX(Dataset!E$3:E$12)=MIN(Dataset!E$3:E$12),0,(Dataset!E5-MIN(Dataset!E$3:E$12))/(MAX(Dataset!E$3:E$12)-MIN(Dataset!E$3:E$12))) -> 0.35 | F7: =IF(MAX(Dataset!F$3:F$12)=MIN(Dataset!F$3:F$12),0,(Dataset!F5-MIN(Dataset!F$3:F$12))/(MAX(Dataset!F$3:F$12)-MIN(Dataset!F$3:F$12))) -> 0.21705426 | G7: =Dataset!G5 -> 0 | H7: =Dataset!H5 -> 0 | I7: =IF(MAX(Dataset!I$3:I$12)=MIN(Dataset!I$3:I$12),0,(Dataset!I5-MIN(Dataset!I$3:I$12))/(MAX(Dataset!I$3:I$12)-MIN(Dataset!I$3:I$12))) -> 0.55384615 | J7: =Dataset!J5 -> 0 | K7: =IF(MAX(Dataset!K$3:K$12)=MIN(Dataset!K$3:K$12),0,(Dataset!K5-MIN(Dataset!K$3:K$12))/(MAX(Dataset!K$3:K$12)-MIN(Dataset!K$3:K$12))) -> 0.026315789 | L7: =Dataset!L5 -> 1 | M7: =IF(MAX(Dataset!M$3:M$12)=MIN(Dataset!M$3:M$12),0,(Dataset!M5-MIN(Dataset!M$3:M$12))/(MAX(Dataset!M$3:M$12)-MIN(Dataset!M$3:M$12))) -> 0 | N7: =Dataset!N5 -> 7 | O7: =Dataset!O5 -> 2
A8: S₄ | B8: =IF(MAX(Dataset!B$3:B$12)=MIN(Dataset!B$3:B$12),0,(Dataset!B6-MIN(Dataset!B$3:B$12))/(MAX(Dataset!B$3:B$12)-MIN(Dataset!B$3:B$12))) -> 0.44444444 | C8: =Dataset!C6 -> 1 | D8: =Dataset!D6 -> 4 | E8: =IF(MAX(Dataset!E$3:E$12)=MIN(Dataset!E$3:E$12),0,(Dataset!E6-MIN(Dataset!E$3:E$12))/(MAX(Dataset!E$3:E$12)-MIN(Dataset!E$3:E$12))) -> 0.45 | F8: =IF(MAX(Dataset!F$3:F$12)=MIN(Dataset!F$3:F$12),0,(Dataset!F6-MIN(Dataset!F$3:F$12))/(MAX(Dataset!F$3:F$12)-MIN(Dataset!F$3:F$12))) -> 0.22222222 | G8: =Dataset!G6 -> 0 | H8: =Dataset!H6 -> 0 | I8: =IF(MAX(Dataset!I$3:I$12)=MIN(Dataset!I$3:I$12),0,(Dataset!I6-MIN(Dataset!I$3:I$12))/(MAX(Dataset!I$3:I$12)-MIN(Dataset!I$3:I$12))) -> 0 | J8: =Dataset!J6 -> 1 | K8: =IF(MAX(Dataset!K$3:K$12)=MIN(Dataset!K$3:K$12),0,(Dataset!K6-MIN(Dataset!K$3:K$12))/(MAX(Dataset!K$3:K$12)-MIN(Dataset!K$3:K$12))) -> 0 | L8: =Dataset!L6 -> 2 | M8: =IF(MAX(Dataset!M$3:M$12)=MIN(Dataset!M$3:M$12),0,(Dataset!M6-MIN(Dataset!M$3:M$12))/(MAX(Dataset!M$3:M$12)-MIN(Dataset!M$3:M$12))) -> 0.33333333 | N8: =Dataset!N6 -> 7 | O8: =Dataset!O6 -> 1
A9: S₅ | B9: =IF(MAX(Dataset!B$3:B$12)=MIN(Dataset!B$3:B$12),0,(Dataset!B7-MIN(Dataset!B$3:B$12))/(MAX(Dataset!B$3:B$12)-MIN(Dataset!B$3:B$12))) -> 1 | C9: =Dataset!C7 -> 0 | D9: =Dataset!D7 -> 2 | E9: =IF(MAX(Dataset!E$3:E$12)=MIN(Dataset!E$3:E$12),0,(Dataset!E7-MIN(Dataset!E$3:E$12))/(MAX(Dataset!E$3:E$12)-MIN(Dataset!E$3:E$12))) -> 0.25 | F9: =IF(MAX(Dataset!F$3:F$12)=MIN(Dataset!F$3:F$12),0,(Dataset!F7-MIN(Dataset!F$3:F$12))/(MAX(Dataset!F$3:F$12)-MIN(Dataset!F$3:F$12))) -> 0.2377261 | G9: =Dataset!G7 -> 0 | H9: =Dataset!H7 -> 2 | I9: =IF(MAX(Dataset!I$3:I$12)=MIN(Dataset!I$3:I$12),0,(Dataset!I7-MIN(Dataset!I$3:I$12))/(MAX(Dataset!I$3:I$12)-MIN(Dataset!I$3:I$12))) -> 0.24615385 | J9: =Dataset!J7 -> 1 | K9: =IF(MAX(Dataset!K$3:K$12)=MIN(Dataset!K$3:K$12),0,(Dataset!K7-MIN(Dataset!K$3:K$12))/(MAX(Dataset!K$3:K$12)-MIN(Dataset!K$3:K$12))) -> 0 | L9: =Dataset!L7 -> 1 | M9: =IF(MAX(Dataset!M$3:M$12)=MIN(Dataset!M$3:M$12),0,(Dataset!M7-MIN(Dataset!M$3:M$12))/(MAX(Dataset!M$3:M$12)-MIN(Dataset!M$3:M$12))) -> 0.33333333 | N9: =Dataset!N7 -> 3 | O9: =Dataset!O7 -> 1
A10: S₆ | B10: =IF(MAX(Dataset!B$3:B$12)=MIN(Dataset!B$3:B$12),0,(Dataset!B8-MIN(Dataset!B$3:B$12))/(MAX(Dataset!B$3:B$12)-MIN(Dataset!B$3:B$12))) -> 0.5 | C10: =Dataset!C8 -> 1 | D10: =Dataset!D8 -> 4 | E10: =IF(MAX(Dataset!E$3:E$12)=MIN(Dataset!E$3:E$12),0,(Dataset!E8-MIN(Dataset!E$3:E$12))/(MAX(Dataset!E$3:E$12)-MIN(Dataset!E$3:E$12))) -> 0.25 | F10: =IF(MAX(Dataset!F$3:F$12)=MIN(Dataset!F$3:F$12),0,(Dataset!F8-MIN(Dataset!F$3:F$12))/(MAX(Dataset!F$3:F$12)-MIN(Dataset!F$3:F$12))) -> 0 | G10: =Dataset!G8 -> 0 | H10: =Dataset!H8 -> 0 | I10: =IF(MAX(Dataset!I$3:I$12)=MIN(Dataset!I$3:I$12),0,(Dataset!I8-MIN(Dataset!I$3:I$12))/(MAX(Dataset!I$3:I$12)-MIN(Dataset!I$3:I$12))) -> 0.53846154 | J10: =Dataset!J8 -> 0 | K10: =IF(MAX(Dataset!K$3:K$12)=MIN(Dataset!K$3:K$12),0,(Dataset!K8-MIN(Dataset!K$3:K$12))/(MAX(Dataset!K$3:K$12)-MIN(Dataset!K$3:K$12))) -> 0.052631579 | L10: =Dataset!L8 -> 1 | M10: =IF(MAX(Dataset!M$3:M$12)=MIN(Dataset!M$3:M$12),0,(Dataset!M8-MIN(Dataset!M$3:M$12))/(MAX(Dataset!M$3:M$12)-MIN(Dataset!M$3:M$12))) -> 0 | N10: =Dataset!N8 -> 7 | O10: =Dataset!O8 -> 1
A11: S₇ | B11: =IF(MAX(Dataset!B$3:B$12)=MIN(Dataset!B$3:B$12),0,(Dataset!B9-MIN(Dataset!B$3:B$12))/(MAX(Dataset!B$3:B$12)-MIN(Dataset!B$3:B$12))) -> 0 | C11: =Dataset!C9 -> 1 | D11: =Dataset!D9 -> 3 | E11: =IF(MAX(Dataset!E$3:E$12)=MIN(Dataset!E$3:E$12),0,(Dataset!E9-MIN(Dataset!E$3:E$12))/(MAX(Dataset!E$3:E$12)-MIN(Dataset!E$3:E$12))) -> 0.5 | F11: =IF(MAX(Dataset!F$3:F$12)=MIN(Dataset!F$3:F$12),0,(Dataset!F9-MIN(Dataset!F$3:F$12))/(MAX(Dataset!F$3:F$12)-MIN(Dataset!F$3:F$12))) -> 0.20413437 | G11: =Dataset!G9 -> 1 | H11: =Dataset!H9 -> 2 | I11: =IF(MAX(Dataset!I$3:I$12)=MIN(Dataset!I$3:I$12),0,(Dataset!I9-MIN(Dataset!I$3:I$12))/(MAX(Dataset!I$3:I$12)-MIN(Dataset!I$3:I$12))) -> 0.56923077 | J11: =Dataset!J9 -> 1 | K11: =IF(MAX(Dataset!K$3:K$12)=MIN(Dataset!K$3:K$12),0,(Dataset!K9-MIN(Dataset!K$3:K$12))/(MAX(Dataset!K$3:K$12)-MIN(Dataset!K$3:K$12))) -> 0.10526316 | L11: =Dataset!L9 -> 2 | M11: =IF(MAX(Dataset!M$3:M$12)=MIN(Dataset!M$3:M$12),0,(Dataset!M9-MIN(Dataset!M$3:M$12))/(MAX(Dataset!M$3:M$12)-MIN(Dataset!M$3:M$12))) -> 0.33333333 | N11: =Dataset!N9 -> 6 | O11: =Dataset!O9 -> 2
A12: S₈ | B12: =IF(MAX(Dataset!B$3:B$12)=MIN(Dataset!B$3:B$12),0,(Dataset!B10-MIN(Dataset!B$3:B$12))/(MAX(Dataset!B$3:B$12)-MIN(Dataset!B$3:B$12))) -> 0.16666667 | C12: =Dataset!C10 -> 1 | D12: =Dataset!D10 -> 4 | E12: =IF(MAX(Dataset!E$3:E$12)=MIN(Dataset!E$3:E$12),0,(Dataset!E10-MIN(Dataset!E$3:E$12))/(MAX(Dataset!E$3:E$12)-MIN(Dataset!E$3:E$12))) -> 0 | F12: =IF(MAX(Dataset!F$3:F$12)=MIN(Dataset!F$3:F$12),0,(Dataset!F10-MIN(Dataset!F$3:F$12))/(MAX(Dataset!F$3:F$12)-MIN(Dataset!F$3:F$12))) -> 0.16020672 | G12: =Dataset!G10 -> 0 | H12: =Dataset!H10 -> 2 | I12: =IF(MAX(Dataset!I$3:I$12)=MIN(Dataset!I$3:I$12),0,(Dataset!I10-MIN(Dataset!I$3:I$12))/(MAX(Dataset!I$3:I$12)-MIN(Dataset!I$3:I$12))) -> 0.56923077 | J12: =Dataset!J10 -> 1 | K12: =IF(MAX(Dataset!K$3:K$12)=MIN(Dataset!K$3:K$12),0,(Dataset!K10-MIN(Dataset!K$3:K$12))/(MAX(Dataset!K$3:K$12)-MIN(Dataset!K$3:K$12))) -> 0.26315789 | L12: =Dataset!L10 -> 2 | M12: =IF(MAX(Dataset!M$3:M$12)=MIN(Dataset!M$3:M$12),0,(Dataset!M10-MIN(Dataset!M$3:M$12))/(MAX(Dataset!M$3:M$12)-MIN(Dataset!M$3:M$12))) -> 0.33333333 | N12: =Dataset!N10 -> 7 | O12: =Dataset!O10 -> 2
A13: S₉ | B13: =IF(MAX(Dataset!B$3:B$12)=MIN(Dataset!B$3:B$12),0,(Dataset!B11-MIN(Dataset!B$3:B$12))/(MAX(Dataset!B$3:B$12)-MIN(Dataset!B$3:B$12))) -> 0.22222222 | C13: =Dataset!C11 -> 1 | D13: =Dataset!D11 -> 4 | E13: =IF(MAX(Dataset!E$3:E$12)=MIN(Dataset!E$3:E$12),0,(Dataset!E11-MIN(Dataset!E$3:E$12))/(MAX(Dataset!E$3:E$12)-MIN(Dataset!E$3:E$12))) -> 0.75 | F13: =IF(MAX(Dataset!F$3:F$12)=MIN(Dataset!F$3:F$12),0,(Dataset!F11-MIN(Dataset!F$3:F$12))/(MAX(Dataset!F$3:F$12)-MIN(Dataset!F$3:F$12))) -> 0.2997416 | G13: =Dataset!G11 -> 0 | H13: =Dataset!H11 -> 2 | I13: =IF(MAX(Dataset!I$3:I$12)=MIN(Dataset!I$3:I$12),0,(Dataset!I11-MIN(Dataset!I$3:I$12))/(MAX(Dataset!I$3:I$12)-MIN(Dataset!I$3:I$12))) -> 1 | J13: =Dataset!J11 -> 0 | K13: =IF(MAX(Dataset!K$3:K$12)=MIN(Dataset!K$3:K$12),0,(Dataset!K11-MIN(Dataset!K$3:K$12))/(MAX(Dataset!K$3:K$12)-MIN(Dataset!K$3:K$12))) -> 0.26315789 | L13: =Dataset!L11 -> 2 | M13: =IF(MAX(Dataset!M$3:M$12)=MIN(Dataset!M$3:M$12),0,(Dataset!M11-MIN(Dataset!M$3:M$12))/(MAX(Dataset!M$3:M$12)-MIN(Dataset!M$3:M$12))) -> 0.66666667 | N13: =Dataset!N11 -> 7 | O13: =Dataset!O11 -> 2
A14: S₁₀ | B14: =IF(MAX(Dataset!B$3:B$12)=MIN(Dataset!B$3:B$12),0,(Dataset!B12-MIN(Dataset!B$3:B$12))/(MAX(Dataset!B$3:B$12)-MIN(Dataset!B$3:B$12))) -> 0.38888889 | C14: =Dataset!C12 -> 0 | D14: =Dataset!D12 -> 4 | E14: =IF(MAX(Dataset!E$3:E$12)=MIN(Dataset!E$3:E$12),0,(Dataset!E12-MIN(Dataset!E$3:E$12))/(MAX(Dataset!E$3:E$12)-MIN(Dataset!E$3:E$12))) -> 1 | F14: =IF(MAX(Dataset!F$3:F$12)=MIN(Dataset!F$3:F$12),0,(Dataset!F12-MIN(Dataset!F$3:F$12))/(MAX(Dataset!F$3:F$12)-MIN(Dataset!F$3:F$12))) -> 0.59431525 | G14: =Dataset!G12 -> 0 | H14: =Dataset!H12 -> 2 | I14: =IF(MAX(Dataset!I$3:I$12)=MIN(Dataset!I$3:I$12),0,(Dataset!I12-MIN(Dataset!I$3:I$12))/(MAX(Dataset!I$3:I$12)-MIN(Dataset!I$3:I$12))) -> 0.75384615 | J14: =Dataset!J12 -> 0 | K14: =IF(MAX(Dataset!K$3:K$12)=MIN(Dataset!K$3:K$12),0,(Dataset!K12-MIN(Dataset!K$3:K$12))/(MAX(Dataset!K$3:K$12)-MIN(Dataset!K$3:K$12))) -> 1 | L14: =Dataset!L12 -> 2 | M14: =IF(MAX(Dataset!M$3:M$12)=MIN(Dataset!M$3:M$12),0,(Dataset!M12-MIN(Dataset!M$3:M$12))/(MAX(Dataset!M$3:M$12)-MIN(Dataset!M$3:M$12))) -> 1 | N14: =Dataset!N12 -> 7 | O14: =Dataset!O12 -> 2
A15: Type | B15: =Dataset!B13 -> 1 | C15: =Dataset!C13 -> 0 | D15: =Dataset!D13 -> 0 | E15: =Dataset!E13 -> 1 | F15: =Dataset!F13 -> 1 | G15: =Dataset!G13 -> 0 | H15: =Dataset!H13 -> 0 | I15: =Dataset!I13 -> 1 | ... N15: =Dataset!N13 -> 0 | O15: 1 = I
A16: min | B16: =MIN(Dataset!B$3:B$12) -> 56 | C16: — | D16: — | E16: =MIN(Dataset!E$3:E$12) -> 110 | F16: =MIN(Dataset!F$3:F$12) -> 177 | G16: — | H16: — | I16: =MIN(Dataset!I$3:I$12) -> 105 | J16: — | K16: =MIN(Dataset!K$3:K$12) -> 0.2 | L16: — | M16: =MIN(Dataset!M$3:M$12) -> 0 | N16: —
A17: max | B17: =MAX(Dataset!B$3:B$12) -> 74 | C17: — | D17: — | E17: =MAX(Dataset!E$3:E$12) -> 150 | F17: =MAX(Dataset!F$3:F$12) -> 564 | G17: — | H17: — | I17: =MAX(Dataset!I$3:I$12) -> 170 | J17: — | K17: =MAX(Dataset!K$3:K$12) -> 4 | L17: — | M17: =MAX(Dataset!M$3:M$12) -> 3 | N17: —
A19: Type 1 = quantitative feature (set I): the value is rescaled to [0, 1] with the fractional-linear (min–max) transform; min and max are taken over S₁ … S₁₀.
A20: Type 0 = nominal feature (set J): the original code is kept, because the metric only asks whether two codes are equal.
A21: All cells are formulas linked to the Dataset sheet (values B3:N12, classes O3:O12, type flags B13:N13).

Sheet Zhuravlev Distances
A1: Step 2 · Pairwise distances — Zhuravlev metric ρ(x, y) = Σ(j∈I) |x′ⱼ − y′ⱼ| + Σ(j∈J) [xⱼ ≠ yⱼ]
A3: Zhuravlev distance ρ(Sᵢ, Sⱼ) — row = target object Sᵢ, column = object Sⱼ in original order
A4: ρ | B4: S₁ | C4: S₂ | D4: S₃ | E4: S₄ | F4: S₅ | G4: S₆ | H4: S₇ | I4: S₈ | J4: S₉ | K4: S₁₀
A5: S₁ | B5: =ROUND(B18+B31,10) -> 0 | C5: =ROUND(C18+C31,10) -> 6.1621314 | D5: =ROUND(D18+D31,10) -> 7.0747842 | E5: =ROUND(E18+E31,10) -> 4.8429406 | F5: =ROUND(F18+F31,10) -> 6.0394025 | G5: =ROUND(G18+G31,10) -> 5.9056936 | H5: =ROUND(H18+H31,10) -> 6.5963636 | I5: =ROUND(I18+I31,10) -> 4.8157298 | ... K5: =ROUND(K18+K31,10) -> 4.2218875
A6: S₂ | B6: =ROUND(B19+B32,10) -> 6.1621314 | C6: =ROUND(C19+C32,10) -> 0 | D6: =ROUND(D19+D32,10) -> 6.1979142 | E6: =ROUND(E19+E32,10) -> 6.8173527 | F6: =ROUND(F19+F32,10) -> 6.5779172 | G6: =ROUND(G19+G32,10) -> 5.8595929 | H6: =ROUND(H19+H32,10) -> 6.655391 | I6: =ROUND(I19+I32,10) -> 5.1247573 | ... K6: =ROUND(K19+K32,10) -> 4.2267936
A7: S₃ | B7: =ROUND(B20+B33,10) -> 7.0747842 | C7: =ROUND(C20+C33,10) -> 6.1979142 | D7: =ROUND(D20+D33,10) -> 0 | E7: =ROUND(E20+E33,10) -> 4.4075521 | F7: =ROUND(F20+F33,10) -> 5.7324577 | G7: =ROUND(G20+G33,10) -> 1.8031991 | H7: =ROUND(H20+H33,10) -> 6.6461408 | I7: =ROUND(I20+I33,10) -> 5.1035187 | ... K7: =ROUND(K20+K33,10) -> 7.5342785
A8: S₄ | B8: =ROUND(B21+B34,10) -> 4.8429406 | C8: =ROUND(C21+C34,10) -> 6.8173527 | D8: =ROUND(D21+D34,10) -> 4.4075521 | E8: =ROUND(E21+E34,10) -> 0 | F8: =ROUND(F21+F34,10) -> 6.0172133 | G8: =ROUND(G21+G34,10) -> 3.4022042 | H8: =ROUND(H21+H34,10) -> 5.1870262 | I8: =ROUND(I21+I34,10) -> 2.6221819 | ... K8: =ROUND(K21+K34,10) -> 6.3981614
A9: S₅ | B9: =ROUND(B22+B35,10) -> 6.0394025 | C9: =ROUND(C22+C35,10) -> 6.5779172 | D9: =ROUND(D22+D35,10) -> 5.7324577 | E9: =ROUND(E22+E35,10) -> 6.0172133 | F9: =ROUND(F22+F35,10) -> 0 | G9: =ROUND(G22+G35,10) -> 6.4159987 | H9: =ROUND(H22+H35,10) -> 6.7119318 | I9: =ROUND(I22+I35,10) -> 5.7470875 | ... K9: =ROUND(K22+K35,10) -> 7.8920592
A10: S₆ | B10: =ROUND(B23+B36,10) -> 5.9056936 | C10: =ROUND(C23+C36,10) -> 5.8595929 | D10: =ROUND(D23+D36,10) -> 1.8031991 | E10: =ROUND(E23+E36,10) -> 3.4022042 | F10: =ROUND(F23+F36,10) -> 6.4159987 | G10: =ROUND(G23+G36,10) -> 0 | H10: =ROUND(H23+H36,10) -> 7.3708685 | I10: =ROUND(I23+I36,10) -> 4.3181689 | ... K10: =ROUND(K23+K36,10) -> 6.6181794
A11: S₇ | B11: =ROUND(B24+B37,10) -> 6.5963636 | C11: =ROUND(C24+C37,10) -> 6.655391 | D11: =ROUND(D24+D37,10) -> 6.6461408 | E11: =ROUND(E24+E37,10) -> 5.1870262 | F11: =ROUND(F24+F37,10) -> 6.7119318 | G11: =ROUND(G24+G37,10) -> 7.3708685 | H11: =ROUND(H24+H37,10) -> 0 | I11: =ROUND(I24+I37,10) -> 3.8684891 | ... K11: =ROUND(K24+K37,10) -> 8.0250887
A12: S₈ | B12: =ROUND(B25+B38,10) -> 4.8157298 | C12: =ROUND(C25+C38,10) -> 5.1247573 | D12: =ROUND(D25+D38,10) -> 5.1035187 | E12: =ROUND(E25+E38,10) -> 2.6221819 | F12: =ROUND(F25+F38,10) -> 5.7470875 | G12: =ROUND(G25+G38,10) -> 4.3181689 | H12: =ROUND(H25+H38,10) -> 3.8684891 | I12: =ROUND(I25+I38,10) -> 0 | ... K12: =ROUND(K25+K38,10) -> 5.2444549
A13: S₉ | B13: =ROUND(B26+B39,10) -> 3.4680753 | C13: =ROUND(C26+C39,10) -> 4.6399233 | D13: =ROUND(D26+D39,10) -> 4.9990166 | E13: =ROUND(E26+E39,10) -> 4.1962328 | F13: =ROUND(F26+F39,10) -> 7.6901307 | G13: =ROUND(G26+G39,10) -> 4.4162508 | H13: =ROUND(H26+H39,10) -> 5.4898268 | I13: =ROUND(I26+I39,10) -> 2.709193 | ... K13: =ROUND(K26+K39,10) -> 3.0275696
A14: S₁₀ | B14: =ROUND(B27+B40,10) -> 4.2218875 | C14: =ROUND(C27+C40,10) -> 4.2267936 | D14: =ROUND(D27+D40,10) -> 7.5342785 | E14: =ROUND(E27+E40,10) -> 6.3981614 | F14: =ROUND(F27+F40,10) -> 7.8920592 | G14: =ROUND(G27+G40,10) -> 6.6181794 | H14: =ROUND(H27+H40,10) -> 8.0250887 | I14: =ROUND(I27+I40,10) -> 5.2444549 | ... K14: =ROUND(K27+K40,10) -> 0
A16: Quantitative part Σ(j∈I) |x′ⱼ − y′ⱼ| (normalized values from Step 1)
A17: № | B17: S₁ | C17: S₂ | D17: S₃ | E17: S₄ | F17: S₅ | G17: S₆ | H17: S₇ | I17: S₈ | J17: S₉ | K17: S₁₀
A18: S₁ | B18: =SUMPRODUCT(Dataset!$B$13:$N$13,ABS('Normalized Dataset'!$B$5:$N$5-'Normalized Dataset'!$B$5:$N$5)) -> 0 | C18: =SUMPRODUCT(Dataset!$B$13:$N$13,ABS('Normalized Dataset'!$B$5:$N$5-'Normalized Dataset'!$B$6:$N$6)) -> 3.1621314 | D18: =SUMPRODUCT(Dataset!$B$13:$N$13,ABS('Normalized Dataset'!$B$5:$N$5-'Normalized Dataset'!$B$7:$N$7)) -> 3.0747842 | E18: =SUMPRODUCT(Dataset!$B$13:$N$13,ABS('Normalized Dataset'!$B$5:$N$5-'Normalized Dataset'!$B$8:$N$8)) -> 1.8429406 | F18: =SUMPRODUCT(Dataset!$B$13:$N$13,ABS('Normalized Dataset'!$B$5:$N$5-'Normalized Dataset'!$B$9:$N$9)) -> 2.0394025 | G18: =SUMPRODUCT(Dataset!$B$13:$N$13,ABS('Normalized Dataset'!$B$5:$N$5-'Normalized Dataset'!$B$10:$N$10)) -> 2.9056936 | H18: =SUMPRODUCT(Dataset!$B$13:$N$13,ABS('Normalized Dataset'!$B$5:$N$5-'Normalized Dataset'!$B$11:$N$11)) -> 2.5963636 | I18: =SUMPRODUCT(Dataset!$B$13:$N$13,ABS('Normalized Dataset'!$B$5:$N$5-'Normalized Dataset'!$B$12:$N$12)) -> 2.8157298 | J18: =SUMPRODUCT(Dataset!$B$13:$N$13,ABS('Normalized Dataset'!$B$5:$N$5-'Normalized Dataset'!$B$13:$N$13)) -> 2.4680753 | K18: =SUMPRODUCT(Dataset!$B$13:$N$13,ABS('Normalized Dataset'!$B$5:$N$5-'Normalized Dataset'!$B$14:$N$14)) -> 2.2218875
A19: S₂ | B19: =SUMPRODUCT(Dataset!$B$13:$N$13,ABS('Normalized Dataset'!$B$6:$N$6-'Normalized Dataset'!$B$5:$N$5)) -> 3.1621314 | C19: =SUMPRODUCT(Dataset!$B$13:$N$13,ABS('Normalized Dataset'!$B$6:$N$6-'Normalized Dataset'!$B$6:$N$6)) -> 0 | D19: =SUMPRODUCT(Dataset!$B$13:$N$13,ABS('Normalized Dataset'!$B$6:$N$6-'Normalized Dataset'!$B$7:$N$7)) -> 2.1979142 | E19: =SUMPRODUCT(Dataset!$B$13:$N$13,ABS('Normalized Dataset'!$B$6:$N$6-'Normalized Dataset'!$B$8:$N$8)) -> 2.8173527 | F19: =SUMPRODUCT(Dataset!$B$13:$N$13,ABS('Normalized Dataset'!$B$6:$N$6-'Normalized Dataset'!$B$9:$N$9)) -> 2.5779172 | G19: =SUMPRODUCT(Dataset!$B$13:$N$13,ABS('Normalized Dataset'!$B$6:$N$6-'Normalized Dataset'!$B$10:$N$10)) -> 1.8595929 | H19: =SUMPRODUCT(Dataset!$B$13:$N$13,ABS('Normalized Dataset'!$B$6:$N$6-'Normalized Dataset'!$B$11:$N$11)) -> 2.655391 | I19: =SUMPRODUCT(Dataset!$B$13:$N$13,ABS('Normalized Dataset'!$B$6:$N$6-'Normalized Dataset'!$B$12:$N$12)) -> 2.1247573 | J19: =SUMPRODUCT(Dataset!$B$13:$N$13,ABS('Normalized Dataset'!$B$6:$N$6-'Normalized Dataset'!$B$13:$N$13)) -> 2.6399233 | K19: =SUMPRODUCT(Dataset!$B$13:$N$13,ABS('Normalized Dataset'!$B$6:$N$6-'Normalized Dataset'!$B$14:$N$14)) -> 3.2267936
A20: S₃ | B20: =SUMPRODUCT(Dataset!$B$13:$N$13,ABS('Normalized Dataset'!$B$7:$N$7-'Normalized Dataset'!$B$5:$N$5)) -> 3.0747842 | C20: =SUMPRODUCT(Dataset!$B$13:$N$13,ABS('Normalized Dataset'!$B$7:$N$7-'Normalized Dataset'!$B$6:$N$6)) -> 2.1979142 | D20: =SUMPRODUCT(Dataset!$B$13:$N$13,ABS('Normalized Dataset'!$B$7:$N$7-'Normalized Dataset'!$B$7:$N$7)) -> 0 | E20: =SUMPRODUCT(Dataset!$B$13:$N$13,ABS('Normalized Dataset'!$B$7:$N$7-'Normalized Dataset'!$B$8:$N$8)) -> 1.4075521 | F20: =SUMPRODUCT(Dataset!$B$13:$N$13,ABS('Normalized Dataset'!$B$7:$N$7-'Normalized Dataset'!$B$9:$N$9)) -> 1.7324577 | G20: =SUMPRODUCT(Dataset!$B$13:$N$13,ABS('Normalized Dataset'!$B$7:$N$7-'Normalized Dataset'!$B$10:$N$10)) -> 0.80319911 | H20: =SUMPRODUCT(Dataset!$B$13:$N$13,ABS('Normalized Dataset'!$B$7:$N$7-'Normalized Dataset'!$B$11:$N$11)) -> 0.64614077 | I20: =SUMPRODUCT(Dataset!$B$13:$N$13,ABS('Normalized Dataset'!$B$7:$N$7-'Normalized Dataset'!$B$12:$N$12)) -> 1.1035187 | J20: =SUMPRODUCT(Dataset!$B$13:$N$13,ABS('Normalized Dataset'!$B$7:$N$7-'Normalized Dataset'!$B$13:$N$13)) -> 1.9990166 | K20: =SUMPRODUCT(Dataset!$B$13:$N$13,ABS('Normalized Dataset'!$B$7:$N$7-'Normalized Dataset'!$B$14:$N$14)) -> 3.5342785
A21: S₄ | B21: =SUMPRODUCT(Dataset!$B$13:$N$13,ABS('Normalized Dataset'!$B$8:$N$8-'Normalized Dataset'!$B$5:$N$5)) -> 1.8429406 | C21: =SUMPRODUCT(Dataset!$B$13:$N$13,ABS('Normalized Dataset'!$B$8:$N$8-'Normalized Dataset'!$B$6:$N$6)) -> 2.8173527 | D21: =SUMPRODUCT(Dataset!$B$13:$N$13,ABS('Normalized Dataset'!$B$8:$N$8-'Normalized Dataset'!$B$7:$N$7)) -> 1.4075521 | E21: =SUMPRODUCT(Dataset!$B$13:$N$13,ABS('Normalized Dataset'!$B$8:$N$8-'Normalized Dataset'!$B$8:$N$8)) -> 0 | F21: =SUMPRODUCT(Dataset!$B$13:$N$13,ABS('Normalized Dataset'!$B$8:$N$8-'Normalized Dataset'!$B$9:$N$9)) -> 1.0172133 | G21: =SUMPRODUCT(Dataset!$B$13:$N$13,ABS('Normalized Dataset'!$B$8:$N$8-'Normalized Dataset'!$B$10:$N$10)) -> 1.4022042 | H21: =SUMPRODUCT(Dataset!$B$13:$N$13,ABS('Normalized Dataset'!$B$8:$N$8-'Normalized Dataset'!$B$11:$N$11)) -> 1.1870262 | I21: =SUMPRODUCT(Dataset!$B$13:$N$13,ABS('Normalized Dataset'!$B$8:$N$8-'Normalized Dataset'!$B$12:$N$12)) -> 1.6221819 | J21: =SUMPRODUCT(Dataset!$B$13:$N$13,ABS('Normalized Dataset'!$B$8:$N$8-'Normalized Dataset'!$B$13:$N$13)) -> 2.1962328 | K21: =SUMPRODUCT(Dataset!$B$13:$N$13,ABS('Normalized Dataset'!$B$8:$N$8-'Normalized Dataset'!$B$14:$N$14)) -> 3.3981614
A22: S₅ | B22: =SUMPRODUCT(Dataset!$B$13:$N$13,ABS('Normalized Dataset'!$B$9:$N$9-'Normalized Dataset'!$B$5:$N$5)) -> 2.0394025 | C22: =SUMPRODUCT(Dataset!$B$13:$N$13,ABS('Normalized Dataset'!$B$9:$N$9-'Normalized Dataset'!$B$6:$N$6)) -> 2.5779172 | D22: =SUMPRODUCT(Dataset!$B$13:$N$13,ABS('Normalized Dataset'!$B$9:$N$9-'Normalized Dataset'!$B$7:$N$7)) -> 1.7324577 | E22: =SUMPRODUCT(Dataset!$B$13:$N$13,ABS('Normalized Dataset'!$B$9:$N$9-'Normalized Dataset'!$B$8:$N$8)) -> 1.0172133 | F22: =SUMPRODUCT(Dataset!$B$13:$N$13,ABS('Normalized Dataset'!$B$9:$N$9-'Normalized Dataset'!$B$9:$N$9)) -> 0 | G22: =SUMPRODUCT(Dataset!$B$13:$N$13,ABS('Normalized Dataset'!$B$9:$N$9-'Normalized Dataset'!$B$10:$N$10)) -> 1.4159987 | H22: =SUMPRODUCT(Dataset!$B$13:$N$13,ABS('Normalized Dataset'!$B$9:$N$9-'Normalized Dataset'!$B$11:$N$11)) -> 1.7119318 | I22: =SUMPRODUCT(Dataset!$B$13:$N$13,ABS('Normalized Dataset'!$B$9:$N$9-'Normalized Dataset'!$B$12:$N$12)) -> 1.7470875 | J22: =SUMPRODUCT(Dataset!$B$13:$N$13,ABS('Normalized Dataset'!$B$9:$N$9-'Normalized Dataset'!$B$13:$N$13)) -> 2.6901307 | K22: =SUMPRODUCT(Dataset!$B$13:$N$13,ABS('Normalized Dataset'!$B$9:$N$9-'Normalized Dataset'!$B$14:$N$14)) -> 3.8920592
A23: S₆ | B23: =SUMPRODUCT(Dataset!$B$13:$N$13,ABS('Normalized Dataset'!$B$10:$N$10-'Normalized Dataset'!$B$5:$N$5)) -> 2.9056936 | C23: =SUMPRODUCT(Dataset!$B$13:$N$13,ABS('Normalized Dataset'!$B$10:$N$10-'Normalized Dataset'!$B$6:$N$6)) -> 1.8595929 | D23: =SUMPRODUCT(Dataset!$B$13:$N$13,ABS('Normalized Dataset'!$B$10:$N$10-'Normalized Dataset'!$B$7:$N$7)) -> 0.80319911 | E23: =SUMPRODUCT(Dataset!$B$13:$N$13,ABS('Normalized Dataset'!$B$10:$N$10-'Normalized Dataset'!$B$8:$N$8)) -> 1.4022042 | F23: =SUMPRODUCT(Dataset!$B$13:$N$13,ABS('Normalized Dataset'!$B$10:$N$10-'Normalized Dataset'!$B$9:$N$9)) -> 1.4159987 | G23: =SUMPRODUCT(Dataset!$B$13:$N$13,ABS('Normalized Dataset'!$B$10:$N$10-'Normalized Dataset'!$B$10:$N$10)) -> 0 | H23: =SUMPRODUCT(Dataset!$B$13:$N$13,ABS('Normalized Dataset'!$B$10:$N$10-'Normalized Dataset'!$B$11:$N$11)) -> 1.3708685 | I23: =SUMPRODUCT(Dataset!$B$13:$N$13,ABS('Normalized Dataset'!$B$10:$N$10-'Normalized Dataset'!$B$12:$N$12)) -> 1.3181689 | J23: =SUMPRODUCT(Dataset!$B$13:$N$13,ABS('Normalized Dataset'!$B$10:$N$10-'Normalized Dataset'!$B$13:$N$13)) -> 2.4162508 | K23: =SUMPRODUCT(Dataset!$B$13:$N$13,ABS('Normalized Dataset'!$B$10:$N$10-'Normalized Dataset'!$B$14:$N$14)) -> 3.6181794
A24: S₇ | B24: =SUMPRODUCT(Dataset!$B$13:$N$13,ABS('Normalized Dataset'!$B$11:$N$11-'Normalized Dataset'!$B$5:$N$5)) -> 2.5963636 | C24: =SUMPRODUCT(Dataset!$B$13:$N$13,ABS('Normalized Dataset'!$B$11:$N$11-'Normalized Dataset'!$B$6:$N$6)) -> 2.655391 | D24: =SUMPRODUCT(Dataset!$B$13:$N$13,ABS('Normalized Dataset'!$B$11:$N$11-'Normalized Dataset'!$B$7:$N$7)) -> 0.64614077 | E24: =SUMPRODUCT(Dataset!$B$13:$N$13,ABS('Normalized Dataset'!$B$11:$N$11-'Normalized Dataset'!$B$8:$N$8)) -> 1.1870262 | F24: =SUMPRODUCT(Dataset!$B$13:$N$13,ABS('Normalized Dataset'!$B$11:$N$11-'Normalized Dataset'!$B$9:$N$9)) -> 1.7119318 | G24: =SUMPRODUCT(Dataset!$B$13:$N$13,ABS('Normalized Dataset'!$B$11:$N$11-'Normalized Dataset'!$B$10:$N$10)) -> 1.3708685 | H24: =SUMPRODUCT(Dataset!$B$13:$N$13,ABS('Normalized Dataset'!$B$11:$N$11-'Normalized Dataset'!$B$11:$N$11)) -> 0 | I24: =SUMPRODUCT(Dataset!$B$13:$N$13,ABS('Normalized Dataset'!$B$11:$N$11-'Normalized Dataset'!$B$12:$N$12)) -> 0.86848905 | J24: =SUMPRODUCT(Dataset!$B$13:$N$13,ABS('Normalized Dataset'!$B$11:$N$11-'Normalized Dataset'!$B$13:$N$13)) -> 1.4898268 | K24: =SUMPRODUCT(Dataset!$B$13:$N$13,ABS('Normalized Dataset'!$B$11:$N$11-'Normalized Dataset'!$B$14:$N$14)) -> 3.0250887
A25: S₈ | B25: =SUMPRODUCT(Dataset!$B$13:$N$13,ABS('Normalized Dataset'!$B$12:$N$12-'Normalized Dataset'!$B$5:$N$5)) -> 2.8157298 | C25: =SUMPRODUCT(Dataset!$B$13:$N$13,ABS('Normalized Dataset'!$B$12:$N$12-'Normalized Dataset'!$B$6:$N$6)) -> 2.1247573 | D25: =SUMPRODUCT(Dataset!$B$13:$N$13,ABS('Normalized Dataset'!$B$12:$N$12-'Normalized Dataset'!$B$7:$N$7)) -> 1.1035187 | E25: =SUMPRODUCT(Dataset!$B$13:$N$13,ABS('Normalized Dataset'!$B$12:$N$12-'Normalized Dataset'!$B$8:$N$8)) -> 1.6221819 | F25: =SUMPRODUCT(Dataset!$B$13:$N$13,ABS('Normalized Dataset'!$B$12:$N$12-'Normalized Dataset'!$B$9:$N$9)) -> 1.7470875 | G25: =SUMPRODUCT(Dataset!$B$13:$N$13,ABS('Normalized Dataset'!$B$12:$N$12-'Normalized Dataset'!$B$10:$N$10)) -> 1.3181689 | H25: =SUMPRODUCT(Dataset!$B$13:$N$13,ABS('Normalized Dataset'!$B$12:$N$12-'Normalized Dataset'!$B$11:$N$11)) -> 0.86848905 | I25: =SUMPRODUCT(Dataset!$B$13:$N$13,ABS('Normalized Dataset'!$B$12:$N$12-'Normalized Dataset'!$B$12:$N$12)) -> 0 | J25: =SUMPRODUCT(Dataset!$B$13:$N$13,ABS('Normalized Dataset'!$B$12:$N$12-'Normalized Dataset'!$B$13:$N$13)) -> 1.709193 | K25: =SUMPRODUCT(Dataset!$B$13:$N$13,ABS('Normalized Dataset'!$B$12:$N$12-'Normalized Dataset'!$B$14:$N$14)) -> 3.2444549
A26: S₉ | B26: =SUMPRODUCT(Dataset!$B$13:$N$13,ABS('Normalized Dataset'!$B$13:$N$13-'Normalized Dataset'!$B$5:$N$5)) -> 2.4680753 | C26: =SUMPRODUCT(Dataset!$B$13:$N$13,ABS('Normalized Dataset'!$B$13:$N$13-'Normalized Dataset'!$B$6:$N$6)) -> 2.6399233 | D26: =SUMPRODUCT(Dataset!$B$13:$N$13,ABS('Normalized Dataset'!$B$13:$N$13-'Normalized Dataset'!$B$7:$N$7)) -> 1.9990166 | E26: =SUMPRODUCT(Dataset!$B$13:$N$13,ABS('Normalized Dataset'!$B$13:$N$13-'Normalized Dataset'!$B$8:$N$8)) -> 2.1962328 | F26: =SUMPRODUCT(Dataset!$B$13:$N$13,ABS('Normalized Dataset'!$B$13:$N$13-'Normalized Dataset'!$B$9:$N$9)) -> 2.6901307 | G26: =SUMPRODUCT(Dataset!$B$13:$N$13,ABS('Normalized Dataset'!$B$13:$N$13-'Normalized Dataset'!$B$10:$N$10)) -> 2.4162508 | H26: =SUMPRODUCT(Dataset!$B$13:$N$13,ABS('Normalized Dataset'!$B$13:$N$13-'Normalized Dataset'!$B$11:$N$11)) -> 1.4898268 | I26: =SUMPRODUCT(Dataset!$B$13:$N$13,ABS('Normalized Dataset'!$B$13:$N$13-'Normalized Dataset'!$B$12:$N$12)) -> 1.709193 | J26: =SUMPRODUCT(Dataset!$B$13:$N$13,ABS('Normalized Dataset'!$B$13:$N$13-'Normalized Dataset'!$B$13:$N$13)) -> 0 | K26: =SUMPRODUCT(Dataset!$B$13:$N$13,ABS('Normalized Dataset'!$B$13:$N$13-'Normalized Dataset'!$B$14:$N$14)) -> 2.0275696
A27: S₁₀ | B27: =SUMPRODUCT(Dataset!$B$13:$N$13,ABS('Normalized Dataset'!$B$14:$N$14-'Normalized Dataset'!$B$5:$N$5)) -> 2.2218875 | C27: =SUMPRODUCT(Dataset!$B$13:$N$13,ABS('Normalized Dataset'!$B$14:$N$14-'Normalized Dataset'!$B$6:$N$6)) -> 3.2267936 | D27: =SUMPRODUCT(Dataset!$B$13:$N$13,ABS('Normalized Dataset'!$B$14:$N$14-'Normalized Dataset'!$B$7:$N$7)) -> 3.5342785 | E27: =SUMPRODUCT(Dataset!$B$13:$N$13,ABS('Normalized Dataset'!$B$14:$N$14-'Normalized Dataset'!$B$8:$N$8)) -> 3.3981614 | F27: =SUMPRODUCT(Dataset!$B$13:$N$13,ABS('Normalized Dataset'!$B$14:$N$14-'Normalized Dataset'!$B$9:$N$9)) -> 3.8920592 | G27: =SUMPRODUCT(Dataset!$B$13:$N$13,ABS('Normalized Dataset'!$B$14:$N$14-'Normalized Dataset'!$B$10:$N$10)) -> 3.6181794 | H27: =SUMPRODUCT(Dataset!$B$13:$N$13,ABS('Normalized Dataset'!$B$14:$N$14-'Normalized Dataset'!$B$11:$N$11)) -> 3.0250887 | I27: =SUMPRODUCT(Dataset!$B$13:$N$13,ABS('Normalized Dataset'!$B$14:$N$14-'Normalized Dataset'!$B$12:$N$12)) -> 3.2444549 | J27: =SUMPRODUCT(Dataset!$B$13:$N$13,ABS('Normalized Dataset'!$B$14:$N$14-'Normalized Dataset'!$B$13:$N$13)) -> 2.0275696 | K27: =SUMPRODUCT(Dataset!$B$13:$N$13,ABS('Normalized Dataset'!$B$14:$N$14-'Normalized Dataset'!$B$14:$N$14)) -> 0
A29: Nominal part Σ(j∈J) [xⱼ ≠ yⱼ] (number of nominal features with different codes)
A30: № | B30: S₁ | C30: S₂ | D30: S₃ | E30: S₄ | F30: S₅ | G30: S₆ | H30: S₇ | I30: S₈ | J30: S₉ | K30: S₁₀
A31: S₁ | B31: =SUMPRODUCT((1-Dataset!$B$13:$N$13)*(Dataset!$B$3:$N$3<>Dataset!$B$3:$N$3)) -> 0 | C31: =SUMPRODUCT((1-Dataset!$B$13:$N$13)*(Dataset!$B$3:$N$3<>Dataset!$B$4:$N$4)) -> 3 | D31: =SUMPRODUCT((1-Dataset!$B$13:$N$13)*(Dataset!$B$3:$N$3<>Dataset!$B$5:$N$5)) -> 4 | E31: =SUMPRODUCT((1-Dataset!$B$13:$N$13)*(Dataset!$B$3:$N$3<>Dataset!$B$6:$N$6)) -> 3 | F31: =SUMPRODUCT((1-Dataset!$B$13:$N$13)*(Dataset!$B$3:$N$3<>Dataset!$B$7:$N$7)) -> 4 | G31: =SUMPRODUCT((1-Dataset!$B$13:$N$13)*(Dataset!$B$3:$N$3<>Dataset!$B$8:$N$8)) -> 3 | H31: =SUMPRODUCT((1-Dataset!$B$13:$N$13)*(Dataset!$B$3:$N$3<>Dataset!$B$9:$N$9)) -> 4 | I31: =SUMPRODUCT((1-Dataset!$B$13:$N$13)*(Dataset!$B$3:$N$3<>Dataset!$B$10:$N$10)) -> 2 | J31: =SUMPRODUCT((1-Dataset!$B$13:$N$13)*(Dataset!$B$3:$N$3<>Dataset!$B$11:$N$11)) -> 1 | K31: =SUMPRODUCT((1-Dataset!$B$13:$N$13)*(Dataset!$B$3:$N$3<>Dataset!$B$12:$N$12)) -> 2
A32: S₂ | B32: =SUMPRODUCT((1-Dataset!$B$13:$N$13)*(Dataset!$B$4:$N$4<>Dataset!$B$3:$N$3)) -> 3 | C32: =SUMPRODUCT((1-Dataset!$B$13:$N$13)*(Dataset!$B$4:$N$4<>Dataset!$B$4:$N$4)) -> 0 | D32: =SUMPRODUCT((1-Dataset!$B$13:$N$13)*(Dataset!$B$4:$N$4<>Dataset!$B$5:$N$5)) -> 4 | E32: =SUMPRODUCT((1-Dataset!$B$13:$N$13)*(Dataset!$B$4:$N$4<>Dataset!$B$6:$N$6)) -> 4 | F32: =SUMPRODUCT((1-Dataset!$B$13:$N$13)*(Dataset!$B$4:$N$4<>Dataset!$B$7:$N$7)) -> 4 | G32: =SUMPRODUCT((1-Dataset!$B$13:$N$13)*(Dataset!$B$4:$N$4<>Dataset!$B$8:$N$8)) -> 4 | H32: =SUMPRODUCT((1-Dataset!$B$13:$N$13)*(Dataset!$B$4:$N$4<>Dataset!$B$9:$N$9)) -> 4 | I32: =SUMPRODUCT((1-Dataset!$B$13:$N$13)*(Dataset!$B$4:$N$4<>Dataset!$B$10:$N$10)) -> 3 | J32: =SUMPRODUCT((1-Dataset!$B$13:$N$13)*(Dataset!$B$4:$N$4<>Dataset!$B$11:$N$11)) -> 2 | K32: =SUMPRODUCT((1-Dataset!$B$13:$N$13)*(Dataset!$B$4:$N$4<>Dataset!$B$12:$N$12)) -> 1
A33: S₃ | B33: =SUMPRODUCT((1-Dataset!$B$13:$N$13)*(Dataset!$B$5:$N$5<>Dataset!$B$3:$N$3)) -> 4 | C33: =SUMPRODUCT((1-Dataset!$B$13:$N$13)*(Dataset!$B$5:$N$5<>Dataset!$B$4:$N$4)) -> 4 | D33: =SUMPRODUCT((1-Dataset!$B$13:$N$13)*(Dataset!$B$5:$N$5<>Dataset!$B$5:$N$5)) -> 0 | E33: =SUMPRODUCT((1-Dataset!$B$13:$N$13)*(Dataset!$B$5:$N$5<>Dataset!$B$6:$N$6)) -> 3 | F33: =SUMPRODUCT((1-Dataset!$B$13:$N$13)*(Dataset!$B$5:$N$5<>Dataset!$B$7:$N$7)) -> 4 | G33: =SUMPRODUCT((1-Dataset!$B$13:$N$13)*(Dataset!$B$5:$N$5<>Dataset!$B$8:$N$8)) -> 1 | H33: =SUMPRODUCT((1-Dataset!$B$13:$N$13)*(Dataset!$B$5:$N$5<>Dataset!$B$9:$N$9)) -> 6 | I33: =SUMPRODUCT((1-Dataset!$B$13:$N$13)*(Dataset!$B$5:$N$5<>Dataset!$B$10:$N$10)) -> 4 | J33: =SUMPRODUCT((1-Dataset!$B$13:$N$13)*(Dataset!$B$5:$N$5<>Dataset!$B$11:$N$11)) -> 3 | K33: =SUMPRODUCT((1-Dataset!$B$13:$N$13)*(Dataset!$B$5:$N$5<>Dataset!$B$12:$N$12)) -> 4
A34: S₄ | B34: =SUMPRODUCT((1-Dataset!$B$13:$N$13)*(Dataset!$B$6:$N$6<>Dataset!$B$3:$N$3)) -> 3 | C34: =SUMPRODUCT((1-Dataset!$B$13:$N$13)*(Dataset!$B$6:$N$6<>Dataset!$B$4:$N$4)) -> 4 | D34: =SUMPRODUCT((1-Dataset!$B$13:$N$13)*(Dataset!$B$6:$N$6<>Dataset!$B$5:$N$5)) -> 3 | E34: =SUMPRODUCT((1-Dataset!$B$13:$N$13)*(Dataset!$B$6:$N$6<>Dataset!$B$6:$N$6)) -> 0 | F34: =SUMPRODUCT((1-Dataset!$B$13:$N$13)*(Dataset!$B$6:$N$6<>Dataset!$B$7:$N$7)) -> 5 | G34: =SUMPRODUCT((1-Dataset!$B$13:$N$13)*(Dataset!$B$6:$N$6<>Dataset!$B$8:$N$8)) -> 2 | H34: =SUMPRODUCT((1-Dataset!$B$13:$N$13)*(Dataset!$B$6:$N$6<>Dataset!$B$9:$N$9)) -> 4 | I34: =SUMPRODUCT((1-Dataset!$B$13:$N$13)*(Dataset!$B$6:$N$6<>Dataset!$B$10:$N$10)) -> 1 | J34: =SUMPRODUCT((1-Dataset!$B$13:$N$13)*(Dataset!$B$6:$N$6<>Dataset!$B$11:$N$11)) -> 2 | K34: =SUMPRODUCT((1-Dataset!$B$13:$N$13)*(Dataset!$B$6:$N$6<>Dataset!$B$12:$N$12)) -> 3
A35: S₅ | B35: =SUMPRODUCT((1-Dataset!$B$13:$N$13)*(Dataset!$B$7:$N$7<>Dataset!$B$3:$N$3)) -> 4 | C35: =SUMPRODUCT((1-Dataset!$B$13:$N$13)*(Dataset!$B$7:$N$7<>Dataset!$B$4:$N$4)) -> 4 | D35: =SUMPRODUCT((1-Dataset!$B$13:$N$13)*(Dataset!$B$7:$N$7<>Dataset!$B$5:$N$5)) -> 4 | E35: =SUMPRODUCT((1-Dataset!$B$13:$N$13)*(Dataset!$B$7:$N$7<>Dataset!$B$6:$N$6)) -> 5 | F35: =SUMPRODUCT((1-Dataset!$B$13:$N$13)*(Dataset!$B$7:$N$7<>Dataset!$B$7:$N$7)) -> 0 | G35: =SUMPRODUCT((1-Dataset!$B$13:$N$13)*(Dataset!$B$7:$N$7<>Dataset!$B$8:$N$8)) -> 5 | H35: =SUMPRODUCT((1-Dataset!$B$13:$N$13)*(Dataset!$B$7:$N$7<>Dataset!$B$9:$N$9)) -> 5 | I35: =SUMPRODUCT((1-Dataset!$B$13:$N$13)*(Dataset!$B$7:$N$7<>Dataset!$B$10:$N$10)) -> 4 | J35: =SUMPRODUCT((1-Dataset!$B$13:$N$13)*(Dataset!$B$7:$N$7<>Dataset!$B$11:$N$11)) -> 5 | K35: =SUMPRODUCT((1-Dataset!$B$13:$N$13)*(Dataset!$B$7:$N$7<>Dataset!$B$12:$N$12)) -> 4
A36: S₆ | B36: =SUMPRODUCT((1-Dataset!$B$13:$N$13)*(Dataset!$B$8:$N$8<>Dataset!$B$3:$N$3)) -> 3 | C36: =SUMPRODUCT((1-Dataset!$B$13:$N$13)*(Dataset!$B$8:$N$8<>Dataset!$B$4:$N$4)) -> 4 | D36: =SUMPRODUCT((1-Dataset!$B$13:$N$13)*(Dataset!$B$8:$N$8<>Dataset!$B$5:$N$5)) -> 1 | E36: =SUMPRODUCT((1-Dataset!$B$13:$N$13)*(Dataset!$B$8:$N$8<>Dataset!$B$6:$N$6)) -> 2 | F36: =SUMPRODUCT((1-Dataset!$B$13:$N$13)*(Dataset!$B$8:$N$8<>Dataset!$B$7:$N$7)) -> 5 | G36: =SUMPRODUCT((1-Dataset!$B$13:$N$13)*(Dataset!$B$8:$N$8<>Dataset!$B$8:$N$8)) -> 0 | H36: =SUMPRODUCT((1-Dataset!$B$13:$N$13)*(Dataset!$B$8:$N$8<>Dataset!$B$9:$N$9)) -> 6 | I36: =SUMPRODUCT((1-Dataset!$B$13:$N$13)*(Dataset!$B$8:$N$8<>Dataset!$B$10:$N$10)) -> 3 | J36: =SUMPRODUCT((1-Dataset!$B$13:$N$13)*(Dataset!$B$8:$N$8<>Dataset!$B$11:$N$11)) -> 2 | K36: =SUMPRODUCT((1-Dataset!$B$13:$N$13)*(Dataset!$B$8:$N$8<>Dataset!$B$12:$N$12)) -> 3
A37: S₇ | B37: =SUMPRODUCT((1-Dataset!$B$13:$N$13)*(Dataset!$B$9:$N$9<>Dataset!$B$3:$N$3)) -> 4 | C37: =SUMPRODUCT((1-Dataset!$B$13:$N$13)*(Dataset!$B$9:$N$9<>Dataset!$B$4:$N$4)) -> 4 | D37: =SUMPRODUCT((1-Dataset!$B$13:$N$13)*(Dataset!$B$9:$N$9<>Dataset!$B$5:$N$5)) -> 6 | E37: =SUMPRODUCT((1-Dataset!$B$13:$N$13)*(Dataset!$B$9:$N$9<>Dataset!$B$6:$N$6)) -> 4 | F37: =SUMPRODUCT((1-Dataset!$B$13:$N$13)*(Dataset!$B$9:$N$9<>Dataset!$B$7:$N$7)) -> 5 | G37: =SUMPRODUCT((1-Dataset!$B$13:$N$13)*(Dataset!$B$9:$N$9<>Dataset!$B$8:$N$8)) -> 6 | H37: =SUMPRODUCT((1-Dataset!$B$13:$N$13)*(Dataset!$B$9:$N$9<>Dataset!$B$9:$N$9)) -> 0 | I37: =SUMPRODUCT((1-Dataset!$B$13:$N$13)*(Dataset!$B$9:$N$9<>Dataset!$B$10:$N$10)) -> 3 | J37: =SUMPRODUCT((1-Dataset!$B$13:$N$13)*(Dataset!$B$9:$N$9<>Dataset!$B$11:$N$11)) -> 4 | K37: =SUMPRODUCT((1-Dataset!$B$13:$N$13)*(Dataset!$B$9:$N$9<>Dataset!$B$12:$N$12)) -> 5
A38: S₈ | B38: =SUMPRODUCT((1-Dataset!$B$13:$N$13)*(Dataset!$B$10:$N$10<>Dataset!$B$3:$N$3)) -> 2 | C38: =SUMPRODUCT((1-Dataset!$B$13:$N$13)*(Dataset!$B$10:$N$10<>Dataset!$B$4:$N$4)) -> 3 | D38: =SUMPRODUCT((1-Dataset!$B$13:$N$13)*(Dataset!$B$10:$N$10<>Dataset!$B$5:$N$5)) -> 4 | E38: =SUMPRODUCT((1-Dataset!$B$13:$N$13)*(Dataset!$B$10:$N$10<>Dataset!$B$6:$N$6)) -> 1 | F38: =SUMPRODUCT((1-Dataset!$B$13:$N$13)*(Dataset!$B$10:$N$10<>Dataset!$B$7:$N$7)) -> 4 | G38: =SUMPRODUCT((1-Dataset!$B$13:$N$13)*(Dataset!$B$10:$N$10<>Dataset!$B$8:$N$8)) -> 3 | H38: =SUMPRODUCT((1-Dataset!$B$13:$N$13)*(Dataset!$B$10:$N$10<>Dataset!$B$9:$N$9)) -> 3 | I38: =SUMPRODUCT((1-Dataset!$B$13:$N$13)*(Dataset!$B$10:$N$10<>Dataset!$B$10:$N$10)) -> 0 | J38: =SUMPRODUCT((1-Dataset!$B$13:$N$13)*(Dataset!$B$10:$N$10<>Dataset!$B$11:$N$11)) -> 1 | K38: =SUMPRODUCT((1-Dataset!$B$13:$N$13)*(Dataset!$B$10:$N$10<>Dataset!$B$12:$N$12)) -> 2
A39: S₉ | B39: =SUMPRODUCT((1-Dataset!$B$13:$N$13)*(Dataset!$B$11:$N$11<>Dataset!$B$3:$N$3)) -> 1 | C39: =SUMPRODUCT((1-Dataset!$B$13:$N$13)*(Dataset!$B$11:$N$11<>Dataset!$B$4:$N$4)) -> 2 | D39: =SUMPRODUCT((1-Dataset!$B$13:$N$13)*(Dataset!$B$11:$N$11<>Dataset!$B$5:$N$5)) -> 3 | E39: =SUMPRODUCT((1-Dataset!$B$13:$N$13)*(Dataset!$B$11:$N$11<>Dataset!$B$6:$N$6)) -> 2 | F39: =SUMPRODUCT((1-Dataset!$B$13:$N$13)*(Dataset!$B$11:$N$11<>Dataset!$B$7:$N$7)) -> 5 | G39: =SUMPRODUCT((1-Dataset!$B$13:$N$13)*(Dataset!$B$11:$N$11<>Dataset!$B$8:$N$8)) -> 2 | H39: =SUMPRODUCT((1-Dataset!$B$13:$N$13)*(Dataset!$B$11:$N$11<>Dataset!$B$9:$N$9)) -> 4 | I39: =SUMPRODUCT((1-Dataset!$B$13:$N$13)*(Dataset!$B$11:$N$11<>Dataset!$B$10:$N$10)) -> 1 | J39: =SUMPRODUCT((1-Dataset!$B$13:$N$13)*(Dataset!$B$11:$N$11<>Dataset!$B$11:$N$11)) -> 0 | K39: =SUMPRODUCT((1-Dataset!$B$13:$N$13)*(Dataset!$B$11:$N$11<>Dataset!$B$12:$N$12)) -> 1
A40: S₁₀ | B40: =SUMPRODUCT((1-Dataset!$B$13:$N$13)*(Dataset!$B$12:$N$12<>Dataset!$B$3:$N$3)) -> 2 | C40: =SUMPRODUCT((1-Dataset!$B$13:$N$13)*(Dataset!$B$12:$N$12<>Dataset!$B$4:$N$4)) -> 1 | D40: =SUMPRODUCT((1-Dataset!$B$13:$N$13)*(Dataset!$B$12:$N$12<>Dataset!$B$5:$N$5)) -> 4 | E40: =SUMPRODUCT((1-Dataset!$B$13:$N$13)*(Dataset!$B$12:$N$12<>Dataset!$B$6:$N$6)) -> 3 | F40: =SUMPRODUCT((1-Dataset!$B$13:$N$13)*(Dataset!$B$12:$N$12<>Dataset!$B$7:$N$7)) -> 4 | G40: =SUMPRODUCT((1-Dataset!$B$13:$N$13)*(Dataset!$B$12:$N$12<>Dataset!$B$8:$N$8)) -> 3 | H40: =SUMPRODUCT((1-Dataset!$B$13:$N$13)*(Dataset!$B$12:$N$12<>Dataset!$B$9:$N$9)) -> 5 | I40: =SUMPRODUCT((1-Dataset!$B$13:$N$13)*(Dataset!$B$12:$N$12<>Dataset!$B$10:$N$10)) -> 2 | J40: =SUMPRODUCT((1-Dataset!$B$13:$N$13)*(Dataset!$B$12:$N$12<>Dataset!$B$11:$N$11)) -> 1 | K40: =SUMPRODUCT((1-Dataset!$B$13:$N$13)*(Dataset!$B$12:$N$12<>Dataset!$B$12:$N$12)) -> 0
A42: Each row lists the distances from the target object Sᵢ to S₁ … S₁₀ in their original order (image 1: S₁ → S₂, S₃, …, S₁₀).
A43: ρ = quantitative part + nominal part, rounded to 10 decimals so that mathematically equal distances tie exactly. Diagonal ρ(Sᵢ, Sᵢ) = 0 is shown in grey and never used as a neighbour.
A44: Number format shows 4 decimals; full precision is stored in the cells.

Sheet Sorted Neighbors
A1: Step 3 · Neighbours of every object sorted by ascending ρ — original index and class kept
A3: Rank of Sⱼ in the neighbour list of Sᵢ (self excluded; equal distances → smaller original index first)
A4: Sᵢ \ Sⱼ | B4: S₁ | C4: S₂ | D4: S₃ | E4: S₄ | F4: S₅ | G4: S₆ | H4: S₇ | I4: S₈ | J4: S₉ | K4: S₁₀
A5: S₁ | B5: — | C5: =1+SUMPRODUCT(('Zhuravlev Distances'!$B$5:$K$5<'Zhuravlev Distances'!C$5)*(COLUMN('Zhuravlev Distances'!$B$5:$K$5)<>COLUMN('Zhuravlev Distances'!B$5)))+SUMPRODUCT(('Zhuravlev Distances'!$B$5:$K$5='Zhuravlev Distances'!C$5)*(COLUMN('Zhuravlev Distances'!$B$5:$K$5)<COLUMN('Zhuravlev Distances'!C$5))*(COLUMN('Zhuravlev Distances'!$B$5:$K$5)<>COLUMN('Zhuravlev Distances'!B$5))) -> 7 | D5: =1+SUMPRODUCT(('Zhuravlev Distances'!$B$5:$K$5<'Zhuravlev Distances'!D$5)*(COLUMN('Zhuravlev Distances'!$B$5:$K$5)<>COLUMN('Zhuravlev Distances'!B$5)))+SUMPRODUCT(('Zhuravlev Distances'!$B$5:$K$5='Zhuravlev Distances'!D$5)*(COLUMN('Zhuravlev Distances'!$B$5:$K$5)<COLUMN('Zhuravlev Distances'!D$5))*(COLUMN('Zhuravlev Distances'!$B$5:$K$5)<>COLUMN('Zhuravlev Distances'!B$5))) -> 9 | E5: =1+SUMPRODUCT(('Zhuravlev Distances'!$B$5:$K$5<'Zhuravlev Distances'!E$5)*(COLUMN('Zhuravlev Distances'!$B$5:$K$5)<>COLUMN('Zhuravlev Distances'!B$5)))+SUMPRODUCT(('Zhuravlev Distances'!$B$5:$K$5='Zhuravlev Distances'!E$5)*(COLUMN('Zhuravlev Distances'!$B$5:$K$5)<COLUMN('Zhuravlev Distances'!E$5))*(COLUMN('Zhuravlev Distances'!$B$5:$K$5)<>COLUMN('Zhuravlev Distances'!B$5))) -> 4 | F5: =1+SUMPRODUCT(('Zhuravlev Distances'!$B$5:$K$5<'Zhuravlev Distances'!F$5)*(COLUMN('Zhuravlev Distances'!$B$5:$K$5)<>COLUMN('Zhuravlev Distances'!B$5)))+SUMPRODUCT(('Zhuravlev Distances'!$B$5:$K$5='Zhuravlev Distances'!F$5)*(COLUMN('Zhuravlev Distances'!$B$5:$K$5)<COLUMN('Zhuravlev Distances'!F$5))*(COLUMN('Zhuravlev Distances'!$B$5:$K$5)<>COLUMN('Zhuravlev Distances'!B$5))) -> 6 | G5: =1+SUMPRODUCT(('Zhuravlev Distances'!$B$5:$K$5<'Zhuravlev Distances'!G$5)*(COLUMN('Zhuravlev Distances'!$B$5:$K$5)<>COLUMN('Zhuravlev Distances'!B$5)))+SUMPRODUCT(('Zhuravlev Distances'!$B$5:$K$5='Zhuravlev Distances'!G$5)*(COLUMN('Zhuravlev Distances'!$B$5:$K$5)<COLUMN('Zhuravlev Distances'!G$5))*(COLUMN('Zhuravlev Distances'!$B$5:$K$5)<>COLUMN('Zhuravlev Distances'!B$5))) -> 5 | H5: =1+SUMPRODUCT(('Zhuravlev Distances'!$B$5:$K$5<'Zhuravlev Distances'!H$5)*(COLUMN('Zhuravlev Distances'!$B$5:$K$5)<>COLUMN('Zhuravlev Distances'!B$5)))+SUMPRODUCT(('Zhuravlev Distances'!$B$5:$K$5='Zhuravlev Distances'!H$5)*(COLUMN('Zhuravlev Distances'!$B$5:$K$5)<COLUMN('Zhuravlev Distances'!H$5))*(COLUMN('Zhuravlev Distances'!$B$5:$K$5)<>COLUMN('Zhuravlev Distances'!B$5))) -> 8 | I5: =1+SUMPRODUCT(('Zhuravlev Distances'!$B$5:$K$5<'Zhuravlev Distances'!I$5)*(COLUMN('Zhuravlev Distances'!$B$5:$K$5)<>COLUMN('Zhuravlev Distances'!B$5)))+SUMPRODUCT(('Zhuravlev Distances'!$B$5:$K$5='Zhuravlev Distances'!I$5)*(COLUMN('Zhuravlev Distances'!$B$5:$K$5)<COLUMN('Zhuravlev Distances'!I$5))*(COLUMN('Zhuravlev Distances'!$B$5:$K$5)<>COLUMN('Zhuravlev Distances'!B$5))) -> 3 | J5: =1+SUMPRODUCT(('Zhuravlev Distances'!$B$5:$K$5<'Zhuravlev Distances'!J$5)*(COLUMN('Zhuravlev Distances'!$B$5:$K$5)<>COLUMN('Zhuravlev Distances'!B$5)))+SUMPRODUCT(('Zhuravlev Distances'!$B$5:$K$5='Zhuravlev Distances'!J$5)*(COLUMN('Zhuravlev Distances'!$B$5:$K$5)<COLUMN('Zhuravlev Distances'!J$5))*(COLUMN('Zhuravlev Distances'!$B$5:$K$5)<>COLUMN('Zhuravlev Distances'!B$5))) -> 1 | K5: =1+SUMPRODUCT(('Zhuravlev Distances'!$B$5:$K$5<'Zhuravlev Distances'!K$5)*(COLUMN('Zhuravlev Distances'!$B$5:$K$5)<>COLUMN('Zhuravlev Distances'!B$5)))+SUMPRODUCT(('Zhuravlev Distances'!$B$5:$K$5='Zhuravlev Distances'!K$5)*(COLUMN('Zhuravlev Distances'!$B$5:$K$5)<COLUMN('Zhuravlev Distances'!K$5))*(COLUMN('Zhuravlev Distances'!$B$5:$K$5)<>COLUMN('Zhuravlev Distances'!B$5))) -> 2
A6: S₂ | B6: =1+SUMPRODUCT(('Zhuravlev Distances'!$B$6:$K$6<'Zhuravlev Distances'!B$6)*(COLUMN('Zhuravlev Distances'!$B$6:$K$6)<>COLUMN('Zhuravlev Distances'!C$6)))+SUMPRODUCT(('Zhuravlev Distances'!$B$6:$K$6='Zhuravlev Distances'!B$6)*(COLUMN('Zhuravlev Distances'!$B$6:$K$6)<COLUMN('Zhuravlev Distances'!B$6))*(COLUMN('Zhuravlev Distances'!$B$6:$K$6)<>COLUMN('Zhuravlev Distances'!C$6))) -> 5 | C6: — | D6: =1+SUMPRODUCT(('Zhuravlev Distances'!$B$6:$K$6<'Zhuravlev Distances'!D$6)*(COLUMN('Zhuravlev Distances'!$B$6:$K$6)<>COLUMN('Zhuravlev Distances'!C$6)))+SUMPRODUCT(('Zhuravlev Distances'!$B$6:$K$6='Zhuravlev Distances'!D$6)*(COLUMN('Zhuravlev Distances'!$B$6:$K$6)<COLUMN('Zhuravlev Distances'!D$6))*(COLUMN('Zhuravlev Distances'!$B$6:$K$6)<>COLUMN('Zhuravlev Distances'!C$6))) -> 6 | E6: =1+SUMPRODUCT(('Zhuravlev Distances'!$B$6:$K$6<'Zhuravlev Distances'!E$6)*(COLUMN('Zhuravlev Distances'!$B$6:$K$6)<>COLUMN('Zhuravlev Distances'!C$6)))+SUMPRODUCT(('Zhuravlev Distances'!$B$6:$K$6='Zhuravlev Distances'!E$6)*(COLUMN('Zhuravlev Distances'!$B$6:$K$6)<COLUMN('Zhuravlev Distances'!E$6))*(COLUMN('Zhuravlev Distances'!$B$6:$K$6)<>COLUMN('Zhuravlev Distances'!C$6))) -> 9 | F6: =1+SUMPRODUCT(('Zhuravlev Distances'!$B$6:$K$6<'Zhuravlev Distances'!F$6)*(COLUMN('Zhuravlev Distances'!$B$6:$K$6)<>COLUMN('Zhuravlev Distances'!C$6)))+SUMPRODUCT(('Zhuravlev Distances'!$B$6:$K$6='Zhuravlev Distances'!F$6)*(COLUMN('Zhuravlev Distances'!$B$6:$K$6)<COLUMN('Zhuravlev Distances'!F$6))*(COLUMN('Zhuravlev Distances'!$B$6:$K$6)<>COLUMN('Zhuravlev Distances'!C$6))) -> 7 | G6: =1+SUMPRODUCT(('Zhuravlev Distances'!$B$6:$K$6<'Zhuravlev Distances'!G$6)*(COLUMN('Zhuravlev Distances'!$B$6:$K$6)<>COLUMN('Zhuravlev Distances'!C$6)))+SUMPRODUCT(('Zhuravlev Distances'!$B$6:$K$6='Zhuravlev Distances'!G$6)*(COLUMN('Zhuravlev Distances'!$B$6:$K$6)<COLUMN('Zhuravlev Distances'!G$6))*(COLUMN('Zhuravlev Distances'!$B$6:$K$6)<>COLUMN('Zhuravlev Distances'!C$6))) -> 4 | H6: =1+SUMPRODUCT(('Zhuravlev Distances'!$B$6:$K$6<'Zhuravlev Distances'!H$6)*(COLUMN('Zhuravlev Distances'!$B$6:$K$6)<>COLUMN('Zhuravlev Distances'!C$6)))+SUMPRODUCT(('Zhuravlev Distances'!$B$6:$K$6='Zhuravlev Distances'!H$6)*(COLUMN('Zhuravlev Distances'!$B$6:$K$6)<COLUMN('Zhuravlev Distances'!H$6))*(COLUMN('Zhuravlev Distances'!$B$6:$K$6)<>COLUMN('Zhuravlev Distances'!C$6))) -> 8 | I6: =1+SUMPRODUCT(('Zhuravlev Distances'!$B$6:$K$6<'Zhuravlev Distances'!I$6)*(COLUMN('Zhuravlev Distances'!$B$6:$K$6)<>COLUMN('Zhuravlev Distances'!C$6)))+SUMPRODUCT(('Zhuravlev Distances'!$B$6:$K$6='Zhuravlev Distances'!I$6)*(COLUMN('Zhuravlev Distances'!$B$6:$K$6)<COLUMN('Zhuravlev Distances'!I$6))*(COLUMN('Zhuravlev Distances'!$B$6:$K$6)<>COLUMN('Zhuravlev Distances'!C$6))) -> 3 | J6: =1+SUMPRODUCT(('Zhuravlev Distances'!$B$6:$K$6<'Zhuravlev Distances'!J$6)*(COLUMN('Zhuravlev Distances'!$B$6:$K$6)<>COLUMN('Zhuravlev Distances'!C$6)))+SUMPRODUCT(('Zhuravlev Distances'!$B$6:$K$6='Zhuravlev Distances'!J$6)*(COLUMN('Zhuravlev Distances'!$B$6:$K$6)<COLUMN('Zhuravlev Distances'!J$6))*(COLUMN('Zhuravlev Distances'!$B$6:$K$6)<>COLUMN('Zhuravlev Distances'!C$6))) -> 2 | K6: =1+SUMPRODUCT(('Zhuravlev Distances'!$B$6:$K$6<'Zhuravlev Distances'!K$6)*(COLUMN('Zhuravlev Distances'!$B$6:$K$6)<>COLUMN('Zhuravlev Distances'!C$6)))+SUMPRODUCT(('Zhuravlev Distances'!$B$6:$K$6='Zhuravlev Distances'!K$6)*(COLUMN('Zhuravlev Distances'!$B$6:$K$6)<COLUMN('Zhuravlev Distances'!K$6))*(COLUMN('Zhuravlev Distances'!$B$6:$K$6)<>COLUMN('Zhuravlev Distances'!C$6))) -> 1
A7: S₃ | B7: =1+SUMPRODUCT(('Zhuravlev Distances'!$B$7:$K$7<'Zhuravlev Distances'!B$7)*(COLUMN('Zhuravlev Distances'!$B$7:$K$7)<>COLUMN('Zhuravlev Distances'!D$7)))+SUMPRODUCT(('Zhuravlev Distances'!$B$7:$K$7='Zhuravlev Distances'!B$7)*(COLUMN('Zhuravlev Distances'!$B$7:$K$7)<COLUMN('Zhuravlev Distances'!B$7))*(COLUMN('Zhuravlev Distances'!$B$7:$K$7)<>COLUMN('Zhuravlev Distances'!D$7))) -> 8 | C7: =1+SUMPRODUCT(('Zhuravlev Distances'!$B$7:$K$7<'Zhuravlev Distances'!C$7)*(COLUMN('Zhuravlev Distances'!$B$7:$K$7)<>COLUMN('Zhuravlev Distances'!D$7)))+SUMPRODUCT(('Zhuravlev Distances'!$B$7:$K$7='Zhuravlev Distances'!C$7)*(COLUMN('Zhuravlev Distances'!$B$7:$K$7)<COLUMN('Zhuravlev Distances'!C$7))*(COLUMN('Zhuravlev Distances'!$B$7:$K$7)<>COLUMN('Zhuravlev Distances'!D$7))) -> 6 | D7: — | E7: =1+SUMPRODUCT(('Zhuravlev Distances'!$B$7:$K$7<'Zhuravlev Distances'!E$7)*(COLUMN('Zhuravlev Distances'!$B$7:$K$7)<>COLUMN('Zhuravlev Distances'!D$7)))+SUMPRODUCT(('Zhuravlev Distances'!$B$7:$K$7='Zhuravlev Distances'!E$7)*(COLUMN('Zhuravlev Distances'!$B$7:$K$7)<COLUMN('Zhuravlev Distances'!E$7))*(COLUMN('Zhuravlev Distances'!$B$7:$K$7)<>COLUMN('Zhuravlev Distances'!D$7))) -> 2 | F7: =1+SUMPRODUCT(('Zhuravlev Distances'!$B$7:$K$7<'Zhuravlev Distances'!F$7)*(COLUMN('Zhuravlev Distances'!$B$7:$K$7)<>COLUMN('Zhuravlev Distances'!D$7)))+SUMPRODUCT(('Zhuravlev Distances'!$B$7:$K$7='Zhuravlev Distances'!F$7)*(COLUMN('Zhuravlev Distances'!$B$7:$K$7)<COLUMN('Zhuravlev Distances'!F$7))*(COLUMN('Zhuravlev Distances'!$B$7:$K$7)<>COLUMN('Zhuravlev Distances'!D$7))) -> 5 | G7: =1+SUMPRODUCT(('Zhuravlev Distances'!$B$7:$K$7<'Zhuravlev Distances'!G$7)*(COLUMN('Zhuravlev Distances'!$B$7:$K$7)<>COLUMN('Zhuravlev Distances'!D$7)))+SUMPRODUCT(('Zhuravlev Distances'!$B$7:$K$7='Zhuravlev Distances'!G$7)*(COLUMN('Zhuravlev Distances'!$B$7:$K$7)<COLUMN('Zhuravlev Distances'!G$7))*(COLUMN('Zhuravlev Distances'!$B$7:$K$7)<>COLUMN('Zhuravlev Distances'!D$7))) -> 1 | H7: =1+SUMPRODUCT(('Zhuravlev Distances'!$B$7:$K$7<'Zhuravlev Distances'!H$7)*(COLUMN('Zhuravlev Distances'!$B$7:$K$7)<>COLUMN('Zhuravlev Distances'!D$7)))+SUMPRODUCT(('Zhuravlev Distances'!$B$7:$K$7='Zhuravlev Distances'!H$7)*(COLUMN('Zhuravlev Distances'!$B$7:$K$7)<COLUMN('Zhuravlev Distances'!H$7))*(COLUMN('Zhuravlev Distances'!$B$7:$K$7)<>COLUMN('Zhuravlev Distances'!D$7))) -> 7 | I7: =1+SUMPRODUCT(('Zhuravlev Distances'!$B$7:$K$7<'Zhuravlev Distances'!I$7)*(COLUMN('Zhuravlev Distances'!$B$7:$K$7)<>COLUMN('Zhuravlev Distances'!D$7)))+SUMPRODUCT(('Zhuravlev Distances'!$B$7:$K$7='Zhuravlev Distances'!I$7)*(COLUMN('Zhuravlev Distances'!$B$7:$K$7)<COLUMN('Zhuravlev Distances'!I$7))*(COLUMN('Zhuravlev Distances'!$B$7:$K$7)<>COLUMN('Zhuravlev Distances'!D$7))) -> 4 | J7: =1+SUMPRODUCT(('Zhuravlev Distances'!$B$7:$K$7<'Zhuravlev Distances'!J$7)*(COLUMN('Zhuravlev Distances'!$B$7:$K$7)<>COLUMN('Zhuravlev Distances'!D$7)))+SUMPRODUCT(('Zhuravlev Distances'!$B$7:$K$7='Zhuravlev Distances'!J$7)*(COLUMN('Zhuravlev Distances'!$B$7:$K$7)<COLUMN('Zhuravlev Distances'!J$7))*(COLUMN('Zhuravlev Distances'!$B$7:$K$7)<>COLUMN('Zhuravlev Distances'!D$7))) -> 3 | K7: =1+SUMPRODUCT(('Zhuravlev Distances'!$B$7:$K$7<'Zhuravlev Distances'!K$7)*(COLUMN('Zhuravlev Distances'!$B$7:$K$7)<>COLUMN('Zhuravlev Distances'!D$7)))+SUMPRODUCT(('Zhuravlev Distances'!$B$7:$K$7='Zhuravlev Distances'!K$7)*(COLUMN('Zhuravlev Distances'!$B$7:$K$7)<COLUMN('Zhuravlev Distances'!K$7))*(COLUMN('Zhuravlev Distances'!$B$7:$K$7)<>COLUMN('Zhuravlev Distances'!D$7))) -> 9
