Workbook

Sheet Overview
B2: Meta-algorithm
B3: Classification of a new object on the Heart-Disease dataset · 10 objects · 13 features · 2 classes
B5: Workbook map
B6: # | C6: Sheet | D6: Stage | E6: What it contains
B7: 1 | C7: Dataset | D7: 1 · Input data | E7: Original sample: 10 objects (S₁–S₁₀) × 13 features (x₁–x₁₃) with class labels (K1 = 4, K2 = 6); feature-type flags (1 = quantitative, 0 = nominal) and the split into 6 quantitative and 7 nominal features.
B8: 2 | C8: Quantitative | D8: 2 · Feature analysis | E8: Quantitative features: Criterion 1 boundary values and weights, per-feature class-sorted tables, conversion to a nominal scale, gradations, weights and contributions of gradations, and the features expressed as contribution values.
B9: 3 | C9: Nominal | D9: 2 · Feature analysis | E9: Nominal features: class-sorted table, gradations with a helper list, gradation parameters, λ, β and weight ω of each feature, contributions of gradations, and the features expressed as contribution values.
B10: 4 | C10: Dataset (Contribution & Weight) | D10: 3 · Weighted dataset | E10: All 13 features expressed as contribution values, with the weight of every feature and its rank (1 = highest weight).
B11: 5 | C11: Brace for Meta-algorithm | D11: 4 · Preparation | E11: Meta-dataset of 5 initial features y₀–y₄ (from x₃, x₆, x₁₃, x₄, x₉) and 4 latent features r₁–r₄; encoding of the new object (Criterion 1 on x₄, the only quantitative feature in the SET); training dataset — full, sorted by class, and split into its original and latent (additional) parts.
B12: 6 | C12: Meta-algorithm | D12: 5 · Classification | E12: Meta-algorithm applied to the new object: Step 1 organiser of GA, repeated Steps 2–3 (original-feature and latent-sign conditions, STEP 3 check), Step 4 class computation and Step 5 end.
B14: Key figures
B15: # | C15: Figure | D15: Value | E15: Linked to
B16: 1 | C16: Objects (samples) | D16: =COUNT(Dataset!O3:O12) -> 10 | E16: Dataset · O3:O12
B17: 2 | C17: Features in the original dataset | D17: =COUNT(Dataset!B3:N3) -> 13 | E17: Dataset · B3:N3
B18: 3 | C18: Classes | D18: =SUMPRODUCT(1/COUNTIF(Dataset!O3:O12,Dataset!O3:O12)) -> 2 | E18: Dataset · O3:O12
B19: 4 | C19: Objects in class 1 (K1) | D19: =COUNTIF(Dataset!O3:O12,1) -> 4 | E19: Dataset · O3:O12
B20: 5 | C20: Objects in class 2 (K2) | D20: =COUNTIF(Dataset!O3:O12,2) -> 6 | E20: Dataset · O3:O12
B21: 6 | C21: Quantitative features | D21: =Dataset!F17 -> 6 | E21: Dataset · F17
B22: 7 | C22: Nominal features | D22: =Dataset!P17 -> 7 | E22: Dataset · P17
B23: 8 | C23: Initial features in the meta-dataset | D23: ='Brace for Meta-algorithm'!E14 -> 5 | E23: Brace for Meta-algorithm · E14
B24: 9 | C24: Latent (additional) features | D24: ='Brace for Meta-algorithm'!M14 -> 4 | E24: Brace for Meta-algorithm · M14
B25: 10 | C25: Features in the meta-dataset | D25: =D23+D24 -> 9 | E25: D23 + D24 (initial + latent)
B26: 11 | C26: Class assigned to the new object | D26: ='Meta-algorithm'!C223 -> Class 2 | E26: Meta-algorithm · C223 (Step 4)
B28: Colour legend
B29: Aa | C29: Sheet title / main table title
B30: Aa | C30: Section title, Step / STEP box
B31: Aa | C31: Column header (feature symbols x, y, r, a, d …)
B32: Aa | C32: Object label S₁…S₁₀ and row captions
B33: Aa | C33: Quantitative feature values
B34: Aa | C34: Nominal feature values / new-object values
B35: Aa | C35: Class label (1 / 2)
B36: Aa | C36: Selected feature / highlighted result
B37: Aa | C37: Initial (original) features in the meta-dataset
B38: Aa | C38: Additional (latent) features in the meta-dataset
B39: Aa | C39: Final result — class assigned to the new object
B40: Aa | C40: Key label (counts, sign / colour keys)
B42: Notes
B43: • Symbols such as x₁, S₁, ω_c, η_c, a_i and d_i in the sheets are Office-Math equation objects placed over the cells; they display fully in Excel for Windows / Mac.
B44: • All numbers, formulas and results are identical to the original workbook; only formatting, colours, print setup and this Overview sheet were added. Numbers keep the original General display.
B45: • Every sheet is set up to print landscape on A4, one page wide, with the workbook name, sheet name and page numbers in the header / footer.

Sheet Dataset
A1: Heart + Disease (10, 13, 2)
A2: № | O2: Class | Q2: K1 = 4
B3: 70 | C3: 1 | D3: 4 | E3: 130 | F3: 322 | G3: 0 | H3: 2 | I3: 109 | J3: 0 | K3: 2.4 | L3: 2 | M3: 3 | N3: 3 | O3: 2 | Q3: K2 = 6
B4: 67 | C4: 0 | D4: 3 | E4: 115 | F4: 564 | G4: 0 | H4: 2 | I4: 160 | J4: 0 | K4: 1.6 | L4: 2 | M4: 0 | N4: 7 | O4: 1
B5: 57 | C5: 1 | D5: 2 | E5: 124 | F5: 261 | G5: 0 | H5: 0 | I5: 141 | J5: 0 | K5: 0.3 | L5: 1 | M5: 0 | N5: 7 | O5: 2 | Q5: Sign of Quantitative Features - | T5: 1
B6: 64 | C6: 1 | D6: 4 | E6: 128 | F6: 263 | G6: 0 | H6: 0 | I6: 105 | J6: 1 | K6: 0.2 | L6: 2 | M6: 1 | N6: 7 | O6: 1 | Q6: Sign of Nominal Features - | T6: 0
B7: 74 | C7: 0 | D7: 2 | E7: 120 | F7: 269 | G7: 0 | H7: 2 | I7: 121 | J7: 1 | K7: 0.2 | L7: 1 | M7: 1 | N7: 3 | O7: 1
B8: 65 | C8: 1 | D8: 4 | E8: 120 | F8: 177 | G8: 0 | H8: 0 | I8: 140 | J8: 0 | K8: 0.4 | L8: 1 | M8: 0 | N8: 7 | O8: 1
B9: 56 | C9: 1 | D9: 3 | E9: 130 | F9: 256 | G9: 1 | H9: 2 | I9: 142 | J9: 1 | K9: 0.6 | L9: 2 | M9: 1 | N9: 6 | O9: 2
B10: 59 | C10: 1 | D10: 4 | E10: 110 | F10: 239 | G10: 0 | H10: 2 | I10: 142 | J10: 1 | K10: 1.2 | L10: 2 | M10: 1 | N10: 7 | O10: 2
B11: 60 | C11: 1 | D11: 4 | E11: 140 | F11: 293 | G11: 0 | H11: 2 | I11: 170 | J11: 0 | K11: 1.2 | L11: 2 | M11: 2 | N11: 7 | O11: 2
B12: 63 | C12: 0 | D12: 4 | E12: 150 | F12: 407 | G12: 0 | H12: 2 | I12: 154 | J12: 0 | K12: 4 | L12: 2 | M12: 3 | N12: 7 | O12: 2
B13: 1 | C13: 0 | D13: 0 | E13: 1 | F13: 1 | G13: 0 | H13: 0 | I13: 1 | J13: 0 | K13: 1 | L13: 0 | M13: 1 | N13: 0
B17: Total Number of Quantitative Features - | F17: 6 | L17: Total Number of Nominal Features - | P17: 7
A19: Quantitative Features | K19: Nominal Features
A20: № | H20: Class | K20: № | S20: Class
B21: 70 | C21: 130 | D21: 322 | E21: 109 | F21: 2.4 | G21: 3 | H21: 2 | L21: 1 | M21: 4 | N21: 0 | O21: 2 | P21: 0 | Q21: 2 | R21: 3 | S21: 2
B22: 67 | C22: 115 | D22: 564 | E22: 160 | F22: 1.6 | G22: 0 | H22: 1 | L22: 0 | M22: 3 | N22: 0 | O22: 2 | P22: 0 | Q22: 2 | R22: 7 | S22: 1
B23: 57 | C23: 124 | D23: 261 | E23: 141 | F23: 0.3 | G23: 0 | H23: 2 | L23: 1 | M23: 2 | N23: 0 | O23: 0 | P23: 0 | Q23: 1 | R23: 7 | S23: 2
B24: 64 | C24: 128 | D24: 263 | E24: 105 | F24: 0.2 | G24: 1 | H24: 1 | L24: 1 | M24: 4 | N24: 0 | O24: 0 | P24: 1 | Q24: 2 | R24: 7 | S24: 1
B25: 74 | C25: 120 | D25: 269 | E25: 121 | F25: 0.2 | G25: 1 | H25: 1 | L25: 0 | M25: 2 | N25: 0 | O25: 2 | P25: 1 | Q25: 1 | R25: 3 | S25: 1
B26: 65 | C26: 120 | D26: 177 | E26: 140 | F26: 0.4 | G26: 0 | H26: 1 | L26: 1 | M26: 4 | N26: 0 | O26: 0 | P26: 0 | Q26: 1 | R26: 7 | S26: 1
B27: 56 | C27: 130 | D27: 256 | E27: 142 | F27: 0.6 | G27: 1 | H27: 2 | L27: 1 | M27: 3 | N27: 1 | O27: 2 | P27: 1 | Q27: 2 | R27: 6 | S27: 2
B28: 59 | C28: 110 | D28: 239 | E28: 142 | F28: 1.2 | G28: 1 | H28: 2 | L28: 1 | M28: 4 | N28: 0 | O28: 2 | P28: 1 | Q28: 2 | R28: 7 | S28: 2
B29: 60 | C29: 140 | D29: 293 | E29: 170 | F29: 1.2 | G29: 2 | H29: 2 | L29: 1 | M29: 4 | N29: 0 | O29: 2 | P29: 0 | Q29: 2 | R29: 7 | S29: 2
B30: 63 | C30: 150 | D30: 407 | E30: 154 | F30: 4 | G30: 3 | H30: 2 | L30: 0 | M30: 4 | N30: 0 | O30: 2 | P30: 0 | Q30: 2 | R30: 7 | S30: 2
B31: 1 | C31: 1 | D31: 1 | E31: 1 | F31: 1 | G31: 1 | L31: 0 | M31: 0 | N31: 0 | O31: 0 | P31: 0 | Q31: 0 | R31: 0

Sheet Quantitative
A1: Quantitative Features
A2: № | H2: Class | K2: K1 = 4
B3: 70 | C3: 130 | D3: 322 | E3: 109 | F3: 2.4 | G3: 3 | H3: 2 | K3: K2 = 6 | M3: Color and Sign of Quantitative Features - | Q3: 1
B4: 67 | C4: 115 | D4: 564 | E4: 160 | F4: 1.6 | G4: 0 | H4: 1
B5: 57 | C5: 124 | D5: 261 | E5: 141 | F5: 0.3 | G5: 0 | H5: 2
B6: 64 | C6: 128 | D6: 263 | E6: 105 | F6: 0.2 | G6: 1 | H6: 1 | K6: Criterion 1
B7: 74 | C7: 120 | D7: 269 | E7: 121 | F7: 0.2 | G7: 1 | H7: 1 | K7: №
B8: 65 | C8: 120 | D8: 177 | E8: 140 | F8: 0.4 | G8: 0 | H8: 1 | L8: 56 | M8: 63 | N8: 74 | O8: 0.634921
B9: 56 | C9: 130 | D9: 256 | E9: 142 | F9: 0.6 | G9: 1 | H9: 2 | L9: 110 | M9: 120 | N9: 150 | O9: 0.412698
B10: 59 | C10: 110 | D10: 239 | E10: 142 | F10: 1.2 | G10: 1 | H10: 2 | L10: 177 | M10: 177 | N10: 564 | O10: 0.214286
B11: 60 | C11: 140 | D11: 293 | E11: 170 | F11: 1.2 | G11: 2 | H11: 2 | L11: 105 | M11: 140 | N11: 170 | O11: 0.412698
B12: 63 | C12: 150 | D12: 407 | E12: 154 | F12: 4 | G12: 3 | H12: 2 | L12: 0.2 | M12: 0.4 | N12: 4 | O12: 0.412698
B13: 1 | C13: 1 | D13: 1 | E13: 1 | F13: 1 | G13: 1 | L13: 0 | M13: 0 | N13: 3 | O13: 0.285714
A17: № | C17: Class | G17: № | I17: Class | K17: № | M17: Class | O17: № | Q17: Class | S17: № | U17: Class | W17: № | Y17: Class
B18: 56 | C18: 2 | H18: 110 | I18: 2 | L18: 177 | M18: 1 | P18: 105 | Q18: 1 | T18: 0.2 | U18: 1 | X18: 0 | Y18: 1
B19: 57 | C19: 2 | H19: 115 | I19: 1 | L19: 239 | M19: 2 | P19: 109 | Q19: 2 | T19: 0.2 | U19: 1 | X19: 0 | Y19: 2
B20: 59 | C20: 2 | E20: Class 1 | H20: 120 | I20: 1 | L20: 256 | M20: 2 | P20: 121 | Q20: 1 | T20: 0.3 | U20: 2 | X20: 0 | Y20: 1
B21: 60 | C21: 2 | H21: 120 | I21: 1 | L21: 261 | M21: 2 | P21: 140 | Q21: 1 | T21: 0.4 | U21: 1 | X21: 1 | Y21: 1
B22: 63 | C22: 2 | H22: 124 | I22: 2 | L22: 263 | M22: 1 | P22: 141 | Q22: 2 | T22: 0.6 | U22: 2 | X22: 1 | Y22: 1
B23: 64 | C23: 1 | H23: 128 | I23: 1 | L23: 269 | M23: 1 | P23: 142 | Q23: 2 | T23: 1.2 | U23: 2 | X23: 1 | Y23: 2
B24: 65 | C24: 1 | H24: 130 | I24: 2 | L24: 293 | M24: 2 | P24: 142 | Q24: 2 | T24: 1.2 | U24: 2 | X24: 1 | Y24: 2
B25: 67 | C25: 1 | E25: Class 2 | H25: 130 | I25: 2 | L25: 322 | M25: 2 | P25: 154 | Q25: 2 | T25: 1.6 | U25: 1 | X25: 2 | Y25: 2
B26: 70 | C26: 2 | H26: 140 | I26: 2 | L26: 407 | M26: 2 | P26: 160 | Q26: 1 | T26: 2.4 | U26: 2 | X26: 3 | Y26: 2
B27: 74 | C27: 1 | H27: 150 | I27: 2 | L27: 564 | M27: 1 | P27: 170 | Q27: 2 | T27: 4 | U27: 2 | X27: 3 | Y27: 2
B29: =AVERAGE(B22,B23) -> 63.5 | H29: =AVERAGE(H21,H22) -> 122 | L29: =AVERAGE(L18,L19) -> 208 | P29: =AVERAGE(P21,P22) -> 140.5 | T29: =AVERAGE(T21,T22) -> 0.5 | X29: =AVERAGE(X20,X21) -> 0.5
A33: Quantitative features on a Nominal scale
A34: № | H34: Class
B35: =IF(B3<$B$29,1,2) -> 2 | C35: =IF(C3<$H$29,1,2) -> 2 | D35: =IF(D3<$L$29,1,2) -> 2 | E35: =IF(E3<$P$29,1,2) -> 1 | F35: =IF(F3<$T$29,1,2) -> 2 | G35: =IF(G3<$X$29,1,2) -> 2 | H35: 2
B36: =IF(B4<$B$29,1,2) -> 2 | C36: =IF(C4<$H$29,1,2) -> 1 | D36: =IF(D4<$L$29,1,2) -> 2 | E36: =IF(E4<$P$29,1,2) -> 2 | F36: =IF(F4<$T$29,1,2) -> 2 | G36: =IF(G4<$X$29,1,2) -> 1 | H36: 1
B37: =IF(B5<$B$29,1,2) -> 1 | C37: =IF(C5<$H$29,1,2) -> 2 | D37: =IF(D5<$L$29,1,2) -> 2 | E37: =IF(E5<$P$29,1,2) -> 2 | F37: =IF(F5<$T$29,1,2) -> 1 | G37: =IF(G5<$X$29,1,2) -> 1 | H37: 2
B38: =IF(B6<$B$29,1,2) -> 2 | C38: =IF(C6<$H$29,1,2) -> 2 | D38: =IF(D6<$L$29,1,2) -> 2 | E38: =IF(E6<$P$29,1,2) -> 1 | F38: =IF(F6<$T$29,1,2) -> 1 | G38: =IF(G6<$X$29,1,2) -> 2 | H38: 1
B39: =IF(B7<$B$29,1,2) -> 2 | C39: =IF(C7<$H$29,1,2) -> 1 | D39: =IF(D7<$L$29,1,2) -> 2 | E39: =IF(E7<$P$29,1,2) -> 1 | F39: =IF(F7<$T$29,1,2) -> 1 | G39: =IF(G7<$X$29,1,2) -> 2 | H39: 1
B40: =IF(B8<$B$29,1,2) -> 2 | C40: =IF(C8<$H$29,1,2) -> 1 | D40: =IF(D8<$L$29,1,2) -> 1 | E40: =IF(E8<$P$29,1,2) -> 1 | F40: =IF(F8<$T$29,1,2) -> 1 | G40: =IF(G8<$X$29,1,2) -> 1 | H40: 1
B41: =IF(B9<$B$29,1,2) -> 1 | C41: =IF(C9<$H$29,1,2) -> 2 | D41: =IF(D9<$L$29,1,2) -> 2 | E41: =IF(E9<$P$29,1,2) -> 2 | F41: =IF(F9<$T$29,1,2) -> 2 | G41: =IF(G9<$X$29,1,2) -> 2 | H41: 2
B42: =IF(B10<$B$29,1,2) -> 1 | C42: =IF(C10<$H$29,1,2) -> 1 | D42: =IF(D10<$L$29,1,2) -> 2 | E42: =IF(E10<$P$29,1,2) -> 2 | F42: =IF(F10<$T$29,1,2) -> 2 | G42: =IF(G10<$X$29,1,2) -> 2 | H42: 2
B43: =IF(B11<$B$29,1,2) -> 1 | C43: =IF(C11<$H$29,1,2) -> 2 | D43: =IF(D11<$L$29,1,2) -> 2 | E43: =IF(E11<$P$29,1,2) -> 2 | F43: =IF(F11<$T$29,1,2) -> 2 | G43: =IF(G11<$X$29,1,2) -> 2 | H43: 2
B44: =IF(B12<$B$29,1,2) -> 1 | C44: =IF(C12<$H$29,1,2) -> 2 | D44: =IF(D12<$L$29,1,2) -> 2 | E44: =IF(E12<$P$29,1,2) -> 2 | F44: =IF(F12<$T$29,1,2) -> 2 | G44: =IF(G12<$X$29,1,2) -> 2 | H44: 2
A47: Sorted by Classes of Quantitative features on a Nominal scale
A48: № | H48: Class
B49: =IF(B4<$B$29,1,2) -> 2 | C49: =IF(C4<$H$29,1,2) -> 1 | D49: =IF(D4<$L$29,1,2) -> 2 | E49: =IF(E4<$P$29,1,2) -> 2 | F49: =IF(F4<$T$29,1,2) -> 2 | G49: =IF(G4<$X$29,1,2) -> 1 | H49: 1
...

Sheet Nominal
A1: Nominal Features
A2: № | I2: Class | L2: K1 = 4
B3: 1 | C3: 4 | D3: 0 | E3: 2 | F3: 0 | G3: 2 | H3: 3 | I3: 2 | L3: K2 = 6 | N3: Color and Sign of Nominal Features - | R3: 0
B4: 0 | C4: 3 | D4: 0 | E4: 2 | F4: 0 | G4: 2 | H4: 7 | I4: 1
B5: 1 | C5: 2 | D5: 0 | E5: 0 | F5: 0 | G5: 1 | H5: 7 | I5: 2
B6: 1 | C6: 4 | D6: 0 | E6: 0 | F6: 1 | G6: 2 | H6: 7 | I6: 1
B7: 0 | C7: 2 | D7: 0 | E7: 2 | F7: 1 | G7: 1 | H7: 3 | I7: 1
B8: 1 | C8: 4 | D8: 0 | E8: 0 | F8: 0 | G8: 1 | H8: 7 | I8: 1
B9: 1 | C9: 3 | D9: 1 | E9: 2 | F9: 1 | G9: 2 | H9: 6 | I9: 2
B10: 1 | C10: 4 | D10: 0 | E10: 2 | F10: 1 | G10: 2 | H10: 7 | I10: 2
B11: 1 | C11: 4 | D11: 0 | E11: 2 | F11: 0 | G11: 2 | H11: 7 | I11: 2
B12: 0 | C12: 4 | D12: 0 | E12: 2 | F12: 0 | G12: 2 | H12: 7 | I12: 2
B13: 0 | C13: 0 | D13: 0 | E13: 0 | F13: 0 | G13: 0 | H13: 0
A17: Nominal Features
A18: № | I18: Class
B19: 0 | C19: 3 | D19: 0 | E19: 2 | F19: 0 | G19: 2 | H19: 7 | I19: 1
B20: 1 | C20: 4 | D20: 0 | E20: 0 | F20: 1 | G20: 2 | H20: 7 | I20: 1
B21: 0 | C21: 2 | D21: 0 | E21: 2 | F21: 1 | G21: 1 | H21: 3 | I21: 1
B22: 1 | C22: 4 | D22: 0 | E22: 0 | F22: 0 | G22: 1 | H22: 7 | I22: 1
B23: 1 | C23: 4 | D23: 0 | E23: 2 | F23: 0 | G23: 2 | H23: 3 | I23: 2
B24: 1 | C24: 2 | D24: 0 | E24: 0 | F24: 0 | G24: 1 | H24: 7 | I24: 2
B25: 1 | C25: 3 | D25: 1 | E25: 2 | F25: 1 | G25: 2 | H25: 6 | I25: 2
B26: 1 | C26: 4 | D26: 0 | E26: 2 | F26: 1 | G26: 2 | H26: 7 | I26: 2
B27: 1 | C27: 4 | D27: 0 | E27: 2 | F27: 0 | G27: 2 | H27: 7 | I27: 2
B28: 0 | C28: 4 | D28: 0 | E28: 2 | F28: 0 | G28: 2 | H28: 7 | I28: 2
A32: Gradations of Nominal Features | L32: Helper List Spreadsheet for Gradations of Nominal Features
A33: Gradations | B33: {0,1} | C33: {2,3,4} | D33: {0,1} | E33: {0,2} | F33: {0,1} | G33: {1,2} | H33: {3,6,7} | I33: Class | L33: L31:L32 | M33: M31:M33 | N33: N31:N32 | O33: O31:O32 | P33: P31:P32 | Q33: Q31:Q32 | R33: R31:R33
B34: {=IFERROR(SUMPRODUCT(((B$19:B$28)*1=INDEX($L$34:$L$35,INT((ROW()-34)/2)+1))*((($I$19:$I$28)*1)=1+MOD(ROW()-34,2))),"")} -> 2 | C34: {=IFERROR(SUMPRODUCT(((C$19:C$28)*1=INDEX($M$34:$M$36,INT((ROW()-34)/2)+1))*((($I$19:$I$28)*1)=1+MOD(ROW()-34,2))),"")} -> 1 | D34: {=IFERROR(SUMPRODUCT(((D$19:D$28)*1=INDEX($N$34:$N$35,INT((ROW()-34)/2)+1))*((($I$19:$I$28)*1)=1+MOD(ROW()-34,2))),"")} -> 4 | E34: {=IFERROR(SUMPRODUCT(((E$19:E$28)*1=INDEX($O$34:$O$35,INT((ROW()-34)/2)+1))*((($I$19:$I$28)*1)=1+MOD(ROW()-34,2))),"")} -> 2 | F34: {=IFERROR(SUMPRODUCT(((F$19:F$28)*1=INDEX($P$34:$P$35,INT((ROW()-34)/2)+1))*((($I$19:$I$28)*1)=1+MOD(ROW()-34,2))),"")} -> 2 | G34: {=IFERROR(SUMPRODUCT(((G$19:G$28)*1=INDEX($Q$34:$Q$35,INT((ROW()-34)/2)+1))*((($I$19:$I$28)*1)=1+MOD(ROW()-34,2))),"")} -> 2 | H34: {=IFERROR(SUMPRODUCT(((H$19:H$28)*1=INDEX($R$34:$R$36,INT((ROW()-34)/2)+1))*((($I$19:$I$28)*1)=1+MOD(ROW()-34,2))),"")} -> 1 | I34: 1 | L34: 0 | M34: 2 | N34: 0 | O34: 0 | P34: 0 | Q34: 1 | R34: 3
B35: {=IFERROR(SUMPRODUCT(((B$19:B$28)*1=INDEX($L$34:$L$35,INT((ROW()-34)/2)+1))*((($I$19:$I$28)*1)=1+MOD(ROW()-34,2))),"")} -> 1 | C35: {=IFERROR(SUMPRODUCT(((C$19:C$28)*1=INDEX($M$34:$M$36,INT((ROW()-34)/2)+1))*((($I$19:$I$28)*1)=1+MOD(ROW()-34,2))),"")} -> 1 | D35: {=IFERROR(SUMPRODUCT(((D$19:D$28)*1=INDEX($N$34:$N$35,INT((ROW()-34)/2)+1))*((($I$19:$I$28)*1)=1+MOD(ROW()-34,2))),"")} -> 5 | E35: {=IFERROR(SUMPRODUCT(((E$19:E$28)*1=INDEX($O$34:$O$35,INT((ROW()-34)/2)+1))*((($I$19:$I$28)*1)=1+MOD(ROW()-34,2))),"")} -> 1 | F35: {=IFERROR(SUMPRODUCT(((F$19:F$28)*1=INDEX($P$34:$P$35,INT((ROW()-34)/2)+1))*((($I$19:$I$28)*1)=1+MOD(ROW()-34,2))),"")} -> 4 | G35: {=IFERROR(SUMPRODUCT(((G$19:G$28)*1=INDEX($Q$34:$Q$35,INT((ROW()-34)/2)+1))*((($I$19:$I$28)*1)=1+MOD(ROW()-34,2))),"")} -> 1 | H35: {=IFERROR(SUMPRODUCT(((H$19:H$28)*1=INDEX($R$34:$R$36,INT((ROW()-34)/2)+1))*((($I$19:$I$28)*1)=1+MOD(ROW()-34,2))),"")} -> 1 | I35: 2 | L35: 1 | M35: 3 | N35: 1 | O35: 2 | P35: 1 | Q35: 2 | R35: 6
B36: {=IFERROR(SUMPRODUCT(((B$19:B$28)*1=INDEX($L$34:$L$35,INT((ROW()-34)/2)+1))*((($I$19:$I$28)*1)=1+MOD(ROW()-34,2))),"")} -> 2 | C36: {=IFERROR(SUMPRODUCT(((C$19:C$28)*1=INDEX($M$34:$M$36,INT((ROW()-34)/2)+1))*((($I$19:$I$28)*1)=1+MOD(ROW()-34,2))),"")} -> 1 | D36: {=IFERROR(SUMPRODUCT(((D$19:D$28)*1=INDEX($N$34:$N$35,INT((ROW()-34)/2)+1))*((($I$19:$I$28)*1)=1+MOD(ROW()-34,2))),"")} -> 0 | E36: {=IFERROR(SUMPRODUCT(((E$19:E$28)*1=INDEX($O$34:$O$35,INT((ROW()-34)/2)+1))*((($I$19:$I$28)*1)=1+MOD(ROW()-34,2))),"")} -> 2 | F36: {=IFERROR(SUMPRODUCT(((F$19:F$28)*1=INDEX($P$34:$P$35,INT((ROW()-34)/2)+1))*((($I$19:$I$28)*1)=1+MOD(ROW()-34,2))),"")} -> 2 | G36: {=IFERROR(SUMPRODUCT(((G$19:G$28)*1=INDEX($Q$34:$Q$35,INT((ROW()-34)/2)+1))*((($I$19:$I$28)*1)=1+MOD(ROW()-34,2))),"")} -> 2 | H36: {=IFERROR(SUMPRODUCT(((H$19:H$28)*1=INDEX($R$34:$R$36,INT((ROW()-34)/2)+1))*((($I$19:$I$28)*1)=1+MOD(ROW()-34,2))),"")} -> 0 | I36: 1 | M36: 4 | R36: 7
B37: {=IFERROR(SUMPRODUCT(((B$19:B$28)*1=INDEX($L$34:$L$35,INT((ROW()-34)/2)+1))*((($I$19:$I$28)*1)=1+MOD(ROW()-34,2))),"")} -> 5 | C37: {=IFERROR(SUMPRODUCT(((C$19:C$28)*1=INDEX($M$34:$M$36,INT((ROW()-34)/2)+1))*((($I$19:$I$28)*1)=1+MOD(ROW()-34,2))),"")} -> 1 | D37: {=IFERROR(SUMPRODUCT(((D$19:D$28)*1=INDEX($N$34:$N$35,INT((ROW()-34)/2)+1))*((($I$19:$I$28)*1)=1+MOD(ROW()-34,2))),"")} -> 1 | E37: {=IFERROR(SUMPRODUCT(((E$19:E$28)*1=INDEX($O$34:$O$35,INT((ROW()-34)/2)+1))*((($I$19:$I$28)*1)=1+MOD(ROW()-34,2))),"")} -> 5 | F37: {=IFERROR(SUMPRODUCT(((F$19:F$28)*1=INDEX($P$34:$P$35,INT((ROW()-34)/2)+1))*((($I$19:$I$28)*1)=1+MOD(ROW()-34,2))),"")} -> 2 | G37: {=IFERROR(SUMPRODUCT(((G$19:G$28)*1=INDEX($Q$34:$Q$35,INT((ROW()-34)/2)+1))*((($I$19:$I$28)*1)=1+MOD(ROW()-34,2))),"")} -> 5 | H37: {=IFERROR(SUMPRODUCT(((H$19:H$28)*1=INDEX($R$34:$R$36,INT((ROW()-34)/2)+1))*((($I$19:$I$28)*1)=1+MOD(ROW()-34,2))),"")} -> 1 | I37: 2
C38: {=IFERROR(SUMPRODUCT(((C$19:C$28)*1=INDEX($M$34:$M$36,INT((ROW()-34)/2)+1))*((($I$19:$I$28)*1)=1+MOD(ROW()-34,2))),"")} -> 2 | H38: {=IFERROR(SUMPRODUCT(((H$19:H$28)*1=INDEX($R$34:$R$36,INT((ROW()-34)/2)+1))*((($I$19:$I$28)*1)=1+MOD(ROW()-34,2))),"")} -> 3 | I38: 1
C39: {=IFERROR(SUMPRODUCT(((C$19:C$28)*1=INDEX($M$34:$M$36,INT((ROW()-34)/2)+1))*((($I$19:$I$28)*1)=1+MOD(ROW()-34,2))),"")} -> 4 | H39: {=IFERROR(SUMPRODUCT(((H$19:H$28)*1=INDEX($R$34:$R$36,INT((ROW()-34)/2)+1))*((($I$19:$I$28)*1)=1+MOD(ROW()-34,2))),"")} -> 4 | I39: 2
B44: =COUNTA(_xlfn.UNIQUE(B3:B12)) -> 2 | C44: =COUNTA(_xlfn.UNIQUE(C3:C12)) -> 3 | D44: =COUNTA(_xlfn.UNIQUE(D3:D12)) -> 2 | E44: =COUNTA(_xlfn.UNIQUE(E3:E12)) -> 2 | F44: =COUNTA(_xlfn.UNIQUE(F3:F12)) -> 2 | G44: =COUNTA(_xlfn.UNIQUE(G3:G12)) -> 2 | H44: =COUNTA(_xlfn.UNIQUE(H3:H12)) -> 3 | J44: K1 = | K44: 4
B45: =COUNTA(_xlfn.UNIQUE(B19:B22)) -> 2 | C45: =COUNTA(_xlfn.UNIQUE(C19:C22)) -> 3 | D45: =COUNTA(_xlfn.UNIQUE(D19:D22)) -> 1 | E45: =COUNTA(_xlfn.UNIQUE(E19:E22)) -> 2 | F45: =COUNTA(_xlfn.UNIQUE(F19:F22)) -> 2 | G45: =COUNTA(_xlfn.UNIQUE(G19:G22)) -> 2 | H45: =COUNTA(_xlfn.UNIQUE(H19:H22)) -> 2 | J45: K2 = | K45: 6
B46: =COUNTA(_xlfn.UNIQUE(B23:B28)) -> 2 | C46: =COUNTA(_xlfn.UNIQUE(C23:C28)) -> 3 | D46: =COUNTA(_xlfn.UNIQUE(D23:D28)) -> 2 | E46: =COUNTA(_xlfn.UNIQUE(E23:E28)) -> 2 | F46: =COUNTA(_xlfn.UNIQUE(F23:F28)) -> 2 | G46: =COUNTA(_xlfn.UNIQUE(G23:G28)) -> 2 | H46: =COUNTA(_xlfn.UNIQUE(H23:H28)) -> 3
B47: =IFERROR(IF(B$44>2, ($K44-B45+1)*($K44-B45), $K44*($K44-1)), "Error!!!") -> 12 | C47: =IFERROR(IF(C$44>2, ($K44-C45+1)*($K44-C45), $K44*($K44-1)), "Error!!!") -> 2 | D47: =IFERROR(IF(D$44>2, ($K44-D45+1)*($K44-D45), $K44*($K44-1)), "Error!!!") -> 12 | E47: =IFERROR(IF(E$44>2, ($K44-E45+1)*($K44-E45), $K44*($K44-1)), "Error!!!") -> 12 | F47: =IFERROR(IF(F$44>2, ($K44-F45+1)*($K44-F45), $K44*($K44-1)), "Error!!!") -> 12 | G47: =IFERROR(IF(G$44>2, ($K44-G45+1)*($K44-G45), $K44*($K44-1)), "Error!!!") -> 12 | H47: =IFERROR(IF(H$44>2, ($K44-H45+1)*($K44-H45), $K44*($K44-1)), "Error!!!") -> 6
B48: =IFERROR(IF(B$44>2, ($K45-B46+1)*($K45-B46), $K45*($K45-1)), "Error!!!") -> 30 | C48: =IFERROR(IF(C$44>2, ($K45-C46+1)*($K45-C46), $K45*($K45-1)), "Error!!!") -> 12 | D48: =IFERROR(IF(D$44>2, ($K45-D46+1)*($K45-D46), $K45*($K45-1)), "Error!!!") -> 30 | E48: =IFERROR(IF(E$44>2, ($K45-E46+1)*($K45-E46), $K45*($K45-1)), "Error!!!") -> 30 | F48: =IFERROR(IF(F$44>2, ($K45-F46+1)*($K45-F46), $K45*($K45-1)), "Error!!!") -> 30 | G48: =IFERROR(IF(G$44>2, ($K45-G46+1)*($K45-G46), $K45*($K45-1)), "Error!!!") -> 30 | H48: =IFERROR(IF(H$44>2, ($K45-H46+1)*($K45-H46), $K45*($K45-1)), "Error!!!") -> 12
A52: Lambda, Beta and Weight of Nominal Features
A53: Weight
...

Sheet Dataset (Contribution & Weight)
A1: Heart + Disease with Contribution Values (10, 13, 2)
A2: № | O2: Class
B3: 0.52910083 | C3: -0.14285714 | D3: -0.13194444 | E3: -0.2407405 | F3: -0.0535715 | G3: 0.074074074 | H3: -0.14285714 | I3: 0.2407405 | J3: -0.053571429 | K3: -0.2407405 | L3: -0.14285714 | M3: -0.095238 | N3: 0.060763889 | O3: 2
B4: 0.52910083 | C4: 0.14285714 | D4: 0.065972222 | E4: 0.2407405 | F4: -0.0535715 | G4: 0.074074074 | H4: -0.14285714 | I4: -0.2407405 | J4: -0.053571429 | K4: -0.2407405 | L4: -0.14285714 | M4: 0.095238 | N4: 0.060763889 | O4: 1
B5: -0.52910083 | C5: -0.14285714 | D5: 0.065972222 | E5: -0.2407405 | F5: -0.0535715 | G5: 0.074074074 | H5: 0.14285714 | I5: -0.2407405 | J5: -0.053571429 | K5: 0.2407405 | L5: 0.14285714 | M5: 0.095238 | N5: 0.060763889 | O5: 2
B6: 0.52910083 | C6: -0.14285714 | D6: -0.13194444 | E6: -0.2407405 | F6: -0.0535715 | G6: 0.074074074 | H6: 0.14285714 | I6: 0.2407405 | J6: 0.053571429 | K6: 0.2407405 | L6: -0.14285714 | M6: -0.095238 | N6: 0.060763889 | O6: 1
B7: 0.52910083 | C7: 0.14285714 | D7: 0.065972222 | E7: 0.2407405 | F7: -0.0535715 | G7: 0.074074074 | H7: -0.14285714 | I7: 0.2407405 | J7: 0.053571429 | K7: 0.2407405 | L7: 0.14285714 | M7: -0.095238 | N7: 0.060763889 | O7: 1
B8: 0.52910083 | C8: -0.14285714 | D8: -0.13194444 | E8: 0.2407405 | F8: 0.0535715 | G8: 0.074074074 | H8: 0.14285714 | I8: 0.2407405 | J8: -0.053571429 | K8: 0.2407405 | L8: 0.14285714 | M8: 0.095238 | N8: 0.060763889 | O8: 1
B9: -0.52910083 | C9: -0.14285714 | D9: 0.065972222 | E9: -0.2407405 | F9: -0.0535715 | G9: -0.074074074 | H9: -0.14285714 | I9: -0.2407405 | J9: 0.053571429 | K9: -0.2407405 | L9: -0.14285714 | M9: -0.095238 | N9: -0.12152778 | O9: 2
B10: -0.52910083 | C10: -0.14285714 | D10: -0.13194444 | E10: 0.2407405 | F10: -0.0535715 | G10: 0.074074074 | H10: -0.14285714 | I10: -0.2407405 | J10: 0.053571429 | K10: -0.2407405 | L10: -0.14285714 | M10: -0.095238 | N10: 0.060763889 | O10: 2
B11: -0.52910083 | C11: -0.14285714 | D11: -0.13194444 | E11: -0.2407405 | F11: -0.0535715 | G11: 0.074074074 | H11: -0.14285714 | I11: -0.2407405 | J11: -0.053571429 | K11: -0.2407405 | L11: -0.14285714 | M11: -0.095238 | N11: 0.060763889 | O11: 2
B12: -0.52910083 | C12: 0.14285714 | D12: -0.13194444 | E12: -0.2407405 | F12: -0.0535715 | G12: 0.074074074 | H12: -0.14285714 | I12: -0.2407405 | J12: -0.053571429 | K12: -0.2407405 | L12: -0.14285714 | M12: -0.095238 | N12: 0.060763889 | O12: 2
B13: 1 | C13: 0 | D13: 0 | E13: 1 | F13: 1 | G13: 0 | H13: 0 | I13: 1 | J13: 0 | K13: 1 | L13: 0 | M13: 1 | N13: 0
B16: Weight [Heart-Disease (10, 13, 2)]
B18: 0.634921 | C18: 0.42857143 | D18: 0.79166667 | E18: 0.412698 | F18: 0.214286 | G18: 0.44444444 | H18: 0.42857143 | I18: 0.412698 | J18: 0.32142857 | K18: 0.412698 | L18: 0.42857143 | M18: 0.285714 | N18: 0.72916667
B19: =COUNTIF($B$18:$N$18, ">" & B18) + COUNTIF($B$18:B18, "=" & B18) -> 3 | C19: =COUNTIF($B$18:$N$18, ">" & C18) + COUNTIF($B$18:C18, "=" & C18) -> 5 | D19: =COUNTIF($B$18:$N$18, ">" & D18) + COUNTIF($B$18:D18, "=" & D18) -> 1 | E19: =COUNTIF($B$18:$N$18, ">" & E18) + COUNTIF($B$18:E18, "=" & E18) -> 8 | F19: =COUNTIF($B$18:$N$18, ">" & F18) + COUNTIF($B$18:F18, "=" & F18) -> 13 | G19: =COUNTIF($B$18:$N$18, ">" & G18) + COUNTIF($B$18:G18, "=" & G18) -> 4 | H19: =COUNTIF($B$18:$N$18, ">" & H18) + COUNTIF($B$18:H18, "=" & H18) -> 6 | I19: =COUNTIF($B$18:$N$18, ">" & I18) + COUNTIF($B$18:I18, "=" & I18) -> 9 | ... N19: =COUNTIF($B$18:$N$18, ">" & N18) + COUNTIF($B$18:N18, "=" & N18) -> 2

Sheet Brace for Meta-algorithm
A1: Initial Features | I1: Additional (Latent) Features
A2: № | G2: Class | I2: № | N2: Class
B3: -0.13194444 | C3: 0.074074074 | D3: 0.060763889 | E3: -0.2407405 | F3: -0.053571429 | G3: 2 | J3: -0.37806569 | K3: -0.67699741 | L3: -1.3589807 | M3: -1.9056239 | N3: 2 | Q3: 5
B4: 0.065972222 | C4: 0.074074074 | D4: 0.060763889 | E4: 0.2407405 | F4: -0.053571429 | G4: 1 | J4: 0.40872846 | K4: 0.69225412 | L4: 1.0973332 | M4: 1.1955875 | N4: 1
B5: 0.065972222 | C5: 0.074074074 | D5: 0.060763889 | E5: -0.2407405 | F5: -0.053571429 | G5: 2 | J5: -0.14942742 | K5: -0.4136154 | L5: -1.0620338 | M5: -1.5793807 | N5: 2
B6: -0.13194444 | C6: 0.074074074 | D6: 0.060763889 | E6: -0.2407405 | F6: 0.053571429 | G6: 1 | J6: 0.23923915 | K6: 0.54607491 | L6: 0.55066154 | M6: 0.80910909 | N6: 1
B7: 0.065972222 | C7: 0.074074074 | D7: 0.060763889 | E7: 0.2407405 | F7: 0.053571429 | G7: 1 | J7: 0.40872846 | K7: 0.69225412 | L7: 1.0973332 | M7: 1.2912244 | N7: 1
B8: -0.13194444 | C8: 0.074074074 | D8: 0.060763889 | E8: 0.2407405 | F8: -0.053571429 | G8: 1 | J8: 0.23923915 | K8: 0.54607491 | L8: 0.96858288 | M8: 1.0814391 | N8: 1
B9: 0.065972222 | C9: -0.074074074 | D9: -0.12152778 | E9: -0.2407405 | F9: 0.053571429 | G9: 2 | J9: -0.32058778 | K9: -0.82013351 | L9: -1.5186565 | M9: -1.9627812 | N9: 2
B10: -0.13194444 | C10: 0.074074074 | D10: 0.060763889 | E10: 0.2407405 | F10: 0.053571429 | G10: 2 | J10: -0.37806569 | K10: -0.67699741 | L10: -0.81342788 | M10: -1.181445 | N10: 2
B11: -0.13194444 | C11: 0.074074074 | D11: 0.060763889 | E11: -0.2407405 | F11: -0.053571429 | G11: 2 | J11: -0.37806569 | K11: -0.67699741 | L11: -1.3589807 | M11: -1.9056239 | N11: 2
B12: -0.13194444 | C12: 0.074074074 | D12: 0.060763889 | E12: -0.2407405 | F12: -0.053571429 | G12: 2 | J12: -0.37806569 | K12: -0.67699741 | L12: -1.3589807 | M12: -1.9056239 | N12: 2
B14: Total Number of Initial Features - | E14: 5 | J14: Total Number of Additional Features - | M14: 4
A21: Dataset for Meta-algorithms [Heart + Disease (10, 13, 2)]
A22: № | K22: Class | M22: K1 = 4
B23: -0.13194444 | C23: 0.074074074 | D23: 0.060763889 | E23: -0.2407405 | F23: -0.053571429 | G23: -0.37806569 | H23: -0.67699741 | I23: -1.3589807 | J23: -1.9056239 | K23: 2 | M23: K2 = 6
B24: 0.065972222 | C24: 0.074074074 | D24: 0.060763889 | E24: 0.2407405 | F24: -0.053571429 | G24: 0.40872846 | H24: 0.69225412 | I24: 1.0973332 | J24: 1.1955875 | K24: 1
B25: 0.065972222 | C25: 0.074074074 | D25: 0.060763889 | E25: -0.2407405 | F25: -0.053571429 | G25: -0.14942742 | H25: -0.4136154 | I25: -1.0620338 | J25: -1.5793807 | K25: 2 | M25: Color of Initial Features
B26: -0.13194444 | C26: 0.074074074 | D26: 0.060763889 | E26: -0.2407405 | F26: 0.053571429 | G26: 0.23923915 | H26: 0.54607491 | I26: 0.55066154 | J26: 0.80910909 | K26: 1 | M26: Color of Additional Features
B27: 0.065972222 | C27: 0.074074074 | D27: 0.060763889 | E27: 0.2407405 | F27: 0.053571429 | G27: 0.40872846 | H27: 0.69225412 | I27: 1.0973332 | J27: 1.2912244 | K27: 1
B28: -0.13194444 | C28: 0.074074074 | D28: 0.060763889 | E28: 0.2407405 | F28: -0.053571429 | G28: 0.23923915 | H28: 0.54607491 | I28: 0.96858288 | J28: 1.0814391 | K28: 1
B29: 0.065972222 | C29: -0.074074074 | D29: -0.12152778 | E29: -0.2407405 | F29: 0.053571429 | G29: -0.32058778 | H29: -0.82013351 | I29: -1.5186565 | J29: -1.9627812 | K29: 2
B30: -0.13194444 | C30: 0.074074074 | D30: 0.060763889 | E30: 0.2407405 | F30: 0.053571429 | G30: -0.37806569 | H30: -0.67699741 | I30: -0.81342788 | J30: -1.181445 | K30: 2
B31: -0.13194444 | C31: 0.074074074 | D31: 0.060763889 | E31: -0.2407405 | F31: -0.053571429 | G31: -0.37806569 | H31: -0.67699741 | I31: -1.3589807 | J31: -1.9056239 | K31: 2
B32: -0.13194444 | C32: 0.074074074 | D32: 0.060763889 | E32: -0.2407405 | F32: -0.053571429 | G32: -0.37806569 | H32: -0.67699741 | I32: -1.3589807 | J32: -1.9056239 | K32: 2
A40: Classifying a New Object with Meta-algorithm [Heart + Disease (10, 13, 2)]
A42: Criterion 1 (Quantitative Features)
A43: №
B44: 56 | C44: 63 | D44: 74 | E44: 0.634921
B45: 110 | C45: 120 | D45: 150 | E45: 0.412698 | F45: We need only this FEATURE !!! Cause only this is in the SET among Quant. Features
B46: 177 | C46: 177 | D46: 564 | E46: 0.214286
B47: 105 | C47: 140 | D47: 170 | E47: 0.412698
B48: 0.2 | C48: 0.4 | D48: 4 | E48: 0.412698
B49: 0 | C49: 0 | D49: 3 | E49: 0.285714
D52: № | F52: Class
E53: 110 | F53: 2
E54: 115 | F54: 1 | H54: Class 1
E55: 120 | F55: 1
E56: 120 | F56: 1
E57: 124 | F57: 2
...

Sheet Meta-algorithm
A1: Original Training Dataset for Meta-algorithm [Heart + Disease (10, 13, 2)] | I1: Additional (Latent) Training Dataset for Meta-algorithm [Heart + Disease (10, 13, 2)]
G2: Class | N2: Class
B3: 3 | C3: 0 | D3: 7 | E3: 1 | F3: 0 | G3: 1 | J3: 0.40872846 | K3: 0.69225412 | L3: 1.0973332 | M3: 1.1955875 | N3: 1 | Q3: 5
B4: 4 | C4: 0 | D4: 7 | E4: 2 | F4: 1 | G4: 1 | J4: 0.23923915 | K4: 0.54607491 | L4: 0.55066154 | M4: 0.80910909 | N4: 1 | Q4: =Q3-1 -> 4
B5: 2 | C5: 0 | D5: 3 | E5: 1 | F5: 1 | G5: 1 | J5: 0.40872846 | K5: 0.69225412 | L5: 1.0973332 | M5: 1.2912244 | N5: 1
B6: 4 | C6: 0 | D6: 7 | E6: 1 | F6: 0 | G6: 1 | J6: 0.23923915 | K6: 0.54607491 | L6: 0.96858288 | M6: 1.0814391 | N6: 1 | Q6: 4
B7: 4 | C7: 0 | D7: 3 | E7: 2 | F7: 0 | G7: 2 | J7: -0.37806569 | K7: -0.67699741 | L7: -1.3589807 | M7: -1.9056239 | N7: 2 | Q7: 6
B8: 2 | C8: 0 | D8: 7 | E8: 2 | F8: 0 | G8: 2 | J8: -0.14942742 | K8: -0.4136154 | L8: -1.0620338 | M8: -1.5793807 | N8: 2
B9: 3 | C9: 1 | D9: 6 | E9: 2 | F9: 1 | G9: 2 | J9: -0.32058778 | K9: -0.82013351 | L9: -1.5186565 | M9: -1.9627812 | N9: 2
B10: 4 | C10: 0 | D10: 7 | E10: 1 | F10: 1 | G10: 2 | J10: -0.37806569 | K10: -0.67699741 | L10: -0.81342788 | M10: -1.181445 | N10: 2
B11: 4 | C11: 0 | D11: 7 | E11: 2 | F11: 0 | G11: 2 | J11: -0.37806569 | K11: -0.67699741 | L11: -1.3589807 | M11: -1.9056239 | N11: 2
B12: 4 | C12: 0 | D12: 7 | E12: 2 | F12: 0 | G12: 2 | J12: -0.37806569 | K12: -0.67699741 | L12: -1.3589807 | M12: -1.9056239 | N12: 2
A16: Step 1
K18: =Q3-1 -> 4
K19: 0
A22: Classifying a New Object with Meta-algorithm [Heart + Disease (10, 13, 2)]
G23: Class
B24: 4 | C24: 0 | D24: 7 | E24: 2 | F24: 0 | G24: *
B25: 3 | C25: 6 | D25: 13 | E25: 4 | F25: 9
B26: ↓
B30: 3 | D30: The Organizer of GA with the Value of Original Training Dataset
B31: 4 | F31: Class
B32: 2 | C32: → | E32: 4 | F32: 1 | H32: →
B33: 4 | E33: 4 | F33: 1
B34: 4 | E34: 4 | F34: 2 | H34: →
B35: 2 | C35: → | E35: 4 | F35: 2
B36: 3 | E36: 4 | F36: 2
B37: 4 | E37: 4 | F37: 2
B38: 4
B39: 4
A43: Step 2
K45: =Q3-1 -> 4
K46: 1
A49: Classifying a New Object with Meta-algorithm [Heart + Disease (10, 13, 2)]
G50: Class
B51: 4 | C51: 0 | D51: 7 | E51: 2 | F51: 0 | G51: *
B52: 3 | C52: 6 | D52: 13 | E52: 4 | F52: 9
C53: ↓
A55: The Second Feature of GA with the Value of Original Training Dataset | J55: Apply Original Feature Condition
B57: 0 | M57: Apply Latent Sign Condition
...
