Workbook

Sheet Overview
B2: Regularized Stacking Ensemble with HAG
B3: Experiment on the Heart-Disease dataset · 10 objects · 13 features · 2 classes
B5: Workbook map
B6: # | C6: Sheet | D6: Stage | E6: What it contains
B7: 1 | C7: Dataset | D7: 1 · Input data | E7: Original sample: 10 objects (S₁–S₁₀) × 13 features (x₁–x₁₃) with class labels (K1 = 4, K2 = 6); feature-type flags (1 = quantitative, 0 = nominal) and the split into 6 quantitative and 7 nominal features.
B8: 2 | C8: Quantitative | D8: 2 · Feature analysis | E8: Quantitative features: Criterion 1 boundary values and weights, per-feature class-sorted tables, conversion to a nominal scale, gradations, weights and contributions of gradations, and the features expressed as contribution values.
B9: 3 | C9: Nominal | D9: 2 · Feature analysis | E9: Nominal features: class-sorted table, gradations with a helper list, gradation parameters, λ, β and weight ω of each feature, contributions of gradations, and the features expressed as contribution values.
B10: 4 | C10: Dataset (Contribution & Weight) | D10: 3 · Weighted dataset | E10: All 13 features expressed as contribution values, with the weight of every feature and its rank (1 = highest weight).
B11: 5 | C11: Greedy upon Weight (1-Latent) | D11: 4 · Latent feature 1 | E11: Greedy search upon weight: STEP 1 initialisation, STEP 2 selection of the highest-weight feature, STEP 3 generalised assessment of every remaining candidate, and STEP 4 majorizing (sigmoid) function → latent feature 1.
B12: 6 | C12: Greedy upon Weight (2-Latent) | D12: 4 · Latent feature 2 | E12: Same greedy procedure (STEPS 3–4, majorizing function, STEP 4 check) building latent feature 2.
B13: 7 | C13: Greedy upon Weight (3-Latent) | D13: 4 · Latent feature 3 | E13: Same greedy procedure (STEPS 3–4, majorizing function, STEP 4 check) building latent feature 3.
B14: 8 | C14: Greedy upon Weight (4-Latent) | D14: 4 · Latent feature 4 | E14: Same greedy procedure (STEPS 3–4, majorizing function, STEP 4 check) building latent feature 4.
B15: 9 | C15: Dataset for Meta-algorithm | D15: 5 · Output | E15: Final dataset for the meta-algorithm: 5 initial features y₀–y₄ (from x₃, x₆, x₁₃, x₄, x₉) and 4 latent features r₁–r₄, with class labels.
B17: Key figures
B18: # | C18: Figure | D18: Value | E18: Linked to
B19: 1 | C19: Objects (samples) | D19: =COUNT(Dataset!O3:O12) -> 10 | E19: Dataset · O3:O12
B20: 2 | C20: Features in the original dataset | D20: =COUNT(Dataset!B3:N3) -> 13 | E20: Dataset · B3:N3
B21: 3 | C21: Classes | D21: =SUMPRODUCT(1/COUNTIF(Dataset!O3:O12,Dataset!O3:O12)) -> 2 | E21: Dataset · O3:O12
B22: 4 | C22: Objects in class 1 (K1) | D22: =COUNTIF(Dataset!O3:O12,1) -> 4 | E22: Dataset · O3:O12
B23: 5 | C23: Objects in class 2 (K2) | D23: =COUNTIF(Dataset!O3:O12,2) -> 6 | E23: Dataset · O3:O12
B24: 6 | C24: Quantitative features | D24: =Dataset!F17 -> 6 | E24: Dataset · F17
B25: 7 | C25: Nominal features | D25: =Dataset!P17 -> 7 | E25: Dataset · P17
B26: 8 | C26: Initial features kept for the meta-algorithm | D26: ='Dataset for Meta-algorithm'!E14 -> 5 | E26: Dataset for Meta-algorithm · E14
B27: 9 | C27: Latent (additional) features created | D27: ='Dataset for Meta-algorithm'!M14 -> 4 | E27: Dataset for Meta-algorithm · M14
B28: 10 | C28: Features in the meta-dataset | D28: =D26+D27 -> 9 | E28: D26 + D27 (initial kept + latent)
B30: Colour legend
B31: Aa | C31: Sheet title / main table title
B32: Aa | C32: Section title, STEP box
B33: Aa | C33: Column header (feature symbols x₁…x₁₃, y, r, …)
B34: Aa | C34: Object label S₁…S₁₀ and row captions
B35: Aa | C35: Quantitative feature values
B36: Aa | C36: Nominal feature values
B37: Aa | C37: Class label (1 / 2)
B38: Aa | C38: Selected feature / highlighted result
B39: Aa | C39: Initial features in the meta-dataset
B40: Aa | C40: Additional (latent) features in the meta-dataset
B41: Aa | C41: Key label (counts, sign / colour keys)
B43: Notes
B44: • Symbols such as x₁, S₁, ω_c and η_c in the sheets are Office-Math equation objects placed over the cells; they display fully in Excel for Windows / Mac.
B45: • All numbers, formulas and results are identical to the original workbook; only formatting, colours, print setup and this Overview sheet were added. Numbers keep the original General display.
...

Sheet Dataset
A1: Heart + Disease (10, 13, 2)
A2: № | O2: Class | Q2: K1 = 4
B3: 70 | C3: 1 | D3: 4 | E3: 130 | F3: 322 | G3: 0 | H3: 2 | I3: 109 | J3: 0 | K3: 2.4 | L3: 2 | M3: 3 | N3: 3 | O3: 2 | Q3: K2 = 6
B4: 67 | C4: 0 | D4: 3 | E4: 115 | F4: 564 | G4: 0 | H4: 2 | I4: 160 | J4: 0 | K4: 1.6 | L4: 2 | M4: 0 | N4: 7 | O4: 1
B5: 57 | C5: 1 | D5: 2 | E5: 124 | F5: 261 | G5: 0 | H5: 0 | I5: 141 | J5: 0 | K5: 0.3 | L5: 1 | M5: 0 | N5: 7 | O5: 2 | Q5: Sign of Quantitative Features - | T5: 1
B6: 64 | C6: 1 | D6: 4 | E6: 128 | F6: 263 | G6: 0 | H6: 0 | I6: 105 | J6: 1 | K6: 0.2 | L6: 2 | M6: 1 | N6: 7 | O6: 1 | Q6: Sign of Nominal Features - | T6: 0
B7: 74 | C7: 0 | D7: 2 | E7: 120 | F7: 269 | G7: 0 | H7: 2 | I7: 121 | J7: 1 | K7: 0.2 | L7: 1 | M7: 1 | N7: 3 | O7: 1
B8: 65 | C8: 1 | D8: 4 | E8: 120 | F8: 177 | G8: 0 | H8: 0 | I8: 140 | J8: 0 | K8: 0.4 | L8: 1 | M8: 0 | N8: 7 | O8: 1
B9: 56 | C9: 1 | D9: 3 | E9: 130 | F9: 256 | G9: 1 | H9: 2 | I9: 142 | J9: 1 | K9: 0.6 | L9: 2 | M9: 1 | N9: 6 | O9: 2
B10: 59 | C10: 1 | D10: 4 | E10: 110 | F10: 239 | G10: 0 | H10: 2 | I10: 142 | J10: 1 | K10: 1.2 | L10: 2 | M10: 1 | N10: 7 | O10: 2
B11: 60 | C11: 1 | D11: 4 | E11: 140 | F11: 293 | G11: 0 | H11: 2 | I11: 170 | J11: 0 | K11: 1.2 | L11: 2 | M11: 2 | N11: 7 | O11: 2
B12: 63 | C12: 0 | D12: 4 | E12: 150 | F12: 407 | G12: 0 | H12: 2 | I12: 154 | J12: 0 | K12: 4 | L12: 2 | M12: 3 | N12: 7 | O12: 2
B13: 1 | C13: 0 | D13: 0 | E13: 1 | F13: 1 | G13: 0 | H13: 0 | I13: 1 | J13: 0 | K13: 1 | L13: 0 | M13: 1 | N13: 0
B17: Total Number of Quantitative Features - | F17: 6 | L17: Total Number of Nominal Features - | P17: 7
A19: Quantitative Features | K19: Nominal Features
A20: № | H20: Class | K20: № | S20: Class
B21: 70 | C21: 130 | D21: 322 | E21: 109 | F21: 2.4 | G21: 3 | H21: 2 | L21: 1 | M21: 4 | N21: 0 | O21: 2 | P21: 0 | Q21: 2 | R21: 3 | S21: 2
B22: 67 | C22: 115 | D22: 564 | E22: 160 | F22: 1.6 | G22: 0 | H22: 1 | L22: 0 | M22: 3 | N22: 0 | O22: 2 | P22: 0 | Q22: 2 | R22: 7 | S22: 1
B23: 57 | C23: 124 | D23: 261 | E23: 141 | F23: 0.3 | G23: 0 | H23: 2 | L23: 1 | M23: 2 | N23: 0 | O23: 0 | P23: 0 | Q23: 1 | R23: 7 | S23: 2
B24: 64 | C24: 128 | D24: 263 | E24: 105 | F24: 0.2 | G24: 1 | H24: 1 | L24: 1 | M24: 4 | N24: 0 | O24: 0 | P24: 1 | Q24: 2 | R24: 7 | S24: 1
B25: 74 | C25: 120 | D25: 269 | E25: 121 | F25: 0.2 | G25: 1 | H25: 1 | L25: 0 | M25: 2 | N25: 0 | O25: 2 | P25: 1 | Q25: 1 | R25: 3 | S25: 1
B26: 65 | C26: 120 | D26: 177 | E26: 140 | F26: 0.4 | G26: 0 | H26: 1 | L26: 1 | M26: 4 | N26: 0 | O26: 0 | P26: 0 | Q26: 1 | R26: 7 | S26: 1
B27: 56 | C27: 130 | D27: 256 | E27: 142 | F27: 0.6 | G27: 1 | H27: 2 | L27: 1 | M27: 3 | N27: 1 | O27: 2 | P27: 1 | Q27: 2 | R27: 6 | S27: 2
B28: 59 | C28: 110 | D28: 239 | E28: 142 | F28: 1.2 | G28: 1 | H28: 2 | L28: 1 | M28: 4 | N28: 0 | O28: 2 | P28: 1 | Q28: 2 | R28: 7 | S28: 2
B29: 60 | C29: 140 | D29: 293 | E29: 170 | F29: 1.2 | G29: 2 | H29: 2 | L29: 1 | M29: 4 | N29: 0 | O29: 2 | P29: 0 | Q29: 2 | R29: 7 | S29: 2
B30: 63 | C30: 150 | D30: 407 | E30: 154 | F30: 4 | G30: 3 | H30: 2 | L30: 0 | M30: 4 | N30: 0 | O30: 2 | P30: 0 | Q30: 2 | R30: 7 | S30: 2
B31: 1 | C31: 1 | D31: 1 | E31: 1 | F31: 1 | G31: 1 | L31: 0 | M31: 0 | N31: 0 | O31: 0 | P31: 0 | Q31: 0 | R31: 0

Sheet Quantitative
A1: Quantitative Features
A2: № | H2: Class | K2: K1 = 4
B3: 70 | C3: 130 | D3: 322 | E3: 109 | F3: 2.4 | G3: 3 | H3: 2 | K3: K2 = 6 | M3: Color and Sign of Quantitative Features - | Q3: 1
B4: 67 | C4: 115 | D4: 564 | E4: 160 | F4: 1.6 | G4: 0 | H4: 1
B5: 57 | C5: 124 | D5: 261 | E5: 141 | F5: 0.3 | G5: 0 | H5: 2
B6: 64 | C6: 128 | D6: 263 | E6: 105 | F6: 0.2 | G6: 1 | H6: 1 | K6: Criterion 1
B7: 74 | C7: 120 | D7: 269 | E7: 121 | F7: 0.2 | G7: 1 | H7: 1 | K7: №
B8: 65 | C8: 120 | D8: 177 | E8: 140 | F8: 0.4 | G8: 0 | H8: 1 | L8: 56 | M8: 63 | N8: 74 | O8: 0.634921
B9: 56 | C9: 130 | D9: 256 | E9: 142 | F9: 0.6 | G9: 1 | H9: 2 | L9: 110 | M9: 120 | N9: 150 | O9: 0.412698
B10: 59 | C10: 110 | D10: 239 | E10: 142 | F10: 1.2 | G10: 1 | H10: 2 | L10: 177 | M10: 177 | N10: 564 | O10: 0.214286
B11: 60 | C11: 140 | D11: 293 | E11: 170 | F11: 1.2 | G11: 2 | H11: 2 | L11: 105 | M11: 140 | N11: 170 | O11: 0.412698
B12: 63 | C12: 150 | D12: 407 | E12: 154 | F12: 4 | G12: 3 | H12: 2 | L12: 0.2 | M12: 0.4 | N12: 4 | O12: 0.412698
B13: 1 | C13: 1 | D13: 1 | E13: 1 | F13: 1 | G13: 1 | L13: 0 | M13: 0 | N13: 3 | O13: 0.285714
A17: № | C17: Class | E17: № | G17: Class | I17: № | K17: Class | M17: № | O17: Class | Q17: № | S17: Class | U17: № | W17: Class
B18: 56 | C18: 2 | F18: 110 | G18: 2 | J18: 177 | K18: 1 | N18: 105 | O18: 1 | R18: 0.2 | S18: 1 | V18: 0 | W18: 1
B19: 57 | C19: 2 | F19: 115 | G19: 1 | J19: 239 | K19: 2 | N19: 109 | O19: 2 | R19: 0.2 | S19: 1 | V19: 0 | W19: 2
B20: 59 | C20: 2 | F20: 120 | G20: 1 | J20: 256 | K20: 2 | N20: 121 | O20: 1 | R20: 0.3 | S20: 2 | V20: 0 | W20: 1
B21: 60 | C21: 2 | F21: 120 | G21: 1 | J21: 261 | K21: 2 | N21: 140 | O21: 1 | R21: 0.4 | S21: 1 | V21: 1 | W21: 1
B22: 63 | C22: 2 | F22: 124 | G22: 2 | J22: 263 | K22: 1 | N22: 141 | O22: 2 | R22: 0.6 | S22: 2 | V22: 1 | W22: 1
B23: 64 | C23: 1 | F23: 128 | G23: 1 | J23: 269 | K23: 1 | N23: 142 | O23: 2 | R23: 1.2 | S23: 2 | V23: 1 | W23: 2
B24: 65 | C24: 1 | F24: 130 | G24: 2 | J24: 293 | K24: 2 | N24: 142 | O24: 2 | R24: 1.2 | S24: 2 | V24: 1 | W24: 2
B25: 67 | C25: 1 | F25: 130 | G25: 2 | J25: 322 | K25: 2 | N25: 154 | O25: 2 | R25: 1.6 | S25: 1 | V25: 2 | W25: 2
B26: 70 | C26: 2 | F26: 140 | G26: 2 | J26: 407 | K26: 2 | N26: 160 | O26: 1 | R26: 2.4 | S26: 2 | V26: 3 | W26: 2
B27: 74 | C27: 1 | F27: 150 | G27: 2 | J27: 564 | K27: 1 | N27: 170 | O27: 2 | R27: 4 | S27: 2 | V27: 3 | W27: 2
B29: =AVERAGE(B22,B23) -> 63.5 | F29: =AVERAGE(F21,F22) -> 122 | J29: =AVERAGE(J18,J19) -> 208 | N29: =AVERAGE(N21,N22) -> 140.5 | R29: =AVERAGE(R21,R22) -> 0.5 | V29: =AVERAGE(V20,V21) -> 0.5
A33: Quantitative features on a Nominal scale
A34: № | H34: Class
B35: =IF(B3<$B$29,1,2) -> 2 | C35: =IF(C3<$F$29,1,2) -> 2 | D35: =IF(D3<$J$29,1,2) -> 2 | E35: =IF(E3<$N$29,1,2) -> 1 | F35: =IF(F3<$R$29,1,2) -> 2 | G35: =IF(G3<$V$29,1,2) -> 2 | H35: 2
B36: =IF(B4<$B$29,1,2) -> 2 | C36: =IF(C4<$F$29,1,2) -> 1 | D36: =IF(D4<$J$29,1,2) -> 2 | E36: =IF(E4<$N$29,1,2) -> 2 | F36: =IF(F4<$R$29,1,2) -> 2 | G36: =IF(G4<$V$29,1,2) -> 1 | H36: 1
B37: =IF(B5<$B$29,1,2) -> 1 | C37: =IF(C5<$F$29,1,2) -> 2 | D37: =IF(D5<$J$29,1,2) -> 2 | E37: =IF(E5<$N$29,1,2) -> 2 | F37: =IF(F5<$R$29,1,2) -> 1 | G37: =IF(G5<$V$29,1,2) -> 1 | H37: 2
B38: =IF(B6<$B$29,1,2) -> 2 | C38: =IF(C6<$F$29,1,2) -> 2 | D38: =IF(D6<$J$29,1,2) -> 2 | E38: =IF(E6<$N$29,1,2) -> 1 | F38: =IF(F6<$R$29,1,2) -> 1 | G38: =IF(G6<$V$29,1,2) -> 2 | H38: 1
B39: =IF(B7<$B$29,1,2) -> 2 | C39: =IF(C7<$F$29,1,2) -> 1 | D39: =IF(D7<$J$29,1,2) -> 2 | E39: =IF(E7<$N$29,1,2) -> 1 | F39: =IF(F7<$R$29,1,2) -> 1 | G39: =IF(G7<$V$29,1,2) -> 2 | H39: 1
B40: =IF(B8<$B$29,1,2) -> 2 | C40: =IF(C8<$F$29,1,2) -> 1 | D40: =IF(D8<$J$29,1,2) -> 1 | E40: =IF(E8<$N$29,1,2) -> 1 | F40: =IF(F8<$R$29,1,2) -> 1 | G40: =IF(G8<$V$29,1,2) -> 1 | H40: 1
B41: =IF(B9<$B$29,1,2) -> 1 | C41: =IF(C9<$F$29,1,2) -> 2 | D41: =IF(D9<$J$29,1,2) -> 2 | E41: =IF(E9<$N$29,1,2) -> 2 | F41: =IF(F9<$R$29,1,2) -> 2 | G41: =IF(G9<$V$29,1,2) -> 2 | H41: 2
B42: =IF(B10<$B$29,1,2) -> 1 | C42: =IF(C10<$F$29,1,2) -> 1 | D42: =IF(D10<$J$29,1,2) -> 2 | E42: =IF(E10<$N$29,1,2) -> 2 | F42: =IF(F10<$R$29,1,2) -> 2 | G42: =IF(G10<$V$29,1,2) -> 2 | H42: 2
B43: =IF(B11<$B$29,1,2) -> 1 | C43: =IF(C11<$F$29,1,2) -> 2 | D43: =IF(D11<$J$29,1,2) -> 2 | E43: =IF(E11<$N$29,1,2) -> 2 | F43: =IF(F11<$R$29,1,2) -> 2 | G43: =IF(G11<$V$29,1,2) -> 2 | H43: 2
B44: =IF(B12<$B$29,1,2) -> 1 | C44: =IF(C12<$F$29,1,2) -> 2 | D44: =IF(D12<$J$29,1,2) -> 2 | E44: =IF(E12<$N$29,1,2) -> 2 | F44: =IF(F12<$R$29,1,2) -> 2 | G44: =IF(G12<$V$29,1,2) -> 2 | H44: 2
A47: Sorted by Classes of Quantitative features on a Nominal scale
A48: № | H48: Class
B49: =IF(B4<$B$29,1,2) -> 2 | C49: =IF(C4<$F$29,1,2) -> 1 | D49: =IF(D4<$J$29,1,2) -> 2 | E49: =IF(E4<$N$29,1,2) -> 2 | F49: =IF(F4<$R$29,1,2) -> 2 | G49: =IF(G4<$V$29,1,2) -> 1 | H49: 1
...

Sheet Nominal
A1: Nominal Features
A2: № | I2: Class | L2: K1 = 4
B3: 1 | C3: 4 | D3: 0 | E3: 2 | F3: 0 | G3: 2 | H3: 3 | I3: 2 | L3: K2 = 6 | N3: Color and Sign of Nominal Features - | R3: 0
B4: 0 | C4: 3 | D4: 0 | E4: 2 | F4: 0 | G4: 2 | H4: 7 | I4: 1
B5: 1 | C5: 2 | D5: 0 | E5: 0 | F5: 0 | G5: 1 | H5: 7 | I5: 2
B6: 1 | C6: 4 | D6: 0 | E6: 0 | F6: 1 | G6: 2 | H6: 7 | I6: 1
B7: 0 | C7: 2 | D7: 0 | E7: 2 | F7: 1 | G7: 1 | H7: 3 | I7: 1
B8: 1 | C8: 4 | D8: 0 | E8: 0 | F8: 0 | G8: 1 | H8: 7 | I8: 1
B9: 1 | C9: 3 | D9: 1 | E9: 2 | F9: 1 | G9: 2 | H9: 6 | I9: 2
B10: 1 | C10: 4 | D10: 0 | E10: 2 | F10: 1 | G10: 2 | H10: 7 | I10: 2
B11: 1 | C11: 4 | D11: 0 | E11: 2 | F11: 0 | G11: 2 | H11: 7 | I11: 2
B12: 0 | C12: 4 | D12: 0 | E12: 2 | F12: 0 | G12: 2 | H12: 7 | I12: 2
B13: 0 | C13: 0 | D13: 0 | E13: 0 | F13: 0 | G13: 0 | H13: 0
A17: Nominal Features
A18: № | I18: Class
B19: 0 | C19: 3 | D19: 0 | E19: 2 | F19: 0 | G19: 2 | H19: 7 | I19: 1
B20: 1 | C20: 4 | D20: 0 | E20: 0 | F20: 1 | G20: 2 | H20: 7 | I20: 1
B21: 0 | C21: 2 | D21: 0 | E21: 2 | F21: 1 | G21: 1 | H21: 3 | I21: 1
B22: 1 | C22: 4 | D22: 0 | E22: 0 | F22: 0 | G22: 1 | H22: 7 | I22: 1
B23: 1 | C23: 4 | D23: 0 | E23: 2 | F23: 0 | G23: 2 | H23: 3 | I23: 2
B24: 1 | C24: 2 | D24: 0 | E24: 0 | F24: 0 | G24: 1 | H24: 7 | I24: 2
B25: 1 | C25: 3 | D25: 1 | E25: 2 | F25: 1 | G25: 2 | H25: 6 | I25: 2
B26: 1 | C26: 4 | D26: 0 | E26: 2 | F26: 1 | G26: 2 | H26: 7 | I26: 2
B27: 1 | C27: 4 | D27: 0 | E27: 2 | F27: 0 | G27: 2 | H27: 7 | I27: 2
B28: 0 | C28: 4 | D28: 0 | E28: 2 | F28: 0 | G28: 2 | H28: 7 | I28: 2
A32: Gradations of Nominal Features | L32: Helper List Spreadsheet for Gradations of Nominal Features
A33: Gradations | B33: {0,1} | C33: {2,3,4} | D33: {0,1} | E33: {0,2} | F33: {0,1} | G33: {1,2} | H33: {3,6,7} | I33: Class | L33: L31:L32 | M33: M31:M33 | N33: N31:N32 | O33: O31:O32 | P33: P31:P32 | Q33: Q31:Q32 | R33: R31:R33
B34: {=IFERROR(SUMPRODUCT(((B$19:B$28)*1=INDEX($L$34:$L$35,INT((ROW()-34)/2)+1))*((($I$19:$I$28)*1)=1+MOD(ROW()-34,2))),"")} -> 2 | C34: {=IFERROR(SUMPRODUCT(((C$19:C$28)*1=INDEX($M$34:$M$36,INT((ROW()-34)/2)+1))*((($I$19:$I$28)*1)=1+MOD(ROW()-34,2))),"")} -> 1 | D34: {=IFERROR(SUMPRODUCT(((D$19:D$28)*1=INDEX($N$34:$N$35,INT((ROW()-34)/2)+1))*((($I$19:$I$28)*1)=1+MOD(ROW()-34,2))),"")} -> 4 | E34: {=IFERROR(SUMPRODUCT(((E$19:E$28)*1=INDEX($O$34:$O$35,INT((ROW()-34)/2)+1))*((($I$19:$I$28)*1)=1+MOD(ROW()-34,2))),"")} -> 2 | F34: {=IFERROR(SUMPRODUCT(((F$19:F$28)*1=INDEX($P$34:$P$35,INT((ROW()-34)/2)+1))*((($I$19:$I$28)*1)=1+MOD(ROW()-34,2))),"")} -> 2 | G34: {=IFERROR(SUMPRODUCT(((G$19:G$28)*1=INDEX($Q$34:$Q$35,INT((ROW()-34)/2)+1))*((($I$19:$I$28)*1)=1+MOD(ROW()-34,2))),"")} -> 2 | H34: {=IFERROR(SUMPRODUCT(((H$19:H$28)*1=INDEX($R$34:$R$36,INT((ROW()-34)/2)+1))*((($I$19:$I$28)*1)=1+MOD(ROW()-34,2))),"")} -> 1 | I34: 1 | L34: 0 | M34: 2 | N34: 0 | O34: 0 | P34: 0 | Q34: 1 | R34: 3
B35: {=IFERROR(SUMPRODUCT(((B$19:B$28)*1=INDEX($L$34:$L$35,INT((ROW()-34)/2)+1))*((($I$19:$I$28)*1)=1+MOD(ROW()-34,2))),"")} -> 1 | C35: {=IFERROR(SUMPRODUCT(((C$19:C$28)*1=INDEX($M$34:$M$36,INT((ROW()-34)/2)+1))*((($I$19:$I$28)*1)=1+MOD(ROW()-34,2))),"")} -> 1 | D35: {=IFERROR(SUMPRODUCT(((D$19:D$28)*1=INDEX($N$34:$N$35,INT((ROW()-34)/2)+1))*((($I$19:$I$28)*1)=1+MOD(ROW()-34,2))),"")} -> 5 | E35: {=IFERROR(SUMPRODUCT(((E$19:E$28)*1=INDEX($O$34:$O$35,INT((ROW()-34)/2)+1))*((($I$19:$I$28)*1)=1+MOD(ROW()-34,2))),"")} -> 1 | F35: {=IFERROR(SUMPRODUCT(((F$19:F$28)*1=INDEX($P$34:$P$35,INT((ROW()-34)/2)+1))*((($I$19:$I$28)*1)=1+MOD(ROW()-34,2))),"")} -> 4 | G35: {=IFERROR(SUMPRODUCT(((G$19:G$28)*1=INDEX($Q$34:$Q$35,INT((ROW()-34)/2)+1))*((($I$19:$I$28)*1)=1+MOD(ROW()-34,2))),"")} -> 1 | H35: {=IFERROR(SUMPRODUCT(((H$19:H$28)*1=INDEX($R$34:$R$36,INT((ROW()-34)/2)+1))*((($I$19:$I$28)*1)=1+MOD(ROW()-34,2))),"")} -> 1 | I35: 2 | L35: 1 | M35: 3 | N35: 1 | O35: 2 | P35: 1 | Q35: 2 | R35: 6
B36: {=IFERROR(SUMPRODUCT(((B$19:B$28)*1=INDEX($L$34:$L$35,INT((ROW()-34)/2)+1))*((($I$19:$I$28)*1)=1+MOD(ROW()-34,2))),"")} -> 2 | C36: {=IFERROR(SUMPRODUCT(((C$19:C$28)*1=INDEX($M$34:$M$36,INT((ROW()-34)/2)+1))*((($I$19:$I$28)*1)=1+MOD(ROW()-34,2))),"")} -> 1 | D36: {=IFERROR(SUMPRODUCT(((D$19:D$28)*1=INDEX($N$34:$N$35,INT((ROW()-34)/2)+1))*((($I$19:$I$28)*1)=1+MOD(ROW()-34,2))),"")} -> 0 | E36: {=IFERROR(SUMPRODUCT(((E$19:E$28)*1=INDEX($O$34:$O$35,INT((ROW()-34)/2)+1))*((($I$19:$I$28)*1)=1+MOD(ROW()-34,2))),"")} -> 2 | F36: {=IFERROR(SUMPRODUCT(((F$19:F$28)*1=INDEX($P$34:$P$35,INT((ROW()-34)/2)+1))*((($I$19:$I$28)*1)=1+MOD(ROW()-34,2))),"")} -> 2 | G36: {=IFERROR(SUMPRODUCT(((G$19:G$28)*1=INDEX($Q$34:$Q$35,INT((ROW()-34)/2)+1))*((($I$19:$I$28)*1)=1+MOD(ROW()-34,2))),"")} -> 2 | H36: {=IFERROR(SUMPRODUCT(((H$19:H$28)*1=INDEX($R$34:$R$36,INT((ROW()-34)/2)+1))*((($I$19:$I$28)*1)=1+MOD(ROW()-34,2))),"")} -> 0 | I36: 1 | M36: 4 | R36: 7
B37: {=IFERROR(SUMPRODUCT(((B$19:B$28)*1=INDEX($L$34:$L$35,INT((ROW()-34)/2)+1))*((($I$19:$I$28)*1)=1+MOD(ROW()-34,2))),"")} -> 5 | C37: {=IFERROR(SUMPRODUCT(((C$19:C$28)*1=INDEX($M$34:$M$36,INT((ROW()-34)/2)+1))*((($I$19:$I$28)*1)=1+MOD(ROW()-34,2))),"")} -> 1 | D37: {=IFERROR(SUMPRODUCT(((D$19:D$28)*1=INDEX($N$34:$N$35,INT((ROW()-34)/2)+1))*((($I$19:$I$28)*1)=1+MOD(ROW()-34,2))),"")} -> 1 | E37: {=IFERROR(SUMPRODUCT(((E$19:E$28)*1=INDEX($O$34:$O$35,INT((ROW()-34)/2)+1))*((($I$19:$I$28)*1)=1+MOD(ROW()-34,2))),"")} -> 5 | F37: {=IFERROR(SUMPRODUCT(((F$19:F$28)*1=INDEX($P$34:$P$35,INT((ROW()-34)/2)+1))*((($I$19:$I$28)*1)=1+MOD(ROW()-34,2))),"")} -> 2 | G37: {=IFERROR(SUMPRODUCT(((G$19:G$28)*1=INDEX($Q$34:$Q$35,INT((ROW()-34)/2)+1))*((($I$19:$I$28)*1)=1+MOD(ROW()-34,2))),"")} -> 5 | H37: {=IFERROR(SUMPRODUCT(((H$19:H$28)*1=INDEX($R$34:$R$36,INT((ROW()-34)/2)+1))*((($I$19:$I$28)*1)=1+MOD(ROW()-34,2))),"")} -> 1 | I37: 2
C38: {=IFERROR(SUMPRODUCT(((C$19:C$28)*1=INDEX($M$34:$M$36,INT((ROW()-34)/2)+1))*((($I$19:$I$28)*1)=1+MOD(ROW()-34,2))),"")} -> 2 | H38: {=IFERROR(SUMPRODUCT(((H$19:H$28)*1=INDEX($R$34:$R$36,INT((ROW()-34)/2)+1))*((($I$19:$I$28)*1)=1+MOD(ROW()-34,2))),"")} -> 3 | I38: 1
C39: {=IFERROR(SUMPRODUCT(((C$19:C$28)*1=INDEX($M$34:$M$36,INT((ROW()-34)/2)+1))*((($I$19:$I$28)*1)=1+MOD(ROW()-34,2))),"")} -> 4 | H39: {=IFERROR(SUMPRODUCT(((H$19:H$28)*1=INDEX($R$34:$R$36,INT((ROW()-34)/2)+1))*((($I$19:$I$28)*1)=1+MOD(ROW()-34,2))),"")} -> 4 | I39: 2
B44: =COUNTA(_xlfn.UNIQUE(B3:B12)) -> 2 | C44: =COUNTA(_xlfn.UNIQUE(C3:C12)) -> 3 | D44: =COUNTA(_xlfn.UNIQUE(D3:D12)) -> 2 | E44: =COUNTA(_xlfn.UNIQUE(E3:E12)) -> 2 | F44: =COUNTA(_xlfn.UNIQUE(F3:F12)) -> 2 | G44: =COUNTA(_xlfn.UNIQUE(G3:G12)) -> 2 | H44: =COUNTA(_xlfn.UNIQUE(H3:H12)) -> 3 | J44: K1 = | K44: 4
B45: =COUNTA(_xlfn.UNIQUE(B19:B22)) -> 2 | C45: =COUNTA(_xlfn.UNIQUE(C19:C22)) -> 3 | D45: =COUNTA(_xlfn.UNIQUE(D19:D22)) -> 1 | E45: =COUNTA(_xlfn.UNIQUE(E19:E22)) -> 2 | F45: =COUNTA(_xlfn.UNIQUE(F19:F22)) -> 2 | G45: =COUNTA(_xlfn.UNIQUE(G19:G22)) -> 2 | H45: =COUNTA(_xlfn.UNIQUE(H19:H22)) -> 2 | J45: K2 = | K45: 6
B46: =COUNTA(_xlfn.UNIQUE(B23:B28)) -> 2 | C46: =COUNTA(_xlfn.UNIQUE(C23:C28)) -> 3 | D46: =COUNTA(_xlfn.UNIQUE(D23:D28)) -> 2 | E46: =COUNTA(_xlfn.UNIQUE(E23:E28)) -> 2 | F46: =COUNTA(_xlfn.UNIQUE(F23:F28)) -> 2 | G46: =COUNTA(_xlfn.UNIQUE(G23:G28)) -> 2 | H46: =COUNTA(_xlfn.UNIQUE(H23:H28)) -> 3
B47: =IFERROR(IF(B$44>2, ($K44-B45+1)*($K44-B45), $K44*($K44-1)), "Error!!!") -> 12 | C47: =IFERROR(IF(C$44>2, ($K44-C45+1)*($K44-C45), $K44*($K44-1)), "Error!!!") -> 2 | D47: =IFERROR(IF(D$44>2, ($K44-D45+1)*($K44-D45), $K44*($K44-1)), "Error!!!") -> 12 | E47: =IFERROR(IF(E$44>2, ($K44-E45+1)*($K44-E45), $K44*($K44-1)), "Error!!!") -> 12 | F47: =IFERROR(IF(F$44>2, ($K44-F45+1)*($K44-F45), $K44*($K44-1)), "Error!!!") -> 12 | G47: =IFERROR(IF(G$44>2, ($K44-G45+1)*($K44-G45), $K44*($K44-1)), "Error!!!") -> 12 | H47: =IFERROR(IF(H$44>2, ($K44-H45+1)*($K44-H45), $K44*($K44-1)), "Error!!!") -> 6
B48: =IFERROR(IF(B$44>2, ($K45-B46+1)*($K45-B46), $K45*($K45-1)), "Error!!!") -> 30 | C48: =IFERROR(IF(C$44>2, ($K45-C46+1)*($K45-C46), $K45*($K45-1)), "Error!!!") -> 12 | D48: =IFERROR(IF(D$44>2, ($K45-D46+1)*($K45-D46), $K45*($K45-1)), "Error!!!") -> 30 | E48: =IFERROR(IF(E$44>2, ($K45-E46+1)*($K45-E46), $K45*($K45-1)), "Error!!!") -> 30 | F48: =IFERROR(IF(F$44>2, ($K45-F46+1)*($K45-F46), $K45*($K45-1)), "Error!!!") -> 30 | G48: =IFERROR(IF(G$44>2, ($K45-G46+1)*($K45-G46), $K45*($K45-1)), "Error!!!") -> 30 | H48: =IFERROR(IF(H$44>2, ($K45-H46+1)*($K45-H46), $K45*($K45-1)), "Error!!!") -> 12
A52: Lambda, Beta and Weight of Nominal Features
A53: Weight
...

Sheet Dataset (Contribution & Weight)
A1: Heart + Disease with Contribution Values (10, 13, 2)
A2: № | O2: Class
B3: 0.52910083 | C3: -0.14285714 | D3: -0.13194444 | E3: -0.2407405 | F3: -0.0535715 | G3: 0.074074074 | H3: -0.14285714 | I3: 0.2407405 | J3: -0.053571429 | K3: -0.2407405 | L3: -0.14285714 | M3: -0.095238 | N3: 0.060763889 | O3: 2
B4: 0.52910083 | C4: 0.14285714 | D4: 0.065972222 | E4: 0.2407405 | F4: -0.0535715 | G4: 0.074074074 | H4: -0.14285714 | I4: -0.2407405 | J4: -0.053571429 | K4: -0.2407405 | L4: -0.14285714 | M4: 0.095238 | N4: 0.060763889 | O4: 1
B5: -0.52910083 | C5: -0.14285714 | D5: 0.065972222 | E5: -0.2407405 | F5: -0.0535715 | G5: 0.074074074 | H5: 0.14285714 | I5: -0.2407405 | J5: -0.053571429 | K5: 0.2407405 | L5: 0.14285714 | M5: 0.095238 | N5: 0.060763889 | O5: 2
B6: 0.52910083 | C6: -0.14285714 | D6: -0.13194444 | E6: -0.2407405 | F6: -0.0535715 | G6: 0.074074074 | H6: 0.14285714 | I6: 0.2407405 | J6: 0.053571429 | K6: 0.2407405 | L6: -0.14285714 | M6: -0.095238 | N6: 0.060763889 | O6: 1
B7: 0.52910083 | C7: 0.14285714 | D7: 0.065972222 | E7: 0.2407405 | F7: -0.0535715 | G7: 0.074074074 | H7: -0.14285714 | I7: 0.2407405 | J7: 0.053571429 | K7: 0.2407405 | L7: 0.14285714 | M7: -0.095238 | N7: 0.060763889 | O7: 1
B8: 0.52910083 | C8: -0.14285714 | D8: -0.13194444 | E8: 0.2407405 | F8: 0.0535715 | G8: 0.074074074 | H8: 0.14285714 | I8: 0.2407405 | J8: -0.053571429 | K8: 0.2407405 | L8: 0.14285714 | M8: 0.095238 | N8: 0.060763889 | O8: 1
B9: -0.52910083 | C9: -0.14285714 | D9: 0.065972222 | E9: -0.2407405 | F9: -0.0535715 | G9: -0.074074074 | H9: -0.14285714 | I9: -0.2407405 | J9: 0.053571429 | K9: -0.2407405 | L9: -0.14285714 | M9: -0.095238 | N9: -0.12152778 | O9: 2
B10: -0.52910083 | C10: -0.14285714 | D10: -0.13194444 | E10: 0.2407405 | F10: -0.0535715 | G10: 0.074074074 | H10: -0.14285714 | I10: -0.2407405 | J10: 0.053571429 | K10: -0.2407405 | L10: -0.14285714 | M10: -0.095238 | N10: 0.060763889 | O10: 2
B11: -0.52910083 | C11: -0.14285714 | D11: -0.13194444 | E11: -0.2407405 | F11: -0.0535715 | G11: 0.074074074 | H11: -0.14285714 | I11: -0.2407405 | J11: -0.053571429 | K11: -0.2407405 | L11: -0.14285714 | M11: -0.095238 | N11: 0.060763889 | O11: 2
B12: -0.52910083 | C12: 0.14285714 | D12: -0.13194444 | E12: -0.2407405 | F12: -0.0535715 | G12: 0.074074074 | H12: -0.14285714 | I12: -0.2407405 | J12: -0.053571429 | K12: -0.2407405 | L12: -0.14285714 | M12: -0.095238 | N12: 0.060763889 | O12: 2
B13: 1 | C13: 0 | D13: 0 | E13: 1 | F13: 1 | G13: 0 | H13: 0 | I13: 1 | J13: 0 | K13: 1 | L13: 0 | M13: 1 | N13: 0
B16: Weight [Heart-Disease (10, 13, 2)]
B18: 0.634921 | C18: 0.42857143 | D18: 0.79166667 | E18: 0.412698 | F18: 0.214286 | G18: 0.44444444 | H18: 0.42857143 | I18: 0.412698 | J18: 0.32142857 | K18: 0.412698 | L18: 0.42857143 | M18: 0.285714 | N18: 0.72916667
B19: =COUNTIF($B$18:$N$18, ">" & B18) + COUNTIF($B$18:B18, "=" & B18) -> 3 | C19: =COUNTIF($B$18:$N$18, ">" & C18) + COUNTIF($B$18:C18, "=" & C18) -> 5 | D19: =COUNTIF($B$18:$N$18, ">" & D18) + COUNTIF($B$18:D18, "=" & D18) -> 1 | E19: =COUNTIF($B$18:$N$18, ">" & E18) + COUNTIF($B$18:E18, "=" & E18) -> 8 | F19: =COUNTIF($B$18:$N$18, ">" & F18) + COUNTIF($B$18:F18, "=" & F18) -> 13 | G19: =COUNTIF($B$18:$N$18, ">" & G18) + COUNTIF($B$18:G18, "=" & G18) -> 4 | H19: =COUNTIF($B$18:$N$18, ">" & H18) + COUNTIF($B$18:H18, "=" & H18) -> 6 | I19: =COUNTIF($B$18:$N$18, ">" & I18) + COUNTIF($B$18:I18, "=" & I18) -> 9 | ... N19: =COUNTIF($B$18:$N$18, ">" & N18) + COUNTIF($B$18:N18, "=" & N18) -> 2

Sheet Greedy upon Weight (1-Latent)
A1: Heart + Disease with Contribution Values (10, 13, 2)
A2: № | O2: Class | Q2: K1 = | R2: 4 | U2: STEP 1 — Initialization | Z2: Class Mean (K1)
B3: 0.52910083 | C3: -0.14285714 | D3: -0.13194444 | E3: -0.2407405 | F3: -0.0535715 | G3: 0.074074074 | H3: -0.14285714 | I3: 0.2407405 | J3: -0.053571429 | K3: -0.2407405 | L3: -0.14285714 | M3: -0.095238 | N3: 0.060763889 | O3: 2 | Q3: K2 = | R3: 6 | U3: P = | V3: {x1, x2, …, x13}
B4: 0.52910083 | C4: 0.14285714 | D4: 0.065972222 | E4: 0.2407405 | F4: -0.0535715 | G4: 0.074074074 | H4: -0.14285714 | I4: -0.2407405 | J4: -0.053571429 | K4: -0.2407405 | L4: -0.14285714 | M4: 0.095238 | N4: 0.060763889 | O4: 1 | U4: |P| = | V4: =13 -> 13
B5: -0.52910083 | C5: -0.14285714 | D5: 0.065972222 | E5: -0.2407405 | F5: -0.0535715 | G5: 0.074074074 | H5: 0.14285714 | I5: -0.2407405 | J5: -0.053571429 | K5: 0.2407405 | L5: 0.14285714 | M5: 0.095238 | N5: 0.060763889 | O5: 2 | Q5: t = | U5: SET = | V5: ∅
B6: 0.52910083 | C6: -0.14285714 | D6: -0.13194444 | E6: -0.2407405 | F6: -0.0535715 | G6: 0.074074074 | H6: 0.14285714 | I6: 0.2407405 | J6: 0.053571429 | K6: 0.2407405 | L6: -0.14285714 | M6: -0.095238 | N6: 0.060763889 | O6: 1 | U6: counter = | V6: 0 | Z6: Class Mean (K2)
B7: 0.52910083 | C7: 0.14285714 | D7: 0.065972222 | E7: 0.2407405 | F7: -0.0535715 | G7: 0.074074074 | H7: -0.14285714 | I7: 0.2407405 | J7: 0.053571429 | K7: 0.2407405 | L7: 0.14285714 | M7: -0.095238 | N7: 0.060763889 | O7: 1 | Q7: t = m = | R7: 10
B8: 0.52910083 | C8: -0.14285714 | D8: -0.13194444 | E8: 0.2407405 | F8: 0.0535715 | G8: 0.074074074 | H8: 0.14285714 | I8: 0.2407405 | J8: -0.053571429 | K8: 0.2407405 | L8: 0.14285714 | M8: 0.095238 | N8: 0.060763889 | O8: 1
B9: -0.52910083 | C9: -0.14285714 | D9: 0.065972222 | E9: -0.2407405 | F9: -0.0535715 | G9: -0.074074074 | H9: -0.14285714 | I9: -0.2407405 | J9: 0.053571429 | K9: -0.2407405 | L9: -0.14285714 | M9: -0.095238 | N9: -0.12152778 | O9: 2 | Q9: u =
B10: -0.52910083 | C10: -0.14285714 | D10: -0.13194444 | E10: 0.2407405 | F10: -0.0535715 | G10: 0.074074074 | H10: -0.14285714 | I10: -0.2407405 | J10: 0.053571429 | K10: -0.2407405 | L10: -0.14285714 | M10: -0.095238 | N10: 0.060763889 | O10: 2
B11: -0.52910083 | C11: -0.14285714 | D11: -0.13194444 | E11: -0.2407405 | F11: -0.0535715 | G11: 0.074074074 | H11: -0.14285714 | I11: -0.2407405 | J11: -0.053571429 | K11: -0.2407405 | L11: -0.14285714 | M11: -0.095238 | N11: 0.060763889 | O11: 2 | Q11: q = u = | R11: argmin {θ/γ} | Z11: Intra-Class Similarity (Compactness)
B12: -0.52910083 | C12: 0.14285714 | D12: -0.13194444 | E12: -0.2407405 | F12: -0.0535715 | G12: 0.074074074 | H12: -0.14285714 | I12: -0.2407405 | J12: -0.053571429 | K12: -0.2407405 | L12: -0.14285714 | M12: -0.095238 | N12: 0.060763889 | O12: 2
B13: 1 | C13: 0 | D13: 0 | E13: 1 | F13: 1 | G13: 0 | H13: 0 | I13: 1 | J13: 0 | K13: 1 | L13: 0 | M13: 1 | N13: 0
Z15: Inter-Class Difference (Separability)
B16: Weight [Heart-Disease (10, 13, 2)] | Q16: cr1 =
T17: STEP 2 — Select initial feature (max weight)
B18: 0.634921 | C18: 0.42857143 | D18: 0.79166667 | E18: 0.412698 | F18: 0.214286 | G18: 0.44444444 | H18: 0.42857143 | I18: 0.412698 | J18: 0.32142857 | K18: 0.412698 | L18: 0.42857143 | M18: 0.285714 | N18: 0.72916667 | Q18: crit = | U18: max(W)=0.7917 ⇒ x3
B19: =COUNTIF($B$18:$N$18, ">" & B18) + COUNTIF($B$18:B18, "=" & B18) -> 3 | C19: =COUNTIF($B$18:$N$18, ">" & C18) + COUNTIF($B$18:C18, "=" & C18) -> 5 | D19: =COUNTIF($B$18:$N$18, ">" & D18) + COUNTIF($B$18:D18, "=" & D18) -> 1 | E19: =COUNTIF($B$18:$N$18, ">" & E18) + COUNTIF($B$18:E18, "=" & E18) -> 8 | F19: =COUNTIF($B$18:$N$18, ">" & F18) + COUNTIF($B$18:F18, "=" & F18) -> 13 | G19: =COUNTIF($B$18:$N$18, ">" & G18) + COUNTIF($B$18:G18, "=" & G18) -> 4 | H19: =COUNTIF($B$18:$N$18, ">" & H18) + COUNTIF($B$18:H18, "=" & H18) -> 6 | I19: =COUNTIF($B$18:$N$18, ">" & I18) + COUNTIF($B$18:I18, "=" & I18) -> 9 | ... N19: =COUNTIF($B$18:$N$18, ">" & N18) + COUNTIF($B$18:N18, "=" & N18) -> 2 | U19: SET = {5}
U20: counter = 1 | Z20: Majorizing Function (Sigmoid || Logistic)
C23: 10 | N23: 0.3
C24: 10 | K24: 1 | N24: 0.1
F25: ⇒ | I25: ⇒ | N25: 5
F26: 0 | K26: =V4-1 -> 12
A30: Calculation of Generalized Assessment | H30: STEPS
C31: + | E31: = | G31: Classes | P31: STEP 3 | U31: STEP 3 — Try adding each remaining feature
B32: -0.13194444 | C32: + | D32: 0.52910083 | E32: = | F32: =SUM(B32,D32) -> 0.39715639 | G32: 2 | H32: =IF(OR($G32=1,$G32=2), $F32 + IF($G32=1,1,-1)*$N$23*(EXP(-$F32)/(1+EXP(-$F32))), NA()) -> 0.27655767 | I32: =IF(G32=1,H32+N(I31),N(I31)) -> 0 | J32: =IF(G32=2,H32+N(J31),N(J31)) -> 0.27655767 | K32: =IFERROR(I32/COUNTIF($G$32:$G$41,1),"ERROR!!!") -> 0 | L32: =IFERROR(J32/COUNTIF($G$32:$G$41,2),"ERROR!!!") -> 0.046092945 | M32: =IF(ROW()=32, 0, M31) + ABS(H32 - IF($G32=1, $K32, $L32)) -> 0.23046472 | N32: =IF(ROW()=32, 0, N31) + ABS(H32 - IF($G32=1, $L32, $K32)) -> 0.27655767 | S32: =IF(O41<C23,O41,C23) -> 0.3805993 | V32: x ∈ P \ {x3}
B33: 0.065972222 | C33: + | D33: 0.52910083 | E33: = | F33: =SUM(B33,D33) -> 0.59507306 | G33: 1 | H33: =IF(OR($G33=1,$G33=2), $F33 + IF($G33=1,1,-1)*$N$23*(EXP(-$F33)/(1+EXP(-$F33))), NA()) -> 0.70171457 | I33: =IF(G33=1,H33+N(I32),N(I32)) -> 0.70171457 | J33: =IF(G33=2,H33+N(J32),N(J32)) -> 0.27655767 | K33: =IFERROR(I33/COUNTIF($G$32:$G$41,1),"ERROR!!!") -> 0.17542864 | L33: =IFERROR(J33/COUNTIF($G$32:$G$41,2),"ERROR!!!") -> 0.046092945 | M33: =IF(ROW()=32, 0, M32) + ABS(H33 - IF($G33=1, $K33, $L33)) -> 0.75675065 | N33: =IF(ROW()=32, 0, N32) + ABS(H33 - IF($G33=1, $L33, $K33)) -> 0.93217929 | S33: 1 | U33: Candidate: add x1
B34: 0.065972222 | C34: + | D34: -0.52910083 | E34: = | F34: =SUM(B34,D34) -> -0.46312861 | G34: 2 | H34: =IF(OR($G34=1,$G34=2), $F34 + IF($G34=1,1,-1)*$N$23*(EXP(-$F34)/(1+EXP(-$F34))), NA()) -> -0.64725544 | I34: =IF(G34=1,H34+N(I33),N(I33)) -> 0.70171457 | J34: =IF(G34=2,H34+N(J33),N(J33)) -> -0.37069778 | K34: =IFERROR(I34/COUNTIF($G$32:$G$41,1),"ERROR!!!") -> 0.17542864 | L34: =IFERROR(J34/COUNTIF($G$32:$G$41,2),"ERROR!!!") -> -0.061782963 | M34: =IF(ROW()=32, 0, M33) + ABS(H34 - IF($G34=1, $K34, $L34)) -> 1.3422231 | N34: =IF(ROW()=32, 0, N33) + ABS(H34 - IF($G34=1, $L34, $K34)) -> 1.7548634 | S34: =IF(O41<C23,S33,F26) -> 1 | U34: New temporary latent value:
B35: -0.13194444 | C35: + | D35: 0.52910083 | E35: = | F35: =SUM(B35,D35) -> 0.39715639 | G35: 1 | H35: =IF(OR($G35=1,$G35=2), $F35 + IF($G35=1,1,-1)*$N$23*(EXP(-$F35)/(1+EXP(-$F35))), NA()) -> 0.51775511 | I35: =IF(G35=1,H35+N(I34),N(I34)) -> 1.2194697 | J35: =IF(G35=2,H35+N(J34),N(J34)) -> -0.37069778 | K35: =IFERROR(I35/COUNTIF($G$32:$G$41,1),"ERROR!!!") -> 0.30486742 | L35: =IFERROR(J35/COUNTIF($G$32:$G$41,2),"ERROR!!!") -> -0.061782963 | M35: =IF(ROW()=32, 0, M34) + ABS(H35 - IF($G35=1, $K35, $L35)) -> 1.5551108 | N35: =IF(ROW()=32, 0, N34) + ABS(H35 - IF($G35=1, $L35, $K35)) -> 2.3344014
B36: 0.065972222 | C36: + | D36: 0.52910083 | E36: = | F36: =SUM(B36,D36) -> 0.59507306 | G36: 1 | H36: =IF(OR($G36=1,$G36=2), $F36 + IF($G36=1,1,-1)*$N$23*(EXP(-$F36)/(1+EXP(-$F36))), NA()) -> 0.70171457 | I36: =IF(G36=1,H36+N(I35),N(I35)) -> 1.9211842 | J36: =IF(G36=2,H36+N(J35),N(J35)) -> -0.37069778 | K36: =IFERROR(I36/COUNTIF($G$32:$G$41,1),"ERROR!!!") -> 0.48029606 | L36: =IFERROR(J36/COUNTIF($G$32:$G$41,2),"ERROR!!!") -> -0.061782963 | M36: =IF(ROW()=32, 0, M35) + ABS(H36 - IF($G36=1, $K36, $L36)) -> 1.7765293 | N36: =IF(ROW()=32, 0, N35) + ABS(H36 - IF($G36=1, $L36, $K36)) -> 3.097899
B37: -0.13194444 | C37: + | D37: 0.52910083 | E37: = | F37: =SUM(B37,D37) -> 0.39715639 | G37: 1 | H37: =IF(OR($G37=1,$G37=2), $F37 + IF($G37=1,1,-1)*$N$23*(EXP(-$F37)/(1+EXP(-$F37))), NA()) -> 0.51775511 | I37: =IF(G37=1,H37+N(I36),N(I36)) -> 2.4389394 | J37: =IF(G37=2,H37+N(J36),N(J36)) -> -0.37069778 | K37: =IFERROR(I37/COUNTIF($G$32:$G$41,1),"ERROR!!!") -> 0.60973484 | L37: =IFERROR(J37/COUNTIF($G$32:$G$41,2),"ERROR!!!") -> -0.061782963 | M37: =IF(ROW()=32, 0, M36) + ABS(H37 - IF($G37=1, $K37, $L37)) -> 1.8685091 | N37: =IF(ROW()=32, 0, N36) + ABS(H37 - IF($G37=1, $L37, $K37)) -> 3.6774371
B38: 0.065972222 | C38: + | D38: -0.52910083 | E38: = | F38: =SUM(B38,D38) -> -0.46312861 | G38: 2 | H38: =IF(OR($G38=1,$G38=2), $F38 + IF($G38=1,1,-1)*$N$23*(EXP(-$F38)/(1+EXP(-$F38))), NA()) -> -0.64725544 | I38: =IF(G38=1,H38+N(I37),N(I37)) -> 2.4389394 | J38: =IF(G38=2,H38+N(J37),N(J37)) -> -1.0179532 | K38: =IFERROR(I38/COUNTIF($G$32:$G$41,1),"ERROR!!!") -> 0.60973484 | L38: =IFERROR(J38/COUNTIF($G$32:$G$41,2),"ERROR!!!") -> -0.16965887 | M38: =IF(ROW()=32, 0, M37) + ABS(H38 - IF($G38=1, $K38, $L38)) -> 2.3461056 | N38: =IF(ROW()=32, 0, N37) + ABS(H38 - IF($G38=1, $L38, $K38)) -> 4.9344273
B39: -0.13194444 | C39: + | D39: -0.52910083 | E39: = | F39: =SUM(B39,D39) -> -0.66104528 | G39: 2 | H39: =IF(OR($G39=1,$G39=2), $F39 + IF($G39=1,1,-1)*$N$23*(EXP(-$F39)/(1+EXP(-$F39))), NA()) -> -0.85889382 | I39: =IF(G39=1,H39+N(I38),N(I38)) -> 2.4389394 | J39: =IF(G39=2,H39+N(J38),N(J38)) -> -1.876847 | K39: =IFERROR(I39/COUNTIF($G$32:$G$41,1),"ERROR!!!") -> 0.60973484 | L39: =IFERROR(J39/COUNTIF($G$32:$G$41,2),"ERROR!!!") -> -0.31280784 | M39: =IF(ROW()=32, 0, M38) + ABS(H39 - IF($G39=1, $K39, $L39)) -> 2.8921916 | N39: =IF(ROW()=32, 0, N38) + ABS(H39 - IF($G39=1, $L39, $K39)) -> 6.403056
B40: -0.13194444 | C40: + | D40: -0.52910083 | E40: = | F40: =SUM(B40,D40) -> -0.66104528 | G40: 2 | H40: =IF(OR($G40=1,$G40=2), $F40 + IF($G40=1,1,-1)*$N$23*(EXP(-$F40)/(1+EXP(-$F40))), NA()) -> -0.85889382 | I40: =IF(G40=1,H40+N(I39),N(I39)) -> 2.4389394 | J40: =IF(G40=2,H40+N(J39),N(J39)) -> -2.7357409 | K40: =IFERROR(I40/COUNTIF($G$32:$G$41,1),"ERROR!!!") -> 0.60973484 | L40: =IFERROR(J40/COUNTIF($G$32:$G$41,2),"ERROR!!!") -> -0.45595681 | M40: =IF(ROW()=32, 0, M39) + ABS(H40 - IF($G40=1, $K40, $L40)) -> 3.2951286 | N40: =IF(ROW()=32, 0, N39) + ABS(H40 - IF($G40=1, $L40, $K40)) -> 7.8716847
B41: -0.13194444 | C41: + | D41: -0.52910083 | E41: = | F41: =SUM(B41,D41) -> -0.66104528 | G41: 2 | H41: =IF(OR($G41=1,$G41=2), $F41 + IF($G41=1,1,-1)*$N$23*(EXP(-$F41)/(1+EXP(-$F41))), NA()) -> -0.85889382 | I41: =IF(G41=1,H41+N(I40),N(I40)) -> 2.4389394 | J41: =IF(G41=2,H41+N(J40),N(J40)) -> -3.5946347 | K41: =IFERROR(I41/COUNTIF($G$32:$G$41,1),"ERROR!!!") -> 0.60973484 | L41: =IFERROR(J41/COUNTIF($G$32:$G$41,2),"ERROR!!!") -> -0.59910578 | M41: =IF(ROW()=32, 0, M40) + ABS(H41 - IF($G41=1, $K41, $L41)) -> 3.5549167 | N41: =IF(ROW()=32, 0, N40) + ABS(H41 - IF($G41=1, $L41, $K41)) -> 9.3403133 | O41: =M41/N41 -> 0.3805993
A45: Calculation of Generalized Assessment | H45: STEPS
C46: + | E46: = | G46: Classes | P46: STEP 3 | U46: STEP 3 — Try adding each remaining feature
B47: -0.13194444 | C47: + | D47: -0.14285714 | E47: = | F47: =SUM(B47,D47) -> -0.27480159 | G47: 2 | H47: =IF(OR($G47=1,$G47=2), $F47 + IF($G47=1,1,-1)*$N$23*(EXP(-$F47)/(1+EXP(-$F47))), NA()) -> -0.44528298 | I47: =IF(G47=1,H47+N(I46),N(I46)) -> 0 | J47: =IF(G47=2,H47+N(J46),N(J46)) -> -0.44528298 | K47: =IFERROR(I47/COUNTIF($G$47:$G$56,1),"ERROR!!!") -> 0 | L47: =IFERROR(J47/COUNTIF($G$47:$G$56,2),"ERROR!!!") -> -0.07421383 | M47: =IF(ROW()=47, 0, M46) + ABS(H47 - IF($G47=1, $K47, $L47)) -> 0.37106915 | N47: =IF(ROW()=47, 0, N46) + ABS(H47 - IF($G47=1, $L47, $K47)) -> 0.44528298 | R47: cr1 = | S47: =IF(O56<S32,O56,S32) -> 0.3805993 | V47: x ∈ P \ {x3}
B48: 0.065972222 | C48: + | D48: 0.14285714 | E48: = | F48: =SUM(B48,D48) -> 0.20882937 | G48: 1 | H48: =IF(OR($G48=1,$G48=2), $F48 + IF($G48=1,1,-1)*$N$23*(EXP(-$F48)/(1+EXP(-$F48))), NA()) -> 0.34322383 | I48: =IF(G48=1,H48+N(I47),N(I47)) -> 0.34322383 | J48: =IF(G48=2,H48+N(J47),N(J47)) -> -0.44528298 | K48: =IFERROR(I48/COUNTIF($G$47:$G$56,1),"ERROR!!!") -> 0.085805959 | L48: =IFERROR(J48/COUNTIF($G$47:$G$56,2),"ERROR!!!") -> -0.07421383 | M48: =IF(ROW()=47, 0, M47) + ABS(H48 - IF($G48=1, $K48, $L48)) -> 0.62848702 | N48: =IF(ROW()=47, 0, N47) + ABS(H48 - IF($G48=1, $L48, $K48)) -> 0.86272064 | R48: u = | S48: 2 | U48: Candidate: add x2
B49: 0.065972222 | C49: + | D49: -0.14285714 | E49: = | F49: =SUM(B49,D49) -> -0.076884921 | G49: 2 | H49: =IF(OR($G49=1,$G49=2), $F49 + IF($G49=1,1,-1)*$N$23*(EXP(-$F49)/(1+EXP(-$F49))), NA()) -> -0.23264845 | I49: =IF(G49=1,H49+N(I48),N(I48)) -> 0.34322383 | J49: =IF(G49=2,H49+N(J48),N(J48)) -> -0.67793143 | K49: =IFERROR(I49/COUNTIF($G$47:$G$56,1),"ERROR!!!") -> 0.085805959 | L49: =IFERROR(J49/COUNTIF($G$47:$G$56,2),"ERROR!!!") -> -0.11298857 | M49: =IF(ROW()=47, 0, M48) + ABS(H49 - IF($G49=1, $K49, $L49)) -> 0.7481469 | N49: =IF(ROW()=47, 0, N48) + ABS(H49 - IF($G49=1, $L49, $K49)) -> 1.1811751 | R49: q = | S49: =IF(O56<S32,S48,S34) -> 1 | U49: New temporary latent value:
...

Sheet Greedy upon Weight (2-Latent)
A1: Heart + Disease with Contribution Values (10, 13, 2)
A2: № | O2: Class | Q2: K1 = | R2: 4 | V2: Class Mean (K1)
B3: 0.52910083 | C3: -0.14285714 | D3: The Organizer | E3: -0.2407405 | F3: -0.0535715 | G3: 0.074074074 | H3: -0.14285714 | I3: 0.2407405 | J3: -0.053571429 | K3: -0.2407405 | L3: -0.14285714 | M3: -0.095238 | N3: 0.060763889 | O3: 2 | Q3: K2 = | R3: 6
B4: 0.52910083 | C4: 0.14285714 | E4: 0.2407405 | F4: -0.0535715 | G4: 0.074074074 | H4: -0.14285714 | I4: -0.2407405 | J4: -0.053571429 | K4: -0.2407405 | L4: -0.14285714 | M4: 0.095238 | N4: 0.060763889 | O4: 1
B5: -0.52910083 | C5: -0.14285714 | E5: -0.2407405 | F5: -0.0535715 | G5: 0.074074074 | H5: 0.14285714 | I5: -0.2407405 | J5: -0.053571429 | K5: 0.2407405 | L5: 0.14285714 | M5: 0.095238 | N5: 0.060763889 | O5: 2 | Q5: t =
B6: 0.52910083 | C6: -0.14285714 | E6: -0.2407405 | F6: -0.0535715 | G6: 0.074074074 | H6: 0.14285714 | I6: 0.2407405 | J6: 0.053571429 | K6: 0.2407405 | L6: -0.14285714 | M6: -0.095238 | N6: 0.060763889 | O6: 1 | V6: Class Mean (K2)
B7: 0.52910083 | C7: 0.14285714 | E7: 0.2407405 | F7: -0.0535715 | G7: 0.074074074 | H7: -0.14285714 | I7: 0.2407405 | J7: 0.053571429 | K7: 0.2407405 | L7: 0.14285714 | M7: -0.095238 | N7: 0.060763889 | O7: 1 | Q7: t = m = | R7: 10
B8: 0.52910083 | C8: -0.14285714 | E8: 0.2407405 | F8: 0.0535715 | G8: 0.074074074 | H8: 0.14285714 | I8: 0.2407405 | J8: -0.053571429 | K8: 0.2407405 | L8: 0.14285714 | M8: 0.095238 | N8: 0.060763889 | O8: 1
B9: -0.52910083 | C9: -0.14285714 | E9: -0.2407405 | F9: -0.0535715 | G9: -0.074074074 | H9: -0.14285714 | I9: -0.2407405 | J9: 0.053571429 | K9: -0.2407405 | L9: -0.14285714 | M9: -0.095238 | N9: -0.12152778 | O9: 2 | Q9: u =
B10: -0.52910083 | C10: -0.14285714 | E10: 0.2407405 | F10: -0.0535715 | G10: 0.074074074 | H10: -0.14285714 | I10: -0.2407405 | J10: 0.053571429 | K10: -0.2407405 | L10: -0.14285714 | M10: -0.095238 | N10: 0.060763889 | O10: 2
B11: -0.52910083 | C11: -0.14285714 | E11: -0.2407405 | F11: -0.0535715 | G11: 0.074074074 | H11: -0.14285714 | I11: -0.2407405 | J11: -0.053571429 | K11: -0.2407405 | L11: -0.14285714 | M11: -0.095238 | N11: 0.060763889 | O11: 2 | Q11: q = u = | R11: argmin {θ/γ} | V11: Intra-Class Similarity (Compactness)
B12: -0.52910083 | C12: 0.14285714 | E12: -0.2407405 | F12: -0.0535715 | G12: 0.074074074 | H12: -0.14285714 | I12: -0.2407405 | J12: -0.053571429 | K12: -0.2407405 | L12: -0.14285714 | M12: -0.095238 | N12: 0.060763889 | O12: 2
B13: 1 | C13: 0 | D13: 0 | E13: 1 | F13: 1 | G13: 0 | H13: 0 | I13: 1 | J13: 0 | K13: 1 | L13: 0 | M13: 1 | N13: 0
V15: Inter-Class Difference (Separability)
B16: Weight [Heart-Disease (10, 13, 2)] | Q16: cr1 =
B18: 0.634921 | C18: 0.42857143 | D18: 0.79166667 | E18: 0.412698 | F18: 0.214286 | G18: 0.44444444 | H18: 0.42857143 | I18: 0.412698 | J18: 0.32142857 | K18: 0.412698 | L18: 0.42857143 | M18: 0.285714 | N18: 0.72916667 | Q18: crit =
B19: =COUNTIF($B$18:$N$18, ">" & B18) + COUNTIF($B$18:B18, "=" & B18) -> 3 | C19: =COUNTIF($B$18:$N$18, ">" & C18) + COUNTIF($B$18:C18, "=" & C18) -> 5 | D19: =COUNTIF($B$18:$N$18, ">" & D18) + COUNTIF($B$18:D18, "=" & D18) -> 1 | E19: =COUNTIF($B$18:$N$18, ">" & E18) + COUNTIF($B$18:E18, "=" & E18) -> 8 | F19: =COUNTIF($B$18:$N$18, ">" & F18) + COUNTIF($B$18:F18, "=" & F18) -> 13 | G19: =COUNTIF($B$18:$N$18, ">" & G18) + COUNTIF($B$18:G18, "=" & G18) -> 4 | H19: =COUNTIF($B$18:$N$18, ">" & H18) + COUNTIF($B$18:H18, "=" & H18) -> 6 | I19: =COUNTIF($B$18:$N$18, ">" & I18) + COUNTIF($B$18:I18, "=" & I18) -> 9 | ... N19: =COUNTIF($B$18:$N$18, ">" & N18) + COUNTIF($B$18:N18, "=" & N18) -> 2
V20: Majorizing Function (Sigmoid || Logistic)
C23: 10 | N23: 0.3
C24: 0.35566388 | K24: 2 | N24: 0.1
F25: ⇒ | I25: ⇒ | N25: 5
F26: 0 | K26: 11
A30: Calculation of Generalized Assessment | H30: STEPS
C31: + | E31: = | G31: Classes | P31: STEP 3 | U31: STEP 3 — Try adding each remaining feature
B32: -0.37806569 | C32: + | D32: 0.52910083 | E32: = | F32: =SUM(B32,D32) -> 0.15103515 | G32: 2 | H32: =IF(OR($G32=1,$G32=2), $F32 + IF($G32=1,1,-1)*$N$23*(EXP(-$F32)/(1+EXP(-$F32))), NA()) -> 0.0123413 | I32: =IF(G32=1,H32+N(I31),N(I31)) -> 0 | J32: =IF(G32=2,H32+N(J31),N(J31)) -> 0.0123413 | K32: =IFERROR(I32/COUNTIF($G$32:$G$41,1),"ERROR!!!") -> 0 | L32: =IFERROR(J32/COUNTIF($G$32:$G$41,2),"ERROR!!!") -> 0.0020568833 | M32: =IF(ROW()=32, 0, M31) + ABS(H32 - IF($G32=1, $K32, $L32)) -> 0.010284416 | N32: =IF(ROW()=32, 0, N31) + ABS(H32 - IF($G32=1, $L32, $K32)) -> 0.0123413 | S32: =IF(O41<C23,O41,C23) -> 0.31720235
B33: 0.40872846 | C33: + | D33: 0.52910083 | E33: = | F33: =SUM(B33,D33) -> 0.93782929 | G33: 1 | H33: =IF(OR($G33=1,$G33=2), $F33 + IF($G33=1,1,-1)*$N$23*(EXP(-$F33)/(1+EXP(-$F33))), NA()) -> 1.022231 | I33: =IF(G33=1,H33+N(I32),N(I32)) -> 1.022231 | J33: =IF(G33=2,H33+N(J32),N(J32)) -> 0.0123413 | K33: =IFERROR(I33/COUNTIF($G$32:$G$41,1),"ERROR!!!") -> 0.25555775 | L33: =IFERROR(J33/COUNTIF($G$32:$G$41,2),"ERROR!!!") -> 0.0020568833 | M33: =IF(ROW()=32, 0, M32) + ABS(H33 - IF($G33=1, $K33, $L33)) -> 0.77695766 | N33: =IF(ROW()=32, 0, N32) + ABS(H33 - IF($G33=1, $L33, $K33)) -> 1.0325154 | S33: 1 | U33: Candidate: add x1
B34: -0.14942742 | C34: + | D34: -0.52910083 | E34: = | F34: =SUM(B34,D34) -> -0.67852825 | G34: 2 | H34: =IF(OR($G34=1,$G34=2), $F34 + IF($G34=1,1,-1)*$N$23*(EXP(-$F34)/(1+EXP(-$F34))), NA()) -> -0.87755129 | I34: =IF(G34=1,H34+N(I33),N(I33)) -> 1.022231 | J34: =IF(G34=2,H34+N(J33),N(J33)) -> -0.86520999 | K34: =IFERROR(I34/COUNTIF($G$32:$G$41,1),"ERROR!!!") -> 0.25555775 | L34: =IFERROR(J34/COUNTIF($G$32:$G$41,2),"ERROR!!!") -> -0.14420167 | M34: =IF(ROW()=32, 0, M33) + ABS(H34 - IF($G34=1, $K34, $L34)) -> 1.5103073 | N34: =IF(ROW()=32, 0, N33) + ABS(H34 - IF($G34=1, $L34, $K34)) -> 2.1656245 | S34: =IF(O41<C23,S33,F26) -> 1 | U34: New temporary latent value:
B35: 0.23923915 | C35: + | D35: 0.52910083 | E35: = | F35: =SUM(B35,D35) -> 0.76833998 | G35: 1 | H35: =IF(OR($G35=1,$G35=2), $F35 + IF($G35=1,1,-1)*$N$23*(EXP(-$F35)/(1+EXP(-$F35))), NA()) -> 0.86339148 | I35: =IF(G35=1,H35+N(I34),N(I34)) -> 1.8856225 | J35: =IF(G35=2,H35+N(J34),N(J34)) -> -0.86520999 | K35: =IFERROR(I35/COUNTIF($G$32:$G$41,1),"ERROR!!!") -> 0.47140562 | L35: =IFERROR(J35/COUNTIF($G$32:$G$41,2),"ERROR!!!") -> -0.14420167 | M35: =IF(ROW()=32, 0, M34) + ABS(H35 - IF($G35=1, $K35, $L35)) -> 1.9022931 | N35: =IF(ROW()=32, 0, N34) + ABS(H35 - IF($G35=1, $L35, $K35)) -> 3.1732176
B36: 0.40872846 | C36: + | D36: 0.52910083 | E36: = | F36: =SUM(B36,D36) -> 0.93782929 | G36: 1 | H36: =IF(OR($G36=1,$G36=2), $F36 + IF($G36=1,1,-1)*$N$23*(EXP(-$F36)/(1+EXP(-$F36))), NA()) -> 1.022231 | I36: =IF(G36=1,H36+N(I35),N(I35)) -> 2.9078535 | J36: =IF(G36=2,H36+N(J35),N(J35)) -> -0.86520999 | K36: =IFERROR(I36/COUNTIF($G$32:$G$41,1),"ERROR!!!") -> 0.72696337 | L36: =IFERROR(J36/COUNTIF($G$32:$G$41,2),"ERROR!!!") -> -0.14420167 | M36: =IF(ROW()=32, 0, M35) + ABS(H36 - IF($G36=1, $K36, $L36)) -> 2.1975608 | N36: =IF(ROW()=32, 0, N35) + ABS(H36 - IF($G36=1, $L36, $K36)) -> 4.3396503
B37: 0.23923915 | C37: + | D37: 0.52910083 | E37: = | F37: =SUM(B37,D37) -> 0.76833998 | G37: 1 | H37: =IF(OR($G37=1,$G37=2), $F37 + IF($G37=1,1,-1)*$N$23*(EXP(-$F37)/(1+EXP(-$F37))), NA()) -> 0.86339148 | I37: =IF(G37=1,H37+N(I36),N(I36)) -> 3.7712449 | J37: =IF(G37=2,H37+N(J36),N(J36)) -> -0.86520999 | K37: =IFERROR(I37/COUNTIF($G$32:$G$41,1),"ERROR!!!") -> 0.94281124 | L37: =IFERROR(J37/COUNTIF($G$32:$G$41,2),"ERROR!!!") -> -0.14420167 | M37: =IF(ROW()=32, 0, M36) + ABS(H37 - IF($G37=1, $K37, $L37)) -> 2.2769805 | N37: =IF(ROW()=32, 0, N36) + ABS(H37 - IF($G37=1, $L37, $K37)) -> 5.3472434
B38: -0.32058778 | C38: + | D38: -0.52910083 | E38: = | F38: =SUM(B38,D38) -> -0.84968861 | G38: 2 | H38: =IF(OR($G38=1,$G38=2), $F38 + IF($G38=1,1,-1)*$N$23*(EXP(-$F38)/(1+EXP(-$F38))), NA()) -> -1.0598392 | I38: =IF(G38=1,H38+N(I37),N(I37)) -> 3.7712449 | J38: =IF(G38=2,H38+N(J37),N(J37)) -> -1.9250491 | K38: =IFERROR(I38/COUNTIF($G$32:$G$41,1),"ERROR!!!") -> 0.94281124 | L38: =IFERROR(J38/COUNTIF($G$32:$G$41,2),"ERROR!!!") -> -0.32084152 | M38: =IF(ROW()=32, 0, M37) + ABS(H38 - IF($G38=1, $K38, $L38)) -> 3.0159782 | N38: =IF(ROW()=32, 0, N37) + ABS(H38 - IF($G38=1, $L38, $K38)) -> 7.3498938
B39: -0.37806569 | C39: + | D39: -0.52910083 | E39: = | F39: =SUM(B39,D39) -> -0.90716652 | G39: 2 | H39: =IF(OR($G39=1,$G39=2), $F39 + IF($G39=1,1,-1)*$N$23*(EXP(-$F39)/(1+EXP(-$F39))), NA()) -> -1.1208925 | I39: =IF(G39=1,H39+N(I38),N(I38)) -> 3.7712449 | J39: =IF(G39=2,H39+N(J38),N(J38)) -> -3.0459417 | K39: =IFERROR(I39/COUNTIF($G$32:$G$41,1),"ERROR!!!") -> 0.94281124 | L39: =IFERROR(J39/COUNTIF($G$32:$G$41,2),"ERROR!!!") -> -0.50765694 | M39: =IF(ROW()=32, 0, M38) + ABS(H39 - IF($G39=1, $K39, $L39)) -> 3.6292137 | N39: =IF(ROW()=32, 0, N38) + ABS(H39 - IF($G39=1, $L39, $K39)) -> 9.4135975
B40: -0.37806569 | C40: + | D40: -0.52910083 | E40: = | F40: =SUM(B40,D40) -> -0.90716652 | G40: 2 | H40: =IF(OR($G40=1,$G40=2), $F40 + IF($G40=1,1,-1)*$N$23*(EXP(-$F40)/(1+EXP(-$F40))), NA()) -> -1.1208925 | I40: =IF(G40=1,H40+N(I39),N(I39)) -> 3.7712449 | J40: =IF(G40=2,H40+N(J39),N(J39)) -> -4.1668342 | K40: =IFERROR(I40/COUNTIF($G$32:$G$41,1),"ERROR!!!") -> 0.94281124 | L40: =IFERROR(J40/COUNTIF($G$32:$G$41,2),"ERROR!!!") -> -0.69447236 | M40: =IF(ROW()=32, 0, M39) + ABS(H40 - IF($G40=1, $K40, $L40)) -> 4.0556339 | N40: =IF(ROW()=32, 0, N39) + ABS(H40 - IF($G40=1, $L40, $K40)) -> 11.477301
B41: -0.37806569 | C41: + | D41: -0.52910083 | E41: = | F41: =SUM(B41,D41) -> -0.90716652 | G41: 2 | H41: =IF(OR($G41=1,$G41=2), $F41 + IF($G41=1,1,-1)*$N$23*(EXP(-$F41)/(1+EXP(-$F41))), NA()) -> -1.1208925 | I41: =IF(G41=1,H41+N(I40),N(I40)) -> 3.7712449 | J41: =IF(G41=2,H41+N(J40),N(J40)) -> -5.2877267 | K41: =IFERROR(I41/COUNTIF($G$32:$G$41,1),"ERROR!!!") -> 0.94281124 | L41: =IFERROR(J41/COUNTIF($G$32:$G$41,2),"ERROR!!!") -> -0.88128778 | M41: =IF(ROW()=32, 0, M40) + ABS(H41 - IF($G41=1, $K41, $L41)) -> 4.2952386 | N41: =IF(ROW()=32, 0, N40) + ABS(H41 - IF($G41=1, $L41, $K41)) -> 13.541005 | O41: =M41/N41 -> 0.31720235
A45: Calculation of Generalized Assessment | H45: STEPS
C46: + | E46: = | G46: Classes | P46: STEP 3 | U46: STEP 3 — Try adding each remaining feature
B47: -0.37806569 | C47: + | D47: -0.14285714 | E47: = | F47: =SUM(B47,D47) -> -0.52092283 | G47: 2 | H47: =IF(OR($G47=1,$G47=2), $F47 + IF($G47=1,1,-1)*$N$23*(EXP(-$F47)/(1+EXP(-$F47))), NA()) -> -0.70913189 | I47: =IF(G47=1,H47+N(I46),N(I46)) -> 0 | J47: =IF(G47=2,H47+N(J46),N(J46)) -> -0.70913189 | K47: =IFERROR(I47/COUNTIF($G$47:$G$56,1),"ERROR!!!") -> 0 | L47: =IFERROR(J47/COUNTIF($G$47:$G$56,2),"ERROR!!!") -> -0.11818865 | M47: =IF(ROW()=47, 0, M46) + ABS(H47 - IF($G47=1, $K47, $L47)) -> 0.59094324 | N47: =IF(ROW()=47, 0, N46) + ABS(H47 - IF($G47=1, $L47, $K47)) -> 0.70913189 | R47: cr1 = | S47: =IF(O56<S32,O56,S32) -> 0.31720235
B48: 0.40872846 | C48: + | D48: 0.14285714 | E48: = | F48: =SUM(B48,D48) -> 0.5515856 | G48: 1 | H48: =IF(OR($G48=1,$G48=2), $F48 + IF($G48=1,1,-1)*$N$23*(EXP(-$F48)/(1+EXP(-$F48))), NA()) -> 0.66123458 | I48: =IF(G48=1,H48+N(I47),N(I47)) -> 0.66123458 | J48: =IF(G48=2,H48+N(J47),N(J47)) -> -0.70913189 | K48: =IFERROR(I48/COUNTIF($G$47:$G$56,1),"ERROR!!!") -> 0.16530865 | L48: =IFERROR(J48/COUNTIF($G$47:$G$56,2),"ERROR!!!") -> -0.11818865 | M48: =IF(ROW()=47, 0, M47) + ABS(H48 - IF($G48=1, $K48, $L48)) -> 1.0868692 | N48: =IF(ROW()=47, 0, N47) + ABS(H48 - IF($G48=1, $L48, $K48)) -> 1.4885551 | R48: u = | S48: 2 | U48: Candidate: add x2
B49: -0.14942742 | C49: + | D49: -0.14285714 | E49: = | F49: =SUM(B49,D49) -> -0.29228456 | G49: 2 | H49: =IF(OR($G49=1,$G49=2), $F49 + IF($G49=1,1,-1)*$N$23*(EXP(-$F49)/(1+EXP(-$F49))), NA()) -> -0.46405116 | I49: =IF(G49=1,H49+N(I48),N(I48)) -> 0.66123458 | J49: =IF(G49=2,H49+N(J48),N(J48)) -> -1.173183 | K49: =IFERROR(I49/COUNTIF($G$47:$G$56,1),"ERROR!!!") -> 0.16530865 | L49: =IFERROR(J49/COUNTIF($G$47:$G$56,2),"ERROR!!!") -> -0.19553051 | M49: =IF(ROW()=47, 0, M48) + ABS(H49 - IF($G49=1, $K49, $L49)) -> 1.3553898 | N49: =IF(ROW()=47, 0, N48) + ABS(H49 - IF($G49=1, $L49, $K49)) -> 2.1179149 | R49: q = | S49: =IF(O56<S32,S48,S34) -> 1 | U49: New temporary latent value:
B50: 0.23923915 | C50: + | D50: -0.14285714 | E50: = | F50: =SUM(B50,D50) -> 0.096382007 | G50: 1 | H50: =IF(OR($G50=1,$G50=2), $F50 + IF($G50=1,1,-1)*$N$23*(EXP(-$F50)/(1+EXP(-$F50))), NA()) -> 0.23915895 | I50: =IF(G50=1,H50+N(I49),N(I49)) -> 0.90039353 | J50: =IF(G50=2,H50+N(J49),N(J49)) -> -1.173183 | K50: =IFERROR(I50/COUNTIF($G$47:$G$56,1),"ERROR!!!") -> 0.22509838 | L50: =IFERROR(J50/COUNTIF($G$47:$G$56,2),"ERROR!!!") -> -0.19553051 | M50: =IF(ROW()=47, 0, M49) + ABS(H50 - IF($G50=1, $K50, $L50)) -> 1.3694504 | N50: =IF(ROW()=47, 0, N49) + ABS(H50 - IF($G50=1, $L50, $K50)) -> 2.5526044
...

Sheet Greedy upon Weight (3-Latent)
A1: Heart + Disease with Contribution Values (10, 13, 2)
A2: № | O2: Class | Q2: K1 = | R2: 4 | V2: Class Mean (K1)
B3: 0.52910083 | C3: -0.14285714 | D3: The Organizer | E3: -0.2407405 | F3: -0.0535715 | G3: 0.074074074 | H3: -0.14285714 | I3: 0.2407405 | J3: -0.053571429 | K3: -0.2407405 | L3: -0.14285714 | M3: -0.095238 | N3: 0.060763889 | O3: 2 | Q3: K2 = | R3: 6
B4: 0.52910083 | C4: 0.14285714 | E4: 0.2407405 | F4: -0.0535715 | G4: 0.074074074 | H4: -0.14285714 | I4: -0.2407405 | J4: -0.053571429 | K4: -0.2407405 | L4: -0.14285714 | M4: 0.095238 | N4: 0.060763889 | O4: 1
B5: -0.52910083 | C5: -0.14285714 | E5: -0.2407405 | F5: -0.0535715 | G5: 0.074074074 | H5: 0.14285714 | I5: -0.2407405 | J5: -0.053571429 | K5: 0.2407405 | L5: 0.14285714 | M5: 0.095238 | N5: 0.060763889 | O5: 2 | Q5: t =
B6: 0.52910083 | C6: -0.14285714 | E6: -0.2407405 | F6: -0.0535715 | G6: 0.074074074 | H6: 0.14285714 | I6: 0.2407405 | J6: 0.053571429 | K6: 0.2407405 | L6: -0.14285714 | M6: -0.095238 | N6: 0.060763889 | O6: 1 | V6: Class Mean (K2)
B7: 0.52910083 | C7: 0.14285714 | E7: 0.2407405 | F7: -0.0535715 | G7: 0.074074074 | H7: -0.14285714 | I7: 0.2407405 | J7: 0.053571429 | K7: 0.2407405 | L7: 0.14285714 | M7: -0.095238 | N7: 0.060763889 | O7: 1 | Q7: t = m = | R7: 10
B8: 0.52910083 | C8: -0.14285714 | E8: 0.2407405 | F8: 0.0535715 | G8: 0.074074074 | H8: 0.14285714 | I8: 0.2407405 | J8: -0.053571429 | K8: 0.2407405 | L8: 0.14285714 | M8: 0.095238 | N8: 0.060763889 | O8: 1
B9: -0.52910083 | C9: -0.14285714 | E9: -0.2407405 | F9: -0.0535715 | G9: -0.074074074 | H9: -0.14285714 | I9: -0.2407405 | J9: 0.053571429 | K9: -0.2407405 | L9: -0.14285714 | M9: -0.095238 | N9: -0.12152778 | O9: 2 | Q9: u =
B10: -0.52910083 | C10: -0.14285714 | E10: 0.2407405 | F10: -0.0535715 | G10: 0.074074074 | H10: -0.14285714 | I10: -0.2407405 | J10: 0.053571429 | K10: -0.2407405 | L10: -0.14285714 | M10: -0.095238 | N10: 0.060763889 | O10: 2
B11: -0.52910083 | C11: -0.14285714 | E11: -0.2407405 | F11: -0.0535715 | G11: 0.074074074 | H11: -0.14285714 | I11: -0.2407405 | J11: -0.053571429 | K11: -0.2407405 | L11: -0.14285714 | M11: -0.095238 | N11: 0.060763889 | O11: 2 | Q11: q = u = | R11: argmin {θ/γ} | V11: Intra-Class Similarity (Compactness)
B12: -0.52910083 | C12: 0.14285714 | E12: -0.2407405 | F12: -0.0535715 | G12: 0.074074074 | H12: -0.14285714 | I12: -0.2407405 | J12: -0.053571429 | K12: -0.2407405 | L12: -0.14285714 | M12: -0.095238 | N12: 0.060763889 | O12: 2
B13: 1 | C13: 0 | D13: 0 | E13: 1 | F13: 1 | G13: 0 | H13: 0 | I13: 1 | J13: 0 | K13: 1 | L13: 0 | M13: 1 | N13: 0
V15: Inter-Class Difference (Separability)
B16: Weight [Heart-Disease (10, 13, 2)] | Q16: cr1 =
B18: 0.634921 | C18: 0.42857143 | D18: 0.79166667 | E18: 0.412698 | F18: 0.214286 | G18: 0.44444444 | H18: 0.42857143 | I18: 0.412698 | J18: 0.32142857 | K18: 0.412698 | L18: 0.42857143 | M18: 0.285714 | N18: 0.72916667 | Q18: crit =
B19: =COUNTIF($B$18:$N$18, ">" & B18) + COUNTIF($B$18:B18, "=" & B18) -> 3 | C19: =COUNTIF($B$18:$N$18, ">" & C18) + COUNTIF($B$18:C18, "=" & C18) -> 5 | D19: =COUNTIF($B$18:$N$18, ">" & D18) + COUNTIF($B$18:D18, "=" & D18) -> 1 | E19: =COUNTIF($B$18:$N$18, ">" & E18) + COUNTIF($B$18:E18, "=" & E18) -> 8 | F19: =COUNTIF($B$18:$N$18, ">" & F18) + COUNTIF($B$18:F18, "=" & F18) -> 13 | G19: =COUNTIF($B$18:$N$18, ">" & G18) + COUNTIF($B$18:G18, "=" & G18) -> 4 | H19: =COUNTIF($B$18:$N$18, ">" & H18) + COUNTIF($B$18:H18, "=" & H18) -> 6 | I19: =COUNTIF($B$18:$N$18, ">" & I18) + COUNTIF($B$18:I18, "=" & I18) -> 9 | ... N19: =COUNTIF($B$18:$N$18, ">" & N18) + COUNTIF($B$18:N18, "=" & N18) -> 2
V20: Majorizing Function (Sigmoid || Logistic)
C23: 10 | N23: 0.3
C24: 0.2818537 | K24: 3 | N24: 0.1
F25: ⇒ | I25: ⇒ | N25: 5
F26: 0 | K26: 10
A30: Calculation of Generalized Assessment | H30: STEPS
C31: + | E31: = | G31: Classes | P31: STEP 3 | U31: STEP 3 — Try adding each remaining feature
B32: -0.67699741 | C32: + | D32: 0.52910083 | E32: = | F32: =SUM(B32,D32) -> -0.14789658 | G32: 2 | H32: =IF(OR($G32=1,$G32=2), $F32 + IF($G32=1,1,-1)*$N$23*(EXP(-$F32)/(1+EXP(-$F32))), NA()) -> -0.30896865 | I32: =IF(G32=1,H32+N(I31),N(I31)) -> 0 | J32: =IF(G32=2,H32+N(J31),N(J31)) -> -0.30896865 | K32: =IFERROR(I32/COUNTIF($G$32:$G$41,1),"ERROR!!!") -> 0 | L32: =IFERROR(J32/COUNTIF($G$32:$G$41,2),"ERROR!!!") -> -0.051494774 | M32: =IF(ROW()=32, 0, M31) + ABS(H32 - IF($G32=1, $K32, $L32)) -> 0.25747387 | N32: =IF(ROW()=32, 0, N31) + ABS(H32 - IF($G32=1, $L32, $K32)) -> 0.30896865 | S32: =IF(O41<C23,O41,C23) -> 0.30324636
B33: 0.69225412 | C33: + | D33: 0.52910083 | E33: = | F33: =SUM(B33,D33) -> 1.221355 | G33: 1 | H33: =IF(OR($G33=1,$G33=2), $F33 + IF($G33=1,1,-1)*$N$23*(EXP(-$F33)/(1+EXP(-$F33))), NA()) -> 1.2896644 | I33: =IF(G33=1,H33+N(I32),N(I32)) -> 1.2896644 | J33: =IF(G33=2,H33+N(J32),N(J32)) -> -0.30896865 | K33: =IFERROR(I33/COUNTIF($G$32:$G$41,1),"ERROR!!!") -> 0.32241609 | L33: =IFERROR(J33/COUNTIF($G$32:$G$41,2),"ERROR!!!") -> -0.051494774 | M33: =IF(ROW()=32, 0, M32) + ABS(H33 - IF($G33=1, $K33, $L33)) -> 1.2247222 | N33: =IF(ROW()=32, 0, N32) + ABS(H33 - IF($G33=1, $L33, $K33)) -> 1.6501278 | S33: 1 | U33: Candidate: add x1
B34: -0.4136154 | C34: + | D34: -0.52910083 | E34: = | F34: =SUM(B34,D34) -> -0.94271623 | G34: 2 | H34: =IF(OR($G34=1,$G34=2), $F34 + IF($G34=1,1,-1)*$N$23*(EXP(-$F34)/(1+EXP(-$F34))), NA()) -> -1.1586106 | I34: =IF(G34=1,H34+N(I33),N(I33)) -> 1.2896644 | J34: =IF(G34=2,H34+N(J33),N(J33)) -> -1.4675793 | K34: =IFERROR(I34/COUNTIF($G$32:$G$41,1),"ERROR!!!") -> 0.32241609 | L34: =IFERROR(J34/COUNTIF($G$32:$G$41,2),"ERROR!!!") -> -0.24459655 | M34: =IF(ROW()=32, 0, M33) + ABS(H34 - IF($G34=1, $K34, $L34)) -> 2.1387362 | N34: =IF(ROW()=32, 0, N33) + ABS(H34 - IF($G34=1, $L34, $K34)) -> 3.1311545 | S34: =IF(O41<C23,S33,F26) -> 1 | U34: New temporary latent value:
B35: 0.54607491 | C35: + | D35: 0.52910083 | E35: = | F35: =SUM(B35,D35) -> 1.0751757 | G35: 1 | H35: =IF(OR($G35=1,$G35=2), $F35 + IF($G35=1,1,-1)*$N$23*(EXP(-$F35)/(1+EXP(-$F35))), NA()) -> 1.1515018 | I35: =IF(G35=1,H35+N(I34),N(I34)) -> 2.4411661 | J35: =IF(G35=2,H35+N(J34),N(J34)) -> -1.4675793 | K35: =IFERROR(I35/COUNTIF($G$32:$G$41,1),"ERROR!!!") -> 0.61029153 | L35: =IFERROR(J35/COUNTIF($G$32:$G$41,2),"ERROR!!!") -> -0.24459655 | M35: =IF(ROW()=32, 0, M34) + ABS(H35 - IF($G35=1, $K35, $L35)) -> 2.6799465 | N35: =IF(ROW()=32, 0, N34) + ABS(H35 - IF($G35=1, $L35, $K35)) -> 4.5272528
B36: 0.69225412 | C36: + | D36: 0.52910083 | E36: = | F36: =SUM(B36,D36) -> 1.221355 | G36: 1 | H36: =IF(OR($G36=1,$G36=2), $F36 + IF($G36=1,1,-1)*$N$23*(EXP(-$F36)/(1+EXP(-$F36))), NA()) -> 1.2896644 | I36: =IF(G36=1,H36+N(I35),N(I35)) -> 3.7308305 | J36: =IF(G36=2,H36+N(J35),N(J35)) -> -1.4675793 | K36: =IFERROR(I36/COUNTIF($G$32:$G$41,1),"ERROR!!!") -> 0.93270763 | L36: =IFERROR(J36/COUNTIF($G$32:$G$41,2),"ERROR!!!") -> -0.24459655 | M36: =IF(ROW()=32, 0, M35) + ABS(H36 - IF($G36=1, $K36, $L36)) -> 3.0369032 | N36: =IF(ROW()=32, 0, N35) + ABS(H36 - IF($G36=1, $L36, $K36)) -> 6.0615138
B37: 0.54607491 | C37: + | D37: 0.52910083 | E37: = | F37: =SUM(B37,D37) -> 1.0751757 | G37: 1 | H37: =IF(OR($G37=1,$G37=2), $F37 + IF($G37=1,1,-1)*$N$23*(EXP(-$F37)/(1+EXP(-$F37))), NA()) -> 1.1515018 | I37: =IF(G37=1,H37+N(I36),N(I36)) -> 4.8823323 | J37: =IF(G37=2,H37+N(J36),N(J36)) -> -1.4675793 | K37: =IFERROR(I37/COUNTIF($G$32:$G$41,1),"ERROR!!!") -> 1.2205831 | L37: =IFERROR(J37/COUNTIF($G$32:$G$41,2),"ERROR!!!") -> -0.24459655 | M37: =IF(ROW()=32, 0, M36) + ABS(H37 - IF($G37=1, $K37, $L37)) -> 3.1059845 | N37: =IF(ROW()=32, 0, N36) + ABS(H37 - IF($G37=1, $L37, $K37)) -> 7.4576121
B38: -0.82013351 | C38: + | D38: -0.52910083 | E38: = | F38: =SUM(B38,D38) -> -1.3492343 | G38: 2 | H38: =IF(OR($G38=1,$G38=2), $F38 + IF($G38=1,1,-1)*$N$23*(EXP(-$F38)/(1+EXP(-$F38))), NA()) -> -1.5874357 | I38: =IF(G38=1,H38+N(I37),N(I37)) -> 4.8823323 | J38: =IF(G38=2,H38+N(J37),N(J37)) -> -3.0550149 | K38: =IFERROR(I38/COUNTIF($G$32:$G$41,1),"ERROR!!!") -> 1.2205831 | L38: =IFERROR(J38/COUNTIF($G$32:$G$41,2),"ERROR!!!") -> -0.50916916 | M38: =IF(ROW()=32, 0, M37) + ABS(H38 - IF($G38=1, $K38, $L38)) -> 4.184251 | N38: =IF(ROW()=32, 0, N37) + ABS(H38 - IF($G38=1, $L38, $K38)) -> 10.265631
B39: -0.67699741 | C39: + | D39: -0.52910083 | E39: = | F39: =SUM(B39,D39) -> -1.2060982 | G39: 2 | H39: =IF(OR($G39=1,$G39=2), $F39 + IF($G39=1,1,-1)*$N$23*(EXP(-$F39)/(1+EXP(-$F39))), NA()) -> -1.4369806 | I39: =IF(G39=1,H39+N(I38),N(I38)) -> 4.8823323 | J39: =IF(G39=2,H39+N(J38),N(J38)) -> -4.4919955 | K39: =IFERROR(I39/COUNTIF($G$32:$G$41,1),"ERROR!!!") -> 1.2205831 | L39: =IFERROR(J39/COUNTIF($G$32:$G$41,2),"ERROR!!!") -> -0.74866592 | M39: =IF(ROW()=32, 0, M38) + ABS(H39 - IF($G39=1, $K39, $L39)) -> 4.8725657 | N39: =IF(ROW()=32, 0, N38) + ABS(H39 - IF($G39=1, $L39, $K39)) -> 12.923194
B40: -0.67699741 | C40: + | D40: -0.52910083 | E40: = | F40: =SUM(B40,D40) -> -1.2060982 | G40: 2 | H40: =IF(OR($G40=1,$G40=2), $F40 + IF($G40=1,1,-1)*$N$23*(EXP(-$F40)/(1+EXP(-$F40))), NA()) -> -1.4369806 | I40: =IF(G40=1,H40+N(I39),N(I39)) -> 4.8823323 | J40: =IF(G40=2,H40+N(J39),N(J39)) -> -5.9289761 | K40: =IFERROR(I40/COUNTIF($G$32:$G$41,1),"ERROR!!!") -> 1.2205831 | L40: =IFERROR(J40/COUNTIF($G$32:$G$41,2),"ERROR!!!") -> -0.98816269 | M40: =IF(ROW()=32, 0, M39) + ABS(H40 - IF($G40=1, $K40, $L40)) -> 5.3213836 | N40: =IF(ROW()=32, 0, N39) + ABS(H40 - IF($G40=1, $L40, $K40)) -> 15.580758
